Workbook

Sheet 01-DgsOLD
B1: Doğuş | C1: 2021 ve sonrası
A2: ödeme yapılan son | G2: temmuz | H2: olması gereken
A3: Tarih | B3: Açıklama | C3: Bedeli | D3: Ödeme | E3: Bakiye | F3: aylık | G3: tüfe | I3: + | J3: Asg.Ü. | K3: adet
B4: Kira dönemi
B5: ADEM DUMAN
A6: 44255 | B6: 28-02-21*27-02-22 | C6: 24000 | D6: 24000 | E6: =C6-D6 -> 0 | F6: =D6/12 -> 2000 | J6: 2320 | K6: =D6/J6 -> 10.344828
A7: 44407 | B7: 28-02-22*27-02-23 | C7: 36000 | D7: 36000 | E7: =C7-D7 -> 0 | F7: =D7/12 -> 3000 | G7: 19.25 | H7: =F6*(100+G7)/100 -> 2385 | I7: =F7/F6-1 -> 0.5 | J7: 2830 | K7: =D7/J7 -> 12.720848
A8: 44772 | B8: 28-02-23*27-02-24 | C8: 60000 | D8: 60000 | E8: =C8-D8 -> 0 | F8: =D8/12 -> 5000 | G8: 80.21 | H8: =F7*(100+G8)/100 -> 5406.3 | I8: =F8/F7-1 -> 0.66666667 | J8: 5500 | K8: =D8/J8 -> 10.909091
A9: 45137 | B9: 28-02-24*27-02-25 | C9: 129000 | D9: 120500 | E9: =C9-D9 -> 8500 | F9: =C9/12 -> 10750 | G9: =58.94/2 -> 29.47 | H9: =F8*(100+(G9/2))/100 -> 5736.75 | I9: =F9/F8-1 -> 1.15 | J9: 11400 | K9: =D9/J9 -> 10.570175
A10: 45701 | B10: 28/02/25-31/12/25 | C10: =J10*K10+E9 -> 229540 | D10: =D52 -> 90000 | E10: =C10-D10 -> 139540 | F10: =ROUND((C10-E9)/10,) -> 22104 | G10: 75 | H10: =F9*(100+(G10/2))/100 -> 14781.25 | I10: =F10/F9-1 -> 1.056186 | J10: 22104 | K10: 10
A14: Kirada Oturma Dönem 28 Şubat ile sonraki yıl 27 Şubat tarihleri arasıdır.
A15: Ödeme kira dönem başalangıcından 6 ay önce başlar. Döneme ait Kira ödemesi bittiğinde
A16: sonraki yılın ödemesi 6 ay önceden başlar
A17: 45168 | B17: tarihine kadar şubat ayı enflasyonu ile artış yapılıp
A18: önceki 6 ay farkı son altı ayda tahsil ediliyordu
A19: 2023 ilk ödemeler 3000 son ödemeler 6500 TL toplamda 60000 TL uygulandı
A20: 2023 bedeli toplamda 60000 aylık 5000 TL oldu
A21: 2023 8. ayda 2023-24 için 60000 TL olan bedel %30 artışla 6500x12=78000 olarak belirlendi
A22: 78000 TL 28-02-2024 ile 27-02-2025 bedelidir ve ödemeler 2023 yılının 8. ayında başlamıştır.
A23: şubat ayında nakit ödeme yapmak yerine 6 ay öncesinden başlayarak 12 aylık ortalama
A24: vadeye göre ödeme yapılmaktadır. Yıllık artışlarda şubat ayına göre değil ağustos ayına
A25: göre uygulanacak
A26: 45350 | B26: Kiranın 12 asgari ücret bedeli olan 17,002*12=204024 TL olacağı ve artık
B27: yıllık artışın asgari ücrete bağlı olarak yapılacağı bildirildi.
B28: 2024 yılı için 10 aylık sözleşme yapılacağı, kira döneminin 2025 yılından sonra
B29: ocak-aralık olarak uygulanacağı anlatıldı.
B30: ödemeler düzenli yapılıyor ise ödediği ayın kira bedeli
B31: 6 ay sonrasının kira bedelidir.
A33: 28-02-2025 -31-12-2025 bedeli | C33: 22104 | D33: 12 | G33: =D33*C33 -> 265248
C35: Ödenecek | D35: Ödenen | E35: Bakiye
A37: 28-02-2025 -27-02-2026 için yapılan ödemeler
G38: =G33-D38 -> 265248
A39: 45534 | C39: 15000 | D39: 15000 | E39: =C39-D39 -> 0 | G39: =G33-D39 -> 250248
A40: 45565 | C40: =C39 -> 15000 | D40: 15000 | E40: =C40-D40+E39 -> 0 | G40: =G39-D40 -> 235248
A41: 45595 | C41: =C40 -> 15000 | D41: 15000 | E41: =C41-D41+E40 -> 0 | G41: =G40-D41 -> 220248
A42: 45626 | C42: =C41 -> 15000 | D42: 15000 | E42: =C42-D42+E41 -> 0 | G42: =G41-D42 -> 205248
A43: 45656 | C43: =C42 -> 15000 | D43: 15000 | E43: =C43-D43+E42 -> 0 | G43: =G42-D43 -> 190248
A44: 45687 | C44: =C43 -> 15000 | D44: 15000 | E44: =C44-D44+E43 -> 0 | G44: =G43-D44 -> 175248
A45: 45716 | C45: =G50/6 -> 29208 | E45: =C45-D45+E44 -> 29208 | G45: =G44-D45 -> 175248
A46: 45746 | C46: =C45 -> 29208 | E46: =C46-D46+E45 -> 58416 | G46: =G45-D46 -> 175248
...

Sheet 01-Dgs
C1: 45701
B2: ADEM DUMAN - 2021-2025
C3: HESAP ÖZETİ
C4: DÖNEM 1 Aylık Tutar | G4: =F6/12 -> 2000
C5: AÜ TL-Adet | F5: 2324 | G5: =F8/F5 -> 10.327022
C6: 28-02-2021 27-02-2022 DÖNEMİ | F6: =F8 -> 24000
E7: BANKA | F7: tutar | G7: bakiye
C8: DÖNEM 1 Hesabı | F8: 24000 | G8: =F8 -> 24000
G9: =G8-F9-E9 -> 24000
B10: 44250 | C10: Ödeme | F10: 2000 | G10: =G9-F10-E10 -> 22000
A11: 1 | B11: 44285 | C11: Ödeme | F11: 2000 | G11: =G10-F11-E11 -> 20000
A12: 2 | B12: 44316 | C12: Ödeme | F12: 2000 | G12: =G11-F12-E12 -> 18000
A13: 3 | B13: 44346 | C13: Ödeme | F13: 1000 | G13: =G12-F13-E13 -> 17000
A14: 4 | B14: 44377 | C14: Ödeme | F14: 3000 | G14: =G13-F14-E14 -> 14000
A15: 5 | B15: 44407 | C15: Ödeme | F15: 4000 | G15: =G14-F15-E15 -> 10000
A16: 6 | B16: 44788 | C16: Ödeme | F16: 10000 | G16: =G15-F16-E16 -> 0
C17: 2021-22 Tutarı 24000 TL | G17: =G16-F17-E17 -> 0
C18: Dönem Sonu Kalan BAKİYE | G18: =G17-F18-E18 -> 0
C20: DÖNEM 2 Aylık Tutar | G20: =F29/12 -> 3000
C21: AÜ | F21: 2825 | G21: =F29/F21 -> 12.743363
C22: 28-02-2022 27-02-2023 DÖNEMİ | F22: =F29 -> 36000
C23: Önceki dönem tüfeli bedel | F23: =F8 -> 24000
B24: 44407 | C24: ŞUBAT 2022 TÜFE | D24: 0.2598 | F24: =F23*D24 -> 6235.2
C25: tüfeli toplam | F25: =F23+F24 -> 30235.2
E26: BANKA | F26: tutar | G26: bakiye
G27: =F27 -> 0
G28: =G27+F28 -> 0
C29: DÖNEM 2 Hesabı | F29: 36000 | G29: =G28+F29 -> 36000
G30: =G29-F30-E30 -> 36000
A31: 1 | B31: 44438 | C31: Nakit 2000 TL | F31: 2000 | G31: =G30-F31-E31 -> 34000
A32: 2 | B32: 44469 | C32: Nakit 2000 TL | F32: 2000 | G32: =G31-F32-E32 -> 32000
A33: 3 | B33: 44499 | C33: Nakit 2000 TL | F33: 2000 | G33: =G32-F33-E33 -> 30000
A34: 4 | B34: 44530 | C34: Nakit 2000 TL | F34: 2000 | G34: =G33-F34-E34 -> 28000
A35: 5 | B35: 44560 | C35: Nakit 2000 TL | F35: 2000 | G35: =G34-F35-E35 -> 26000
A36: 6 | B36: 44591 | C36: Nakit 2000 TL | F36: 2000 | G36: =G35-F36-E36 -> 24000
A37: 7 | B37: 44620 | C37: Nakit 3000 TL ödendi | F37: 3000 | G37: =G36-F37-E37 -> 21000
A38: 8 | B38: 44650 | C38: Nakit 3000 TL | F38: 3000 | G38: =G37-F38-E38 -> 18000
A39: 9 | B39: 44681 | C39: Nakit 3000 TL 10-05-2022 | F39: 5000 | G39: =G38-F39-E39 -> 13000
A40: 10 | B40: 44711 | C40: Nakit 5000 TL | F40: 3000 | G40: =G39-F40-E40 -> 10000
A41: 11 | B41: 44742 | C41: Nakit 5000 TL 05-07-2022 | E41: 4000 | G41: =G40-F41-E41 -> 6000
...

Sheet DGS_31-05-24
B1: 31-05-2024 Adem Dumana bildirildi
B3: MEVCUT DEVAM EDEN DURUM | F3: 28-02-2024 --> 27-02-2025
B4: Temmuz sonundan itibaren uygulanmayacak
B5: Ödeme Tarihi | C5: Açıklama | D5: Ödenecek | E5: Ödenen | F5: Bakiye
B6: 45168 | C6: 1 / 12 | D6: 6500 | E6: 6500 | F6: =D6-E6 -> 0
B7: 45199 | C7: 2 / 12 | D7: 6500 | E7: 6500 | F7: =D7-E7+F6 -> 0
B8: 45229 | C8: 3 / 12 | D8: 6500 | E8: 6500 | F8: =D8-E8+F7 -> 0
B9: 45260 | C9: 4 / 12 | D9: 6500 | E9: 6500 | F9: =D9-E9+F8 -> 0
B10: 45290 | C10: 5 / 12 | D10: 6500 | E10: 6500 | F10: =D10-E10+F9 -> 0
B11: 45321 | C11: 6 / 12 | D11: 6500 | E11: 6500 | F11: =D11-E11+F10 -> 0
B12: 45351 | C12: 7 / 12 | D12: 15000 | E12: 6500 | F12: =D12-E12+F11 -> 8500
B13: 45381 | C13: 8 / 12 | D13: 15000 | E13: 15000 | F13: =D13-E13+F12 -> 8500
B14: 45412 | C14: 9 / 12 | D14: 15000 | E14: 15000 | F14: =D14-E14+F13 -> 8500
B15: 45442 | C15: 10 / 12 | D15: 15000 | F15: =D15-E15+F14 -> 23500
B16: 45473 | C16: 11 / 12 | D16: 15000 | F16: =D16-E16+F15 -> 38500
B17: 45503 | C17: 12 / 12 | D17: 15000 | F17: =D17-E17+F16 -> 53500
F18: =D18-E18+F17 -> 53500
C19: TOPLAMLAR | D19: =SUM(D6:D18) -> 129000 | E19: =SUM(E6:E18) -> 75500 | F19: =F18 -> 53500
C20: Aylık ortalama | D20: =D19/12 -> 10750
B24: 1. SEÇENEK | C24: AYLIK ÖDEMEYLE DEVAM | F24: 28-02-2025 --> 27-02-2026
B26: Ödeme Tarihi | C26: Açıklama | D26: Ödenecek | E26: Ödenen | F26: Bakiye
B27: 45534 | C27: 1 / 12 asgari ücret tutarı
B28: 45565 | C28: 2 / 12 asgari ücret tutarı
B29: 45595 | C29: 3 / 12 asgari ücret tutarı
B30: 45626 | C30: 4 / 12 asgari ücret tutarı
B31: 45656 | C31: 5 / 12 asgari ücret tutarı
B32: 45687 | C32: 6 / 12 asgari ücret tutarı
B33: 45716 | C33: 7 / 12 asgari ücret tutarı
B34: 45746 | C34: 8 / 12 asgari ücret tutarı
B35: 45777 | C35: 9 / 12 asgari ücret tutarı
B36: 45807 | C36: 10 / 12 asgari ücret tutarı
B37: 45838 | C37: 11 / 12 asgari ücret tutarı
B38: 45868 | C38: 12 / 12 asgari ücret tutarı
B43: 2. SEÇENEK | C43: ERKEN YILLIK PEŞİN ÖDEME | F43: 28-02-2025 --> 27-02-2026
B45: Ödeme Tarihi | C45: Açıklama | D45: Ödenecek | E45: Ödenen | F45: Bakiye
B47: 45534 | C47: Tek Ödeme 17002 x 12 | D47: 204024
B53: 3. SEÇENEK | C53: DÖNEM BAŞI YILLIK PEŞİN ÖDEME | F53: 28-02-2025 --> 27-02-2026
B55: Ödeme Tarihi | C55: Açıklama | D55: Ödenecek | E55: Ödenen | F55: Bakiye
B57: 45716 | C57: Tek Ödeme asgari ücret x 12

Sheet 2024
B2: 44255 | C2: 28-02-2021 * 27-02-22 | G2: Ödenecek Toplam 24000 | N2: temmuz | R2: ASGARİ ÜCRET
B3: Tarih | C3: Açıklama | D3: Ödenecek | E3: Ödenen | F3: Bakiye | J3: aylık | K3: + | L3: yıllık | N3: tüfe % | O3: tüfeli fiyat | Q3: TL | R3: adet
B4: 44255 | C4: nakit | D4: 2000 | E4: 2000 | F4: =D4-E4 -> 0 | I4: 2021 | J4: =L4/12 -> 2000 | L4: =E11 -> 24000 | O4: 24000 | Q4: 2320 | R4: =L4/Q4 -> 10.344828
B5: 44285 | C5: Senet 2000 x | D5: 2000 | E5: 2000 | F5: =F4+D5-E5 -> 0 | I5: 2022 | J5: =L5/12 -> 3000 | K5: =L5/L4-1 -> 0.5 | L5: =$E$27 -> 36000 | N5: 0.2598 | O5: =(O4+(L4*N5)) -> 30235.2 | Q5: 2830 | R5: =L5/Q5 -> 12.720848
B6: 44316 | C6: Senet 2000 x | D6: 2000 | E6: 2000 | F6: =F5+D6-E6 -> 0 | I6: 2023 | J6: =L6/12 -> 5000 | K6: =L6/L5-1 -> 0.66666667 | L6: =E43 -> 60000 | N6: 0.7183 | O6: =(O5+(L5*N6)) -> 56094 | Q6: 5500 | R6: =L6/Q6 -> 10.909091
B7: 44346 | C7: Senet 2000 x | D7: 2000 | E7: 1000 | F7: =F6+D7-E7 -> 1000 | I7: 2024 | J7: =L7/12 -> 10041.667 | K7: =L7/L6-1 -> 1.0083333 | L7: =E59 -> 120500 | N7: 0.5591 | O7: =(O6+(L6*N7)) -> 89640 | Q7: 11400 | R7: =L7/Q7*2 -> 21.140351
B8: 44377 | C8: Senet 2000 x | D8: 2000 | E8: 3000 | F8: =F7+D8-E8 -> 0 | I8: 2025 | J8: =L8/12 -> 7500 | K8: =L8/L7-1 -> -0.25311203 | L8: =E76 -> 90000 | N8: 0.5 | O8: =(O7+(L7*N8)) -> 149890 | Q8: 22104 | R8: 12
B9: 44407 | C9: Senet 14000 x | D9: 14000 | E9: 9000 | F9: =F8+D9-E9 -> 5000
B10: 44446 | C10: Nakit | E10: 5000 | F10: =F9+D10-E10 -> 0 | L10: =SUM(L4:L7) -> 240500 | O10: =SUM(O4:O7) -> 199969.2
D11: Toplam Ödenen | E11: =SUM(E4:E10) -> 24000
C12: 28-02-2022 * 27-02-23 | G12: Ödenecek Toplam 36000 | L12: bankadan ödeme | O12: =H76 -> 99500
B13: Tarih | C13: Açıklama | D13: Ödenecek | E13: Ödenen | F13: Bakiye
B14: 44438 | C14: Senet 2000 x | D14: 2000 | E14: 0 | F14: =D14-E14 -> 2000
B15: 44469 | C15: Senet 2000 x | D15: 2000 | E15: 4000 | F15: =F14+D15-E15 -> 0
B16: 44499 | C16: Senet 2000 x | D16: 2000 | E16: 2000 | F16: =F15+D16-E16 -> 0
B17: 44530 | C17: Senet 2000 X | D17: 2000 | E17: 2000 | F17: =F16+D17-E17 -> 0
B18: 44560 | C18: Senet 2000 | D18: 2000 | E18: 2000 | F18: =F17+D18-E18 -> 0
B19: 44591 | C19: Senet 2000 | D19: 2000 | E19: 2000 | F19: =F18+D19-E19 -> 0
B20: 44620 | C20: Nakit 3000 | D20: 3000 | E20: 3000 | F20: =F19+D20-E20 -> 0
B21: 44650 | C21: Nakit 3000 | D21: 3000 | E21: 3000 | F21: =F20+D21-E21 -> 0
B22: 44681 | C22: Nakit 3000 10-05-2022 | D22: 3000 | E22: 5000 | F22: =F21+D22-E22 -> -2000
B23: 44711 | C23: Nakit 5000 | D23: 5000 | E23: 3000 | F23: =F22+D23-E23 -> 0
B24: 44742 | C24: BANKADAN 5-7 4000 | D24: 5000 | E24: 4000 | F24: =F23+D24-E24 -> 1000 | H24: 4000
B25: 44772 | C25: BANKADAN 29-8 5000 | D25: 5000 | E25: 5000 | F25: =F24+D25-E25 -> 1000 | H25: 5000
B26: 44803 | C26: Nakit | E26: 1000 | F26: =F25+D26-E26 -> 0
D27: Toplam Ödenen | E27: =SUM(E14:E26) -> 36000
C28: 28-02-2023 * 27-02-24 Bir yıl | G28: Ödenecek Toplam 62280
C29: 2023 indirim | E29: 2280
B30: Tarih | C30: Açıklama | D30: Ödenecek | E30: Ödenen | F30: Bakiye
B31: 45167 | C31: Nakit 3000 | D31: 3000 | E31: 3000 | F31: =D31-E31 -> 0
B32: 44834 | C32: Nakit 3000 | D32: 3000 | E32: 3000 | F32: =F31+D32-E32 -> 0
B33: 44865 | C33: Nakit 3000 | D33: 3000 | E33: 3000 | F33: =F32+D33-E33 -> 0
B34: 44895 | C34: Nakit 3000 | D34: 3000 | E34: 3000 | F34: =F33+D34-E34 -> 0
B35: 44925 | C35: Nakit 3000 bankadan | D35: 3000 | E35: 3000 | F35: =F34+D35-E35 -> 0 | H35: 3000
B36: 44956 | C36: Nakit 3000 bankadan 6-2 | D36: 6000 | E36: 6000 | F36: =F35+D36-E36 -> 0 | H36: 6000
B37: 44985 | C37: Nakit 3000 ELDEN | D37: 6500 | E37: 6500 | F37: =F36+D37-E37 -> 0
B38: 45015 | C38: Nakit 6500 | D38: 6500 | E38: 6500 | F38: =F37+D38-E38 -> 0
B39: 45046 | C39: Nakit 6500 | D39: 6500 | E39: 6500 | F39: =F38+D39-E39 -> 0
B40: 45076 | C40: Nakit 6500 | D40: 6500 | E40: 6500 | F40: =F39+D40-E40 -> 0
B41: 45107 | C41: Nakit 6500 | D41: 6500 | E41: 6500 | F41: =F40+D41-E41 -> 0
...

Sheet 02--_Tzgmrg
B3: Tuzgümrüğü kira
A6: Tarih | B6: Açıklama | C6: Kira bedeli | D6: Ödeme | E6: Bakiye | F6: Masraf | G6: Kalan Kira
A8: 44946 | B8: 26-12-2022 bankadan 3300 | C8: 1650 | D8: 1650 | E8: =C8-D8 -> 0 | G8: =D8-F8 -> 1650
A9: 44977 | B9: 26-12-2022 bankadan 3300 | C9: 1650 | D9: 1650 | E9: =E8-D9+C9 -> 0 | G9: =D9-F9 -> 1650
A10: 45005 | C10: 1650 | D10: 1650 | E10: =E9-D10+C10 -> 0 | G10: =D10-F10 -> 1650
B11: 30-4-2023-24 | E11: =E10-D11+C11 -> 0 | G11: =D11-F11 -> 0
A12: 44671 | B12: Salih Kaymak | E12: =E11-D12+C12 -> 0 | G12: =D12-F12 -> 0
B13: *12 | E13: =E12-D13+C13 -> 0 | G13: =D13-F13 -> 0
A14: 45036 | C14: 2800 | D14: 2800 | E14: =E13-D14+C14 -> 0 | G14: =D14-F14 -> 2800
A15: 45066 | C15: 2800 | D15: 2800 | E15: =E14-D15+C15 -> 0 | G15: =D15-F15 -> 2800
A16: 45097 | C16: 2800 | D16: 2800 | E16: =E15-D16+C16 -> 0 | G16: =D16-F16 -> 2800
A17: 45127 | C17: 2800 | D17: 2800 | E17: =E16-D17+C17 -> 0 | G17: =D17-F17 -> 2800
A18: 45158 | C18: 2800 | D18: 2800 | E18: =E17-D18+C18 -> 0 | G18: =D18-F18 -> 2800
A19: 45189 | C19: 2800 | D19: 2800 | E19: =E18-D19+C19 -> 0 | G19: =D19-F19 -> 2800
A20: 45232 | B20: bankadan 5600 1/2 | C20: 2800 | D20: 2800 | E20: =E19-D20+C20 -> 0 | G20: =D20-F20 -> 2800
A21: 45250 | B21: bankadan 2/2 | C21: 2800 | D21: 2800 | E21: =E20-D21+C21 -> 0 | G21: =D21-F21 -> 2800
A22: 45280 | C22: 2800 | D22: 2800 | E22: =E21-D22+C22 -> 0 | G22: =D22-F22 -> 2800
A23: 45311 | C23: 2800 | D23: 2800 | E23: =E22-D23+C23 -> 0 | G23: =D23-F23 -> 2800
A24: 45342 | C24: 2800 | D24: 2800 | E24: =E23-D24+C24 -> 0 | G24: =D24-F24 -> 2800
A25: 45371 | C25: 2800 | D25: 2800 | E25: =E24-D25+C25 -> 0 | G25: =D25-F25 -> 2800
B27: Toplamlar | C27: =SUM(C8:C26) -> 38550 | D27: =SUM(D8:D26) -> 38550 | E27: =E22 -> 0 | F27: =SUM(F12:F26) -> 0 | G27: =D27-F27 -> 38550
E29: Tuzgümrüğü Toplam Kira Geliri | G29: =G27 -> 38550
E31: Hacı | F31: 1 | G31: =G29*$F$31 -> 38550
B37: 2022
B39: Tuzgümrüğü kira
A42: Tarih | B42: Açıklama | C42: Kira bedeli | D42: Ödeme | E42: Bakiye | F42: Masraf | G42: Kalan Kira
A44: 44581 | B44: 2021 den kalan | C44: 3000 | E44: =C44-D44 -> 3000 | G44: =D44-F44 -> 0
A45: 44612 | D45: 3000 | E45: =E44-D45 -> 0 | G45: =D45-F45 -> 3000
A46: 44640 | E46: =E45-D46 -> 0 | G46: =D46-F46 -> 0
B47: 30-4-2022-23 | E47: =E46-D47 -> 0 | G47: =D47-F47 -> 0
A48: 44671 | B48: Salih Kaymak | E48: =E47-D48 -> 0 | G48: =D48-F48 -> 0
B49: 1650*12 | E49: =E48-D49 -> 0 | G49: =D49-F49 -> 0
A50: 44671 | B50: 12-05-2022 ilk ödeme | C50: 1650 | D50: 1600 | E50: =C50-D50+E49 -> 50 | G50: =D50-F50 -> 1600
A51: 44701 | C51: 1650 | D51: 1650 | E51: =E50+C51-D51 -> 50 | G51: =D51-F51 -> 1650
A52: 44732 | C52: 1650 | D52: 1650 | E52: =E51+C52-D52 -> 50 | G52: =D52-F52 -> 1650
A53: 44762 | C53: 1650 | D53: 1650 | E53: =E52+C53-D53 -> 50 | G53: =D53-F53 -> 1650
A54: 44793 | C54: 1650 | D54: 1650 | E54: =E53+C54-D54 -> 50 | G54: =D54-F54 -> 1650
A55: 44824 | C55: 1650 | D55: 1650 | E55: =E54+C55-D55 -> 50 | G55: =D55-F55 -> 1650
A56: 44854 | C56: 1650 | D56: 1650 | E56: =E55+C56-D56 -> 50 | G56: =D56-F56 -> 1650
A57: 44885 | C57: 1650 | D57: 1650 | E57: =E56+C57-D57 -> 50 | G57: =D57-F57 -> 1650
...

Sheet 01-03-HAKAN
E1: 45233
B2: DOĞUŞ TİC. - HAKAN BALCI 2003-2012 HESAP CETVELİ
A3: 2003-2004 | C3: evrak no | D3: alınan | E3: ödeme | F3: bakiye
B4: Ny 2003 | D4: 17075.75 | F4: =D4+E4 -> 17075.75
A5: 38253 | B5: yb | D5: 90 | F5: =F4+D5+E5 -> 17165.75
B6: yb | D6: 45 | F6: =F5+D6+E6 -> 17210.75
B7: örtü | D7: 5 | F7: =F6+D7+E7 -> 17215.75
B8: yb | D8: 36 | F8: =F7+D8+E8 -> 17251.75
B9: Araba kredi 7 | D9: 725 | F9: =F8+D9+E9 -> 17976.75
B10: Araba kredi 8 | D10: 725 | F10: =F9+D10+E10 -> 18701.75
B11: Araba kredi 9 | D11: 725 | F11: =F10+D11+E11 -> 19426.75
B12: vergi | D12: 1200 | F12: =F11+D12+E12 -> 20626.75
B13: Araba kredi 10 | D13: 725 | F13: =F12+D13+E13 -> 21351.75
B14: pls | D14: 65 | F14: =F13+D14+E14 -> 21416.75
B15: tunç perde | D15: 400 | F15: =F14+D15+E15 -> 21816.75
B16: Araba kredi 11 | D16: 725 | F16: =F15+D16+E16 -> 22541.75
B17: Araba kredi 12 | D17: 725 | F17: =F16+D17+E17 -> 23266.75
B18: vergi | D18: 4500 | F18: =F17+D18+E18 -> 27766.75
A19: 38328 | B19: Vakıf kredi 1 | C19: 1 | D19: 2426 | F19: =F18+D19+E19 -> 30192.75
B20: ssk | D20: 1520 | F20: =F19+D20+E20 -> 31712.75
B21: 26-2 çek HAKANDAN | E21: -2000 | F21: =F20+D21+E21 -> 29712.75
B22: 27-2 çek HAKANDAN | E22: -3000 | F22: =F21+D22+E22 -> 26712.75
B23: 5-3 çek HAKANDAN | E23: -3750 | F23: =F22+D23+E23 -> 22962.75
A24: 38352 | B24: sanayi hesabı | E24: -1960 | F24: =F23+D24+E24 -> 21002.75
C25: 2004 yıl içi toplamı | D25: =SUM(D5:D24) -> 14637 | E25: =SUM(E5:E24) -> -10710
A28: 2005 | C28: evrak no | D28: alınan | E28: ödeme | F28: bakiye
E29: 2004 NY | F29: =F24 -> 21002.75
A30: 38366 | B30: bağkur | C30: 2 | D30: 677 | F30: =F29+D30+E30 -> 21679.75
A31: 38369 | B31: Vakıf kredi 1 | C31: 3 | D31: 2466.32 | F31: =F30+D31+E31 -> 24146.07
A32: 38378 | B32: tvn | D32: 200 | F32: =F31+D32+E32 -> 24346.07
B33: pls | D33: 140 | F33: =F32+D33+E33 -> 24486.07
B34: kdv | D34: 1000 | F34: =F33+D34+E34 -> 25486.07
A35: 38383 | B35: Araba kredi 1 | D35: 760 | F35: =F34+D35+E35 -> 26246.07
A36: 38411 | B36: Araba kredi 2 | D36: 760 | F36: =F35+D36+E36 -> 27006.07
A37: 38421 | B37: Vakıf kredi 2 | C37: 4 | D37: 2568.86 | F37: =F36+D37+E37 -> 29574.93
A38: 38422 | B38: Vakıf kredi 3 | C38: 5 | D38: 2414.08 | F38: =F37+D38+E38 -> 31989.01
A39: 38422 | B39: Vakıf kredi 4 | C39: 6 | D39: 2279.24 | F39: =F38+D39+E39 -> 34268.25
A40: 38442 | B40: Araba kredi 3 | D40: 742 | F40: =F39+D40+E40 -> 35010.25
B41: pls | D41: 65 | F41: =F40+D41+E41 -> 35075.25
B42: stn | D42: 5 | F42: =F41+D42+E42 -> 35080.25
...

Sheet 01-01-DGS
B1: DOĞUŞ TİCARET – NAZAN BALCI İŞ SONLANDIRMA HESAP CETVELİ
B2: 1994 yılında Doğuş Ticaret Ayten Balcı’ya ait arsaya 5 daire 1 dükkan
B3: olacak şekilde bir bina yaptı. | E3: 45233
C4: Değeri | D4: Kat Karşılığı | E4: Kime Ait | F4: Son Durum
B5: Daire 5 | C5: 80000 | D5: Arsa Sahibine | E5: Ayten Balcı | F5: Ayten Balcı
B6: Daire 4 | C6: 80000 | D6: Doğuş Ticaret | E6: Nazan Balcı | F6: Ayten Balcı
B7: Daire 3 | C7: 80000 | D7: Doğuş Ticaret | E7: Nazan Balcı | F7: Ayten Balcı
B8: Daire 2 satıldı | C8: 80000 | D8: Doğuş Ticaret | E8: Hacı | F8: Satıldı
B9: Daire 1 Satıldı | C9: 80000 | D9: Doğuş Ticaret | E9: Hacı | F9: Satıldı
B10: Dükkan Satıldı | C10: 30000 | D10: Doğuş Ticaret | E10: Hacı + Nazan | F10: Satıldı
A13: * | B13: daire 2 satıldı, Ali Paşa Hamam daki arsanın, Mustafa Işıklıyurt’a ait hisse satın alındı
B14: 2 nolu daire hacı ya ait olmasına rağmen ali paşa ortak alındığından dolayı daire den alınan
B15: paranın yarısı İsmail Balcıya geçmiş oldu. | F15: 80000
A16: * | B16: Dükkan satıldı parayı hacı aldı ortaklardan nazanın alacağı oluştu | F16: -30000
A17: * | B17: hakanın Doğuştan aldığı nakit | F17: ='01-03-HAKAN'!D179 -> 143534.12
A18: * | B18: 2007 de hacı doğuşa geçtiğinde borç ödemesi için mustafa balcı 50000 TL verdi. | F18: 50000
B20: 2015-ocak ayı Doğuşun; Denizbanka 365.000 TL, İşbank a 36.000 TL kredi borcu var
B21: Aylık borç ödemesi 6765+3409=10.174 TL. 1 USD=2.40 TL Aylık ödeme # 4239 USD #
B22: Dolar cinsinden borç yaklaşık 167000 USD
B23: Envanter yaklaşık 110 000 TL Satılabilir mal toplamı yaklaşık 60 000 TL = 25000 usd
B24: * Bu bilgiler şirkette aylık dönen paranın anlaşılabilmesi için verilmiştir.
C28: HACI ALACAK | D28: Bakiye | E28: TL – usd | F28: karşılığı
C29: TL | D29: TL | F29: USD
A30: 2005 | B30: İnşaat Daire 2 den kalan ½ | C30: =F15/2 -> 40000 | D30: =C30 -> 40000 | E30: 1.4 | F30: =C30/E30 -> 28571.429
A31: 04-07 | B31: Hakan BALCI Doğuştan verilen ½ | C31: =F17/2 -> 71767.06 | D31: =D30+C31 -> 111767.06 | E31: =C31/F31 -> 1.4427171 | F31: ='01-03-HAKAN'!F181/2 -> 49744.375
A32: 2008 | B32: mustafa balcıdan doğuşa verilen ½ | C32: =F18/2 -> 25000 | D32: =D31+C32 -> 136767.06 | E32: 1.31 | F32: =C32/E32 -> 19083.969
A33: 2017 | B33: Nazan Doğuş kapanış borcu ½ | C33: =F59*-1 -> 141563.55 | D33: =D32+C33 -> 278330.61 | E33: 3.55 | F33: =C33/E33 -> 39877.056
B34: 2017 yılı sonu | E34: hacının alacağı USD | F34: =SUM(F30:F33) -> 137276.83
C35: NAZAN ALACAK
B36: İnşaat Dükkandan nazana ½ | C36: -15000 | D36: =C36 -> -15000 | E36: 1.4 | F36: =C36/E36 -> -10714.286
D37: =D36+C37 -> -15000
E38: Nazanın alacağı USD | F38: =SUM(F36:F37) -> -10714.286
B39: Toplam TL | C39: =SUM(C30:C38) -> 263330.61
B40: 2017 yılı sonu | E40: hacının KALAN alacağı USD | F40: =F34+F38 -> 126562.54
B44: DOĞUŞ TİCARET KAPANIŞ HESABI 2017 | F44: TL
B45: sanayi boya dükkan masrafı mermer-alçıpan Ali Balcı | D45: TL | E45: -20000 | F45: =E45 -> -20000
B46: hacı bağkur borcu | D46: TL | E46: -24710 | F46: =F45+E46 -> -44710
B47: Envanter satış kdv | D47: TL | E47: -13750 | F47: =F46+E47 -> -58460
B48: maliye kapanışta vergi | D48: TL | E48: -7000 | F48: =F47+E48 -> -65460
B49: Firmalara ölan borçlar (yanar) | D49: TL | E49: -180984.36 | F49: =F48+E49 -> -246444.36
...

Sheet 01-02-DGS
D1: 45233
A3: Doğuşa Olan Borçlar | E3: BAKİYE
A4: Nazan – Hakanın doğuştan ödenen borçlar | B4: ='01-03-HAKAN'!F159 -> 143534.12 | C4: =B4/D4 -> 1.4427171 | D4: ='01-03-HAKAN'!F181 -> 99488.749 | E4: =D4 -> 99488.749
A5: Nazan – Doğuş kapanış borcu ½ | B5: ='01-01-DGS'!F59*-1 -> 141563.55 | C5: 3.55 | D5: =B5/C5 -> 39877.056 | E5: =E4+D5 -> 139365.81
A6: Hacı – Doğuş kapanış borcu ½ | B6: ='01-01-DGS'!F61*-1 -> 131356.55 | C6: 3.55 | D6: =B6/C6 -> 37001.845 | E6: =E5+D6 -> 176367.65
A7: DOĞUŞ KAPANIŞ ALACAK TOPLAMI | B7: =SUM(B4:B6) -> 416454.22 | D7: =SUM(D4:D6) -> 176367.65
A9: Doğuşun Borçları
A10: Hacı – MUSTAFA BALCIdan doğuşa verilen-2007 | B10: 50000 | C10: 1.31 | D10: =B10/C10 -> 38167.939 | E10: =E6+D10*-1 -> 138199.71
A11: Hacı – Doğuş kapanırken hacının ödediği-2017 | B11: ='01-01-DGS'!F64*-1 -> 272920.1 | C11: 3.55 | D11: =B11/C11 -> 76878.901 | E11: =E10+D11*-1 -> 61320.81
A12: DOĞUŞ KAPANIŞ BORÇ TOPLAMI | B12: =SUM(B10:B11) -> 322920.1 | D12: =SUM(D10:D11) -> 115046.84 | E12: =E11 -> 61320.81
E13: =E12 -> 61320.81
D14: Borç – alacak tahsilatı yapılabilseydi doğuş kapanışta kalan sermaye | E14: =E13 -> 61320.81
A16: doğuş hesabından hacıya düşen hisse | D16: =E14/2 -> 30660.405
A17: doğuş hesabından nazana düşen hisse | D17: =D16 -> 30660.405
A20: İnşaat HESABI
B21: Nazanın fazladan aldığı ,nşaat hissesi – Daire ½ | C21: 40000 | D21: 1.4 | E21: =C21/D21 -> 28571.429
B22: Hacının fazladan aldığı dükkan hissesi – Dükkan ½ | C22: 15000 | D22: 1.4 | E22: =C22/D22*-1 -> -10714.286
D23: İnşaat hesabından hacının alacağı | E23: =SUM(E21:E22) -> 17857.143
A27: nazanın toplam borcu | C27: hakandan | D27: =D4*-1 -> -99488.749 | E27: =D27 -> -99488.749
C28: doğuştan | D28: =D5*-1 -> -39877.056 | E28: =E27+D28 -> -139365.81
C29: inşaattan | D29: =E23*-1 -> -17857.143 | E29: =E28+D29 -> -157222.95
E30: =E29+D30 -> -157222.95
C31: nazanın doğuş kapanışta doğuşun varlığının yarısı | D31: =D16 -> 30660.405 | E31: =E30+D31 -> -126562.54
E32: =E31+D32 -> -126562.54
C33: nazanın toplam borcu = hakan + doğuş kapanış + inşaat hesabı | E33: =E32+D33 -> -126562.54
C34: hakanın doğuşa olan toplam borç içindeki payı | D34: =D4/E33 -> -0.78608368

Sheet 1203-YZD
E1: 45234
D3: 1203 m2 SANAYİ Arsa Değeri | E3: 450000
D4: Nazan | E4: Hacı
C6: 2007 hisse oranları | D6: 0.5 | E6: 0.5
C7: 2007 hisse değerleri | D7: =E3*0.5 -> 225000 | E7: =E3*0.5 -> 225000
C9: 2017 DOĞUŞ hesap kapama sonucu | D9: ='01-02-DGS'!E33 -> -126562.54 | E9: =D9*-1 -> 126562.54
D10: nazanın borcu arsa hissesinden düşüldü I V | E10: hacının alacağı arsa hissesine eklendi I V
C11: 2017 hesap sonrası hisse değerleri | D11: =SUM(D7:D9) -> 98437.457 | E11: =SUM(E7:E9) -> 351562.54
C12: 2017 hesap sonrası hisse oranları | D12: =D11/E3 -> 0.2187499 | E12: =E11/E3 -> 0.7812501
D13: '[02-23-sny.ods]02-13-BAKIYE'!$AC$28 | E13: 2019-22 kira gelirlerini hacı tahsil etti I V
C14: 2019-22 kira gelirleri | D14: 7485.3 | E14: =D14*-1 -> -7485.3
C15: 2019-22 kira gelirleri % si | D15: =D18-D12 -> 0.016634 | E15: =E18-E12 -> -0.016634
D16: hacının tahsil ettiği 2019-22 kira gelirleri nazanın hissesine eklendi I V | E16: 2019-22 kira gelirleri hacının hissesinden düşüldü I V
C17: 2022 kira gelirleri eklenmiş hisse değerleri | D17: =D11+D14 -> 105922.76 | E17: =E11+E14 -> 344077.24
C18: 2022 kira gelirleri eklenmiş hisse oranları | D18: =D17/E3 -> 0.2353839 | E18: =E17/E3 -> 0.7646161
B20: 2023 ve sonrası hesaplar için uygulanacak
B21: SON HİSSE ORANLARI | D21: =D18 -> 0.2353839 | E21: =E18 -> 0.7646161
B23: 2023 kira gelirleri SON HİSSE ORANLARINA GÖRE HESAPLANARAK
B24: OCAK 2024 tarihinden itibaren NAZANın hesabına havale edilmeye başlandı
B26: Arsa değeri yan arsanın satış rakamı baz alınatak belirlenmiştir.
B27: Niğdeli, 2007 de Altıngövde den 700.000 TL ye satın aldı.
B28: Dolar olarak değeri 450,000 USD.
