Workbook

Sheet TPLM
A6: 2024 | B6: Ödeme Teminat Tablosu | F6: Alınan
C7: Tutar | D7: Ödeme | E7: Kalan | F7: Teminat
A8: SnyA | B8: Yıkamacı samed | C8: ='SnyA105-22'!E4 -> 45000 | D8: ='SnyA105-22'!F4 -> 0 | E8: =C8-D8 -> 45000 | F8: ='SnyA105-22'!E6 -> 0
A9: SnyB | B9: Motorcu salih | C9: ='SnyB202-22'!D4 -> 170000 | D9: ='SnyB202-22'!E4 -> 170000 | E9: =C9-D9 -> 0 | F9: ='SnyB202-22'!D6 -> -1225.58
A10: SnyCD | B10: Hurdacı ali | C10: ='SnyC301-22'!E4 -> 162230 | D10: ='SnyC301-22'!F4 -> 135000 | E10: =C10-D10 -> 27230 | F10: ='SnyC301-22'!E6 -> -4079.59
A11: SnyE | B11: Motorcu cihan | C11: ='SnyE502-22'!D4 -> 7000 | D11: ='SnyE502-22'!E4 -> 0 | E11: =C11-D11 -> 7000 | F11: ='SnyE502-22'!D6 -> -794.6
A12: SnyF | B12: Demirci merdal | C12: ='SnyF601-22'!E4 -> 447218.54 | D12: ='SnyF601-22'!F4 -> 184917.52 | E12: =C12-D12 -> 262301.02 | F12: ='SnyF601-22'!E6 -> -2824.53
A13: SnyG | B13: Motorcu Metin | C13: ='SnyG702-22'!D4 -> 51000 | D13: ='SnyG702-22'!E4 -> 0 | E13: =C13-D13 -> 51000 | F13: ='SnyG702-22'!D6 -> -1200
A14: SnyH | B14: Yazıhane | C14: =SnH_yazıhane!F2*-1 -> -3999.1 | D14: =C14 -> -3999.1 | E14: =C14-D14 -> 0
B16: Toplamlar | C16: =SUM(C8:C14) -> 878449.44 | D16: =SUM(D8:D14) -> 485918.42 | E16: =SUM(E8:E14) -> 392531.02 | F16: =SUM(F8:F14) -> -10124.3
A19: 2025 | B19: Ödeme Teminat Tablosu | F19: Alınan
C20: Tutar | D20: Ödeme | E20: Kalan | F20: Teminat
A21: SnyA | B21: Yıkamacı samed | C21: 150 | D21: 0 | E21: =C21-D21 -> 150 | F21: ='SnyA105-22'!E19 -> 0
A22: SnyB | B22: Motorcu salih | C22: 250 | D22: 0 | E22: =C22-D22 -> 250 | F22: ='SnyB202-22'!D19 -> 0
A23: SnyC | C23: 170 | D23: ='SnyC301-22'!F18 -> 0 | E23: =C23-D23 -> 170 | F23: ='SnyC301-22'!E20 -> 0
A24: SnyD | C24: 170 | D24: 0 | E24: =C24-D24 -> 170
A25: SnyE | B25: Motorcu cihan | C25: 170 | D25: ='SnyE502-22'!E17 -> 0 | E25: =C25-D25 -> 170 | F25: ='SnyE502-22'!D19 -> 0
A26: SnyF | B26: Demirci merdal | C26: 170 | D26: ='SnyF601-22'!F17 -> 0 | E26: =C26-D26 -> 170 | F26: ='SnyF601-22'!#REF! -> #REF!
A27: SnyG | B27: Motorcu Metin | C27: 170 | D27: ='SnyG702-22'!E17 -> 0 | E27: =C27-D27 -> 170 | F27: ='SnyG702-22'!D19 -> 0
A28: SnyH | B28: Yazıhane | C28: =SnH_yazıhane!F15*-1 -> 0 | D28: =C28 -> 0 | E28: =C28-D28 -> 0
B30: Toplamlar | C30: =SUM(C21:C28) -> 1250 | D30: =SUM(D21:D28) -> 0 | E30: =SUM(E21:E28) -> 1250 | F30: =SUM(F21:F28) -> #REF!

Sheet SnyA105-22
B1: snA-086-20230930-080-samedTURGUT | G1: 55 m2 Boya
A3: Tarih | B3: Açıklama | E3: Kira bedeli | F3: Ödeme | G3: Bakiye
B4: Toplamlar | E4: =SUM(E9:E20) -> 45000 | F4: =SUM(F9:F20) -> 0 | G4: =G20 -> 45000
B5: Masraf | E5: =G40 -> 0
B6: Teminat | E6: =G37 -> 0
F7: NET | G7: =F4-E5 -> 0
B8: ,
A9: 45197 | B9: 30-09-2024 – 31-12-2024 | E9: 45000 | G9: =E9-F9 -> 45000
B10: 15000*3 ay | G10: =E10-F10+G9 -> 45000
G11: =E11-F11+G10 -> 45000
G12: =E12-F12+G11 -> 45000
G13: =E13-F13+G12 -> 45000
G14: =E14-F14+G13 -> 45000
G15: =E15-F15+G14 -> 45000
G16: =E16-F16+G15 -> 45000
G17: =E17-F17+G16 -> 45000
G18: =E18-F18+G17 -> 45000
G19: =E19-F19+G18 -> 45000
G20: =E20-F20+G19 -> 45000
A23: - 2023 - | B23: ELEKTRİK (kendi abonesi var) | D23: Su (ödenmiş yazar) | E23: Tutarı | G23: ( 0 TL )
A24: 44927 | B24: Devreden Teminat | D24: 2137.3 | G24: 0
A25: Ocak | B25: 200 TL su alımı 08-01-24 | C25: 24.8 | D25: =D24+C25 -> 2162.1 | G25: =E25-F25+G24 -> 0
A26: Şubat | B26: ortak hesaptan ödeme 08-01-24 | C26: -21.12 | D26: =D25+C26 -> 2140.98 | G26: =E26-F26+G25 -> 0
A27: Mart | B27: ortak hesaptan ödeme 18-03-24 | C27: -52.17 | D27: 2231.5 | G27: =E27-F27+G26 -> 0
A28: Nisan | G28: =E28-F28+G27 -> 0
A29: Mayıs | G29: =E29-F29+G28 -> 0
A30: Haziran | G30: =E30-F30+G29 -> 0
A31: Temmuz | G31: =E31-F31+G30 -> 0
A32: Ağustos | G32: =E32-F32+G31 -> 0
A33: Eylül | G33: =E33-F33+G32 -> 0
A34: Ekim | G34: =E34-F34+G33 -> 0
A35: Kasım | G35: =E35-F35+G34 -> 0
A36: Aralık | G36: =E36-F36+G35 -> 0
A37: 45291 | B37: Devreden Teminat | G37: =E37-F37+G36 -> 0
A40: snyA | B40: Açıklamalar-Masraflar | G40: =SUM(F41:F42) -> 0
A46: 45166 | B46: Ahmet ilterin devrettiği 3. şahıslardan devralmak için yanıma geldi
B47: Ödeme peşin olursa devralabileceğini söyledim
B48: Ödemeyi 01-09-2023 Cuma günü yapacağını ifade etti. Tamam dedim
A49: 45170 | B49: Ödeme yapılmadı
A50: 45174 | B50: Çağırdım. 3. şahıslarla kavga ettiklerini bana ödeyecekleri kira bedelini onlara, aldıklar
...

Sheet SnyB202-22
B1: SnyB203-22 | D1: 200 m2 Karo kira
A3: Tarih | B3: Açıklama | D3: Kira bedeli | E3: Ödeme | F3: Bakiye
B4: Toplamlar | D4: =SUM(D9:D20) -> 170000 | E4: =SUM(E9:E20) -> 170000 | F4: =F20 -> 0
B5: Masraf | D5: =F40 -> 0
B6: Teminat | D6: =F37 -> -1225.58
E7: NET | F7: =E4-D5 -> 170000
B8: ,
A9: 45291 | B9: 1-1-24 - 31-12-24 kira bedeli | F9: =D9-E9 -> 0
B10: kira bedeli 16 asgari ücret | F10: =D10-E10+F9 -> 0
B11: 2024 için 1 defalık bir önceki yıl asgari ücreti uygulandı | F11: =D11-E11+F10 -> 0
A12: 45295 | B12: 2025 te 2025 asgari ücret * 16 uygulanacak | F12: =D12-E12+F11 -> 0
A13: 45295 | B13: 11402 | C13: 16 | D13: =C13*B13 -> 182432 | F13: =D13-E13+F12 -> 182432
A14: 45295 | B14: indiirim | D14: -12432 | F14: =D14-E14+F13 -> 170000
A15: 45295 | B15: nakit ödeme | E15: 120000 | F15: =D15-E15+F14 -> 50000
A16: 45296 | B16: nakit ödeme | E16: 26000 | F16: =D16-E16+F15 -> 24000
A17: 45299 | B17: bankadan umuta | E17: 24000 | F17: =D17-E17+F16 -> 0
F18: =D18-E18+F17 -> 0
F19: =D19-E19+F18 -> 0
F20: =D20-E20+F19 -> 0
A23: - 2023 - | B23: ELEKTRİK | C23: Su | D23: Tutarı | F23: 1600
B24: Devreden Teminat | F24: -1000.12
B25: Su-Elektrik Ocak | C25: 0 | D25: 900.36 | E25: 999.4 | F25: =D25-E25+F24 -> -1099.16
B26: Su-Elektrik Şubat | C26: 0 | D26: 841.46 | E26: 967.88 | F26: =D26-E26+F25 -> -1225.58
B27: Su-Elektrik art | F27: =D27-E27+F26 -> -1225.58
B28: Su-Elektrik Nisan | F28: =D28-E28+F27 -> -1225.58
B29: Su-Elektrik Mayıs | F29: =D29-E29+F28 -> -1225.58
B30: Su-Elektrik Haziran | F30: =D30-E30+F29 -> -1225.58
B31: Su-Elektrik Temmuz | F31: =D31-E31+F30 -> -1225.58
B32: Su-Elektrik Ağustos | F32: =D32-E32+F31 -> -1225.58
B33: Su-Elektrik Eylül | F33: =D33-E33+F32 -> -1225.58
B34: Su-Elektrik Ekim | F34: =D34-E34+F33 -> -1225.58
B35: Su-Elektrik Kasım | F35: =D35-E35+F34 -> -1225.58
B36: Su-Elektrik Aralık | F36: =D36-E36+F35 -> -1225.58
A37: 45291 | B37: Devreden Teminat | C37: =SUM(C25:C36) -> 0 | F37: =D37-E37+F36 -> -1225.58
F38: KALAN
A40: snyB | B40: Açıklamalar-Masraflar | F40: =SUM(E41:E57) -> 0
B46: Salih Ant - 2.yıl
B47: 3. yıl yıllık kira bedeli 16 asgari ücret uygulanacak
B48: 01-01-23 - 31-12-23 kira bedeli | D48: 170000
B50: Salih Ant - 1.yıl
...

Sheet SnyC301-22
B1: snCD-080-03-2211-Vinc | E1: 400 m2 Vinç kira
A3: Tarih | B3: Açıklama | C3: Tüfe % | E3: Kira bedeli | F3: Ödeme | G3: Bakiye
B4: Toplamlar | E4: =SUM(E9:E21) -> 162230 | F4: =SUM(F9:F21) -> 135000 | G4: =G21 -> 27230
B5: Masraf | E5: =G53 -> 0
B6: Teminat | E6: =G50 -> -4079.59
F7: NET | G7: =F4-E5 -> 135000
B8: Tahliye için icraya başvuruldu
A9: 45259 | G9: =E9-F9 -> 0
D10: =C10*E9 -> 0 | E10: =D10+E9 -> 0 | G10: =E10-F10+G9 -> 0
B11: Aralık | E11: 20000 | G11: =E11-F11+G10 -> 20000
B12: Ödeme Umuta bankadan | F12: 135000 | G12: =E12-F12+G11 -> -115000
A13: - 2024 - | B13: 45292 | D13: =C13*E11 -> 0 | E13: =D13+E11 -> 20000 | G13: =E13-F13+G12 -> -95000
B14: Şubat | D14: =C14*E13 -> 0 | E14: =D14+E13 -> 20000 | G14: =E14-F14+G13 -> -75000
B15: Mart | D15: =C15*E14 -> 0 | E15: =D15+E14 -> 20000 | G15: =E15-F15+G14 -> -55000
B16: Nisan | D16: =C16*E15 -> 0 | E16: =D16+E15 -> 20000 | G16: =E16-F16+G15 -> -35000
B17: Mayıs | D17: =C17*E16 -> 0 | E17: =D17+E16 -> 20000 | G17: =E17-F17+G16 -> -15000
B18: Haziran | C18: 0.03 | D18: =C18*E17 -> 600 | E18: =D18+E17 -> 20600 | G18: =E18-F18+G17 -> 5600
B19: Temmuz | C19: 0.05 | D19: =C19*E18 -> 1030 | E19: =D19+E18 -> 21630 | G19: =E19-F19+G18 -> 27230
B20: Ağustos | G20: =E20-F20+G19 -> 27230
B21: Eylül | G21: =E21-F21+G20 -> 27230
B22: Ekim
B23: Kasım
B24: Aralık
A25: - 2025 - | B25: Ocak
B26: Şubat
B27: Mart
A37: - 2023 - | B37: ELEKTRİK | D37: Su | E37: Tutarı | G37: 3000
B38: Devreden Teminat | G38: -3924.11
B39: Su-Elektrik Ocak | D39: 0 | E39: 875.64 | F39: 875.64 | G39: =E39-F39+G38 -> -3924.11
B40: Su-Elektrik Şubat | D40: 0 | E40: 1036.52 | F40: 1192 | G40: =E40-F40+G39 -> -4079.59
B41: Su-Elektrik art | G41: =E41-F41+G40 -> -4079.59
B42: Su-Elektrik Nisan | G42: =E42-F42+G41 -> -4079.59
B43: Su-Elektrik Mayıs | G43: =E43-F43+G42 -> -4079.59
B44: Su-Elektrik Haziran | G44: =E44-F44+G43 -> -4079.59
B45: Su-Elektrik Temmuz | G45: =E45-F45+G44 -> -4079.59
B46: Su-Elektrik Ağustos | G46: =E46-F46+G45 -> -4079.59
B47: Su-Elektrik Eylül | G47: =E47-F47+G46 -> -4079.59
B48: Su-Elektrik Ekim | G48: =E48-F48+G47 -> -4079.59
B49: Su-Elektrik Kasım | G49: =E49-F49+G48 -> -4079.59
B50: Su-Elektrik Aralık | G50: =E50-F50+G49 -> -4079.59
...

Sheet SnyCD-HSP
B1: - 2024 - 2025
A3: SNYCD-HESAP | F3: =SUM(F7:F60) -> 523609.11 | G3: =SUM(G7:G60) -> 354000 | H3: =F3-G3 -> 169609.11
E4: kira tüfe farkı
A5: Tarih | B5: Açıklama | C5: Tüfe endeks | D5: Tüfe % | E5: Bedel | F5: bedel | G5: Ödeme | H5: Bakiye
H6: =H7+F6-G6 -> 169609.11
H7: =H8+F7-G7 -> 169609.11
H8: =H9+F8-G8 -> 169609.11
H9: =H10+F9-G9 -> 169609.11
H10: =H11+F10-G10 -> 169609.11
H11: =H12+F11-G11 -> 169609.11
H12: =H13+F12-G12 -> 169609.11
B13: 2025 - 4/12 mart | E13: =E15+E14 -> 49910.621 | F13: =E13 -> 49910.621 | H13: =H14+F13-G13 -> 169609.11
A14: 45716 | B14: tüfe 2025-02 | C14: 3000 | D14: =(C14/C17)-1 -> 0.034482759 | E14: =F15*D14 -> 1663.6874 | F14: =H15*D14 -> 3989.9496 | H14: =H15+F14-G14 -> 119698.49
B15: 2025 - 3/12 şubat | E15: =E18+E17 -> 48246.934 | F15: =E15 -> 48246.934 | H15: =H16+F15-G15 -> 115708.54
B16: dava rededildi karşı avukat ücreti | F16: 18000 | H16: =H17+F16-G16 -> 67461.603
A17: 45687 | B17: tüfe 2025-01 | C17: 2900 | D17: =(C17/C19)-1 -> 0.035714286 | E17: =F18*D17 -> 1663.6874 | F17: =H18*D17 -> 1705.5725 | H17: =H18+F17-G17 -> 49461.603 | J17: 45677
B18: 2025 - 2/12 ocak | E18: =E20+E19 -> 46583.246 | F18: =E18 -> 46583.246 | H18: =H19+F18-G18 -> 47756.031
A19: 45656 | B19: tüfe 2024-12 | C19: 2800 | D19: =(C19/C23)-1 -> 0.053728883 | E19: =F20*D19 -> 2375.2465 | F19: =IF(H20<=0,,(H20*D19)) -> 59.79943 | H19: =H20+F19-G19 -> 1172.7842
B20: 2025 - 1/12 aralık | E20: 44208 | F20: =E20 -> 44208 | H20: =H21+F20-G20 -> 1112.9848
B21: 240000* % 60 tüfe | G21: 219000 | H21: =H22+F21-G21 -> -43095.015 | I21: 240 | J21: 60 | K21: =I21*J21/100 -> 144
B22: keşif harç masraf için emrullaha havale | F22: 7080 | H22: =H23+F22-G22 -> 175904.98 | K22: =K21+I21 -> 384
A23: 45626 | B23: tüfe 11 | C23: 2657.23 | D23: =(C23/C25)-1 -> 0.022440177 | E23: =C23 -> 2657.23 | F23: =H24*D23 -> 3705.3146 | H23: =H24+F23-G23 -> 168824.98 | K23: =K22/12 -> 32
B24: 2024 - 12/12 Kasım | E24: =E26+E25 -> 28469.069 | F24: =E24 -> 28469.069 | H24: =H25+F24-G24 -> 165119.67
A25: 45595 | B25: tüfe 10 | C25: 2598.91 | D25: =(C25/C27)-1 -> 0.028798651 | E25: =F26*D25 -> 796.92054 | F25: =H26*D25 -> 3825.1926 | H25: =H26+F25-G25 -> 136650.6 | I25: adet | J25: asg ücret | K25: yıllık
B26: 2023-2024 - 11/12 Ekim | E26: =E28+E27 -> 27672.148 | F26: =E26 -> 27672.148 | H26: =H27+F26-G26 -> 132825.41 | I26: 24 | J26: 22104 | K26: =J26*I26 -> 530496
A27: 45565 | B27: tüfe 9 | C27: 2526.16 | D27: =(C27/C29)-1 -> 0.029681985 | E27: =F28*D27 -> 797.68734 | F27: =IF(H28<=0,,(H28*D27)) -> 3031.1858 | H27: =H28+F27-G27 -> 105153.26 | K27: =K26/12 -> 44208
B28: 2023 - 2024 10/12 Eylül | E28: =E30+E29 -> 26874.461 | F28: =E28 -> 26874.461 | H28: =H29+F28-G28 -> 102122.07 | K28: aylık
A29: 45534 | B29: tüfe 8 | C29: 2453.34 | D29: =(C29/C31)-1 -> 0.024744163 | E29: =F30*D29 -> 648.92884 | F29: =IF(H30<=0,,(H30*D29)) -> 1816.9796 | H29: =H30+F29-G29 -> 75247.613
B30: 2023-2024 - 9/12 Ağustos | E30: =E32+E31 -> 26225.532 | F30: =E30 -> 26225.532 | H30: =H31+F30-G30 -> 73430.634
A31: 45503 | B31: tüfe 7 | C31: 2394.1 | D31: =(C31/C33)-1 -> 0.032255561 | E31: =F32*D31 -> 819.48626 | F31: =IF(H32<=0,,(H32*D31)) -> 1475.0485 | H31: =H32+F31-G31 -> 47205.102
B32: 2023-2024 - 8/12 Temmuz | E32: =E34+E33 -> 25406.046 | F32: =E32 -> 25406.046 | H32: =H33+F32-G32 -> 45730.053
A33: 45473 | B33: tüfe 6 | C33: 2319.29 | D33: =(C33/C35)-1 -> 0.016407739 | E33: =F34*D33 -> 410.12653 | F33: =IF(H34<=0,,(H34*D33)) -> 328.08783 | H33: =H34+F33-G33 -> 20324.007
B34: 2023-2024 - 7/12 Haziran | E34: =E36+E35 -> 24995.919 | F34: =E34 -> 24995.919 | H34: =H35+F34-G34 -> 19995.919
A35: 45442 | B35: tüfe 5 | C35: 2281.85 | D35: =(C35/C37)-1 -> 0.033680634 | E35: =F36*D35 -> 673.61268 | F35: =IF(H36<=0,,(H36*D35)) -> 0 | H35: =H36+F35-G35 -> -5000
B36: 2023-2024 - 6/12 Mayıs | E36: =E38+E37 -> 24322.307 | F36: =F38 -> 20000 | H36: =H37+F36-G36 -> -5000
A37: 45412 | B37: tüfe 4 | C37: 2207.5 | D37: =(C37/C39)-1 -> 0.031797595 | E37: =F38*D37 -> 635.95189 | F37: =IF(H38<=0,,(H38*D37)) -> 0 | H37: =H38+F37-G37 -> -25000
B38: 2023-2024 - 5/12 Nisan | E38: =E40+E39 -> 23686.355 | F38: =F40 -> 20000 | H38: =H39+F38-G38 -> -25000
A39: 45381 | B39: tüfe 3 | C39: 2139.47 | D39: =(C39/C41)-1 -> 0.031626709 | E39: =E40*D39 -> 726.15555 | F39: =IF(H40<=0,,(H40*D39)) -> 0 | H39: =H40+F39-G39 -> -45000
B40: 2023-2024 - 4/12 Mart | E40: =E42+E41 -> 22960.199 | F40: =F42 -> 20000 | H40: =H41+F40-G40 -> -45000
A41: 45351 | B41: tüfe 2 | C41: 2073.88 | D41: =(C41/C43)-1 -> 0.045291882 | E41: =E42*D41 -> 994.85192 | F41: =IF(H42<=0,,(H42*D41)) -> 0 | H41: =H42+F41-G41 -> -65000
...

Sheet SnyE503-24
B1: SnyE.30.20240606.091 - SULEYMAN AKAN | F1: 100 m2 ESTE
A3: Tarih | B3: Açıklama | D3: Kira bedeli | E3: Ödeme | F3: Bakiye
B4: Toplamlar | D4: =SUM(D9:D20) -> 204024 | E4: =SUM(E9:E20) -> 204024 | F4: =F20 -> 0
B5: Masraf | D5: =F40 -> 0
B6: Teminat | D6: =F37 -> -800
E7: NET | F7: =E4-D5 -> 204024
B8: ,
A9: 45167 | B9: 06-06-2024-05-06-2025 Bedeli | D9: 204024 | F9: =D9-E9 -> 204024
B10: nakit | E10: 1000 | F10: =D10-E10+F9 -> 203024
B11: nakit | E11: 50000 | F11: =D11-E11+F10 -> 153024
B12: işbank umut ortak hesap | E12: 33000 | F12: =D12-E12+F11 -> 120024
B13: indirim | E13: 24 | F13: =D13-E13+F12 -> 120000
B14: nakit | E14: 120000 | F14: =D14-E14+F13 -> 0
F15: =D15-E15+F14 -> 0
F16: =D16-E16+F15 -> 0
F17: =D17-E17+F16 -> 0
F18: =D18-E18+F17 -> 0
F19: =D19-E19+F18 -> 0
F20: =D20-E20+F19 -> 0
A23: - 2023 - | B23: ELEKTRİK | C23: Su | D23: Tutarı | F23: ( 1000 TL )
B24: Devreden Teminat | F24: -800
B25: Su-Elektrik Ocak | C25: 0 | F25: =D25-E25+F24 -> -800
B26: Su-Elektrik Şubat | C26: 0 | F26: =D26-E26+F25 -> -800
B27: Su-Elektrik art | F27: =D27-E27+F26 -> -800
B28: Su-Elektrik Nisan | F28: =D28-E28+F27 -> -800
B29: Su-Elektrik Mayıs | F29: =D29-E29+F28 -> -800
B30: Su-Elektrik Haziran | F30: =D30-E30+F29 -> -800
B31: Su-Elektrik Temmuz | F31: =D31-E31+F30 -> -800
B32: Su-Elektrik Ağustos | F32: =D32-E32+F31 -> -800
B33: Su-Elektrik Eylül | F33: =D33-E33+F32 -> -800
B34: Su-Elektrik Ekim | F34: =D34-E34+F33 -> -800
B35: Su-Elektrik Kasım | F35: =D35-E35+F34 -> -800
B36: Su-Elektrik Aralık | F36: =D36-E36+F35 -> -800
A37: 45291 | B37: Devreden Teminat | C37: =SUM(C25:C36) -> 0 | F37: =D37-E37+F36 -> -800
A40: snyE | B40: Açıklamalar-Masraflar | F40: =SUM(E41:E49) -> 0
B42: Motorcu
A43: 45402 | B43: Süleyman AKAN
B44: 24-25 kira bedeli | D44: 204024
A45: 45402 | B45: Anlaşma yapıldı
A47: 45449 | B47: Kira Başlangıç Tarihi
...

Sheet SnyE502-22
B1: 085-20230830-SNYE-02-SZL CIHAN CAM | F1: 100 m2 ESTE
A3: Tarih | B3: Açıklama | D3: Kira bedeli | E3: Ödeme | F3: Bakiye
B4: Toplamlar | D4: =SUM(D9:D20) -> 7000 | E4: =SUM(E9:E20) -> 0 | F4: =F20 -> 7000
B5: Masraf | D5: =F40 -> 0
B6: Teminat | D6: =F37 -> -794.6
E7: NET | F7: =E4-D5 -> 0
B8: ,
A9: 45167 | F9: =D9-E9 -> 0
F10: =D10-E10+F9 -> 0
F11: =D11-E11+F10 -> 0
F12: =D12-E12+F11 -> 0
F13: =D13-E13+F12 -> 0
F14: =D14-E14+F13 -> 0
A15: 44956 | B15: Kira Bedeli senet 5/5 7000 senet | C15: 45322 | D15: 7000 | F15: =D15-E15+F14 -> 7000
F16: =D16-E16+F15 -> 7000
F17: =D17-E17+F16 -> 7000
F18: =D18-E18+F17 -> 7000
F19: =D19-E19+F18 -> 7000
F20: =D20-E20+F19 -> 7000
A23: - 2023 - | B23: ELEKTRİK | C23: Su | D23: Tutarı | F23: ( 1000 TL )
B24: Devreden Teminat | F24: -800
B25: Su-Elektrik Ocak | C25: 0 | D25: 381.33 | E25: 431.36 | F25: =D25-E25+F24 -> -850.03
B26: Su-Elektrik Şubat | C26: 0 | D26: 237.14 | E26: 237.11 | F26: =D26-E26+F25 -> -850
B27: Su-Elektrik art | D27: 55.4 | F27: =D27-E27+F26 -> -794.6
B28: Su-Elektrik Nisan | F28: =D28-E28+F27 -> -794.6
B29: Su-Elektrik Mayıs | F29: =D29-E29+F28 -> -794.6
B30: Su-Elektrik Haziran | F30: =D30-E30+F29 -> -794.6
B31: Su-Elektrik Temmuz | F31: =D31-E31+F30 -> -794.6
B32: Su-Elektrik Ağustos | F32: =D32-E32+F31 -> -794.6
B33: Su-Elektrik Eylül | F33: =D33-E33+F32 -> -794.6
B34: Su-Elektrik Ekim | F34: =D34-E34+F33 -> -794.6
B35: Su-Elektrik Kasım | F35: =D35-E35+F34 -> -794.6
B36: Su-Elektrik Aralık | F36: =D36-E36+F35 -> -794.6
A37: 45291 | B37: Devreden Teminat | C37: =SUM(C25:C36) -> 0 | F37: =D37-E37+F36 -> -794.6
A40: snyE | B40: Açıklamalar-Masraflar | F40: =SUM(E41:E54) -> 0
B42: Motorcu
A43: 44774 | B43: Cihan Çam
B44: 22-23 kira bedeli ödendi | D44: 45000
A45: 44774 | B45: Anlaşma yapıldı
A47: 44803 | B47: Kira Başlangıç Tarihi
...

Sheet SnyF601-22
B1: 082-SnF-02-230101-merdalKipel | G1: 100 m2 ESTE
A3: Tarih | B3: Açıklama | D3: Bedel | E3: Tutar | F3: Ödeme | G3: Bakiye
B4: Toplamlar | E4: =SUM(E9:E39) -> 447218.54 | F4: =SUM(F9:F39) -> 184917.52 | G4: =#REF! -> #REF!
B5: Masraf | E5: =G59 -> 0
B6: Teminat | E6: =G56 -> -2824.53
A7: - 2024 - | F7: NET | G7: =F4-E5 -> 184917.52
B8: ,
A9: 44957 | B9: Ocak | C9: 6.65 | E9: 6920 | F9: 6920 | G9: =E9-F9 -> 0
B10: Şubat | C10: 3.15 | E10: =E9+(E9*C9/100) -> 7380.18 | G10: =E10-F10+G9 -> 7380.18
B11: Mart | C11: 2.29 | E11: =E10+(E10*C10/100) -> 7612.6557 | G11: =E11-F11+G10 -> 14992.836
B12: Nisan avukattan 13000 den | C12: 2.39 | E12: =E11+(E11*C11/100) -> 7786.9855 | F12: 8425.46 | G12: =E12-F12+G11 -> 14354.361
B13: Mayıs 0,04 | C13: 0.04 | E13: =E12+(E12*C12/100) -> 7973.0944 | F13: 28080 | G13: =E13-F13+G12 -> -5752.5444
B14: Haziran | C14: 3.92 | E14: =E13+(E13*C13/100) -> 7976.2837 | G14: =E14-F14+G13 -> 2223.7393
B15: Temmuz | C15: 9.49 | E15: =E14+(E14*C14/100) -> 8288.954 | F15: 50000 | G15: =E15-F15+G14 -> -39487.307
B16: Ağustos | C16: 9.09 | E16: =E15+(E15*C15/100) -> 9075.5757 | G16: =E16-F16+G15 -> -30411.731
B17: Eylül 4,75 | C17: 4.75 | E17: =E16+(E16*C16/100) -> 9900.5456 | G17: =E17-F17+G16 -> -20511.185
B18: Ekim | C18: 3.43 | E18: =E17+(E17*C17/100) -> 10370.821 | G18: =E18-F18+G17 -> -10140.364
A19: 45260 | B19: Kasım - Aralık dahil hesap sıfırlandı | C19: 42.6451 | E19: =E18+(E18*C18/100) -> 10726.541 | F19: 15887.06 | G19: =E19-F19+G18 -> -15300.883
A20: 45291 | B20: Aralık | C20: 2.93 | E20: =E19+(E19*C19/100) -> 15300.885 | G20: =E20-F20+G19 -> 0.0013347145
A22: 45322 | B22: Ocak | C22: 6.71 | E22: 17002 | G22: =E22-F22+G20 -> 17002.001
B23: Şubat | C23: 4.53 | E23: =E22+(E22*C22/100) -> 18142.834 | G23: =E23-F23+G22 -> 35144.836
B24: Mart | C24: 3.16 | E24: =E23+(E23*C23/100) -> 18964.705 | G24: =E24-F24+G23 -> 54109.54
B25: Kira vergi farkı | F25: -3795 | G25: =E25-F25+G24 -> 57904.54
A26: 45397 | B26: Nisan | C26: 3.18 | E26: =E24+(E24*C24/100) -> 19563.989 | F26: 85000 | G26: =E26-F26+G25 -> -7531.4706
B27: icra masrafı | F27: -5600 | G27: =E27-F27+G26 -> -1931.4706
B28: Mayıs | C28: 3.37 | E28: =E26+(E26*C26/100) -> 20186.124 | G28: =E28-F28+G27 -> 18254.653
B29: Haziran | C29: 3.6 | E29: =E28+(E28*C28/100) -> 20866.396 | G29: =E29-F29+G28 -> 39121.05
B30: Temmuz | C30: 3.6 | E30: =E29+(E29*C29/100) -> 21617.587 | G30: =E30-F30+G29 -> 60738.637
B31: Ağustos | E31: =E30+(E30*C30/100) -> 22395.82 | G31: =E31-F31+G30 -> 83134.457
B32: Eylül | E32: =E31+(E31*C31/100) -> 22395.82 | G32: =E32-F32+G31 -> 105530.28
B33: Ekim | E33: =E32+(E32*C32/100) -> 22395.82 | G33: =E33-F33+G32 -> 127926.1
B34: Kasım | E34: =E33+(E33*C33/100) -> 22395.82 | G34: =E34-F34+G33 -> 150321.92
B35: Aralık | E35: =E34+(E34*C34/100) -> 22395.82 | G35: =E35-F35+G34 -> 172717.74
B36: Ocak | E36: =E35+(E35*C35/100) -> 22395.82 | G36: =E36-F36+G35 -> 195113.56
B37: Şubat | E37: =E36+(E36*C36/100) -> 22395.82 | G37: =E37-F37+G36 -> 217509.38
B38: Mart | E38: =E37+(E37*C37/100) -> 22395.82 | G38: =E38-F38+G37 -> 239905.2
B39: Nisan | E39: =E38+(E38*C38/100) -> 22395.82 | G39: =E39-F39+G38 -> 262301.02
A42: =A7 -> - 2024 - | B42: ELEKTRİK | C42: Su | E42: Tutarı | G42: ( 3100 TL )
B43: Devreden Teminat | G43: -2510.63
B44: Su-Elektrik Ocak | C44: 0 | E44: 781.86 | F44: 891.32 | G44: =E44-F44+G43 -> -2620.09
...

Sheet snyF-HSP
C4: 31-3-2022 Asgari ücret 4253 TL - 48000TL = 12 asgari ücret
C6: 31-3-2022 - 31-12-2022 9 aylık tutar | E6: 48000 | H6: =I4+E6-G6 -> 48000
B7: 44651 | C7: Nakit Ödeme | G7: 28000 | H7: =H6+E7-G7 -> 20000
B8: 44681 | C8: 10-05-2022 - 4000 nakit ödeme | G8: 4000 | H8: =H7+E8-G8 -> 16000
B9: 44711 | C9: 20-06-2022 - 4000 nakit ödeme | G9: 4000 | H9: =H8+E9-G9 -> 12000
B10: 44742 | C10: Ödeme yapılmadı 4000 Ocak 2023 ödenmedi | H10: =H9+E10-G10 -> 12000
B11: 44772 | C11: Ödeme yapılmadı 4000 Şubat 2023 ödenmedi | H11: =H10+E11-G11 -> 12000
B12: 44803 | C12: Ödeme yapılmadı 4000 Mart 2023 ödenmedi | H12: =H11+E12-G12 -> 12000
B14: Son 3 ayın ödemesi yapılmadığı için (3x4000) ilk kira dönemi Nisan Aralık olarak kapatıldı
B15: Ocak 2023 ile yeni fiyat (6920) ve yeni dönem uygulandı | E15: aylık kira
D16: tüfe | E16: bedeli | F16: ödenecek | G16: ödeme | H16: bakiye
B17: 44957 | C17: Ocak | D17: 6.65 | E17: 6920 | G17: 6920 | H17: =E17-G17 -> 0
C18: Şubat | D18: 3.15 | E18: =E17+(E17*D17/100) -> 7380.18 | F18: =E18 -> 7380.18 | H18: =F18-G18+H17 -> 7380.18
C19: Mart | D19: 2.29 | E19: =E18+(E18*D18/100) -> 7612.6557 | F19: =E19 -> 7612.6557 | H19: =F19-G19+H18 -> 14992.836
C20: Nisan avukattan 13000 den | D20: 2.39 | E20: =E19+(E19*D19/100) -> 7786.9855 | F20: =E20 -> 7786.9855 | G20: 8425.46 | H20: =F20-G20+H19 -> 14354.361
C21: Mayıs 0,04 | D21: 0.04 | E21: =E20+(E20*D20/100) -> 7973.0944 | F21: =E21 -> 7973.0944 | G21: 28080 | H21: =F21-G21+H20 -> -5752.5444
C22: Haziran | D22: 3.92 | E22: =E21+(E21*D21/100) -> 7976.2837 | F22: =E22 -> 7976.2837 | H22: =F22-G22+H21 -> 2223.7393
C23: Temmuz | D23: 9.49 | E23: =E22+(E22*D22/100) -> 8288.954 | F23: =E23 -> 8288.954 | G23: 50000 | H23: =F23-G23+H22 -> -39487.307
C24: Ağustos | D24: 9.09 | E24: =E23+(E23*D23/100) -> 9075.5757 | F24: =E23 -> 8288.954 | H24: =F24-G24+H23 -> -31198.353
C25: Eylül 4,75 | D25: 4.75 | E25: =E24+(E24*D24/100) -> 9900.5456 | F25: =E23 -> 8288.954 | H25: =F25-G25+H24 -> -22909.399
C26: Ekim | D26: 3.43 | E26: =E25+(E25*D25/100) -> 10370.821 | F26: =E23 -> 8288.954 | H26: =F26-G26+H25 -> -14620.445
C27: Kasım | D27: 3.28 | E27: =E26+(E26*D26/100) -> 10726.541 | F27: =E23 -> 8288.954 | G27: 15887.06 | H27: =F27-G27+H26 -> -22218.551
B28: 45291 | C28: Aralık | D28: 2.93 | E28: =E27+(E27*D27/100) -> 11078.371 | F28: =E23 -> 8288.954 | H28: =F28-G28+H27 -> -13929.597
B29: 45322 | C29: Ocak yıllık 83160*57,5%=131->168 | D29: 6.71 | E29: 14000 | F29: =E23 -> 8288.954 | H29: =F29-G29+H28 -> -5640.6428
C30: Şubat | D30: 4.53 | E30: =E29+(E29*D29/100) -> 14939.4 | F30: =E30 -> 14939.4 | H30: =F30-G30+H29 -> 9298.7572
C31: Mart | D31: 3.16 | E31: =E30+(E30*D30/100) -> 15616.155 | F31: =E31 -> 15616.155 | H31: =F31-G31+H30 -> 24914.912
C32: Kira vergi farkı | E32: 3795 | F32: =E32 -> 3795 | H32: =F32-G32+H31 -> 28709.912
C33: icra masrafı | E33: 5600 | F33: =E33 -> 5600 | H33: =F33-G33+H32 -> 34309.912
C34: Sözleşme DV | E34: 278.97 | F34: =E34 -> 278.97 | H34: =F34-G34+H33 -> 34588.882
C35: Usulsüzlük cezası | E35: 10000 | F35: =E35 -> 10000 | H35: =F35-G35+H34 -> 44588.882
C36: Nisan | D36: 3.18 | E36: =E31+(E31*D31/100) -> 16109.625 | F36: =E36 -> 16109.625 | G36: 85000 | H36: =F36-G36+H35 -> -24301.493
C37: Mayıs | D37: 3.37 | E37: =E36+(E36*D36/100) -> 16621.911 | F37: =E36 -> 16109.625 | H37: =F37-G37+H36 -> -8191.8673
C38: Haziran | D38: 1.64 | E38: =E37+(E37*D37/100) -> 17182.07 | F38: =E37 -> 16621.911 | H38: =F38-G38+H37 -> 8430.0441
C39: Temmuz | D39: 3.23 | E39: =E38+(E38*D38/100) -> 17463.856 | F39: =E39 -> 17463.856 | H39: =F39-G39+H38 -> 25893.9
C40: Ağustos | D40: 2.47 | E40: =E39+(E39*D39/100) -> 18027.938 | F40: =E40 -> 18027.938 | H40: =F40-G40+H39 -> 43921.838
C41: Eylül | D41: 2.97 | E41: =E40+(E40*D40/100) -> 18473.228 | F41: =E41 -> 18473.228 | H41: =F41-G41+H40 -> 62395.067
C42: Ekim | D42: 2.88 | E42: =E41+(E41*D41/100) -> 19021.883 | F42: =E42 -> 19021.883 | H42: =F42-G42+H41 -> 81416.95
C43: Kasım | D43: 2.24 | E43: =E42+(E42*D42/100) -> 19569.713 | F43: =E43 -> 19569.713 | H43: =F43-G43+H42 -> 100986.66
C44: boya masrafı | F44: 5000 | H44: =F44-G44+H43 -> 105986.66
C45: ÖDEME | G45: 148500 | H45: =F45-G45+H44 -> -42513.337
...

Sheet SnyG702-22
B1: SnyG | F1: 100 m2 Sanayi Pano
A3: Tarih | B3: Açıklama | D3: Kira bedeli | E3: Ödeme | F3: Bakiye
B4: Toplamlar | D4: =SUM(D9:D20) -> 51000 | E4: =SUM(E9:E20) -> 0 | F4: =F20 -> 51000
B5: Masraf | D5: =F40 -> 0
B6: Teminat | D6: =F37 -> -1200
E7: NET | F7: =E4-D5 -> 0
B8: ,
A9: 45198 | B9: 30-09-2023 – 29-09-2024 | D9: 51000 | F9: =D9-E9 -> 51000
A10: 45194 | B10: 3*17000 | F10: =D10-E10+F9 -> 51000
A11: 45195 | F11: =D11-E11+F10 -> 51000
A12: 45229 | F12: =D12-E12+F11 -> 51000
A13: 45244 | F13: =D13-E13+F12 -> 51000
F14: =D14-E14+F13 -> 51000
F15: =D15-E15+F14 -> 51000
F16: =D16-E16+F15 -> 51000
A17: 45258 | F17: =D17-E17+F16 -> 51000
F18: =D18-E18+F17 -> 51000
F19: =D19-E19+F18 -> 51000
F20: =D20-E20+F19 -> 51000
A23: - 2023 - | B23: ELEKTRİK | C23: Su | D23: Tutarı | F23: ( 1200 TL )
B24: Devreden Teminat | F24: -1200
B25: Su-Elektrik Ocak | C25: 40 | D25: 483.72 | E25: 483.72 | F25: =D25-E25+F24 -> -1200
B26: Su-Elektrik Şubat | D26: 439.85 | E26: 439.85 | F26: =D26-E26+F25 -> -1200
B27: Su-Elektrik art | F27: =D27-E27+F26 -> -1200
B28: Su-Elektrik Nisan | F28: =D28-E28+F27 -> -1200
B29: Su-Elektrik Mayıs | F29: =D29-E29+F28 -> -1200
B30: Su-Elektrik Haziran | F30: =D30-E30+F29 -> -1200
B31: Su-Elektrik Temmuz | F31: =D31-E31+F30 -> -1200
B32: Su-Elektrik Ağustos | F32: =D32-E32+F31 -> -1200
B33: Su-Elektrik Eylül | F33: =D33-E33+F32 -> -1200
B34: Su-Elektrik Ekim | F34: =D34-E34+F33 -> -1200
B35: Su-Elektrik Kasım | F35: =D35-E35+F34 -> -1200
B36: Su-Elektrik Aralık | F36: =D36-E36+F35 -> -1200
A37: 45291 | B37: Devreden Teminat | C37: =SUM(C25:C36) -> 40 | F37: =D37-E37+F36 -> -1200
A40: snyG | B40: Açıklamalar-Masraflar | F40: =SUM(E41:E55) -> 0
B42: Metin Çelik - 2. yıl
B43: İlk anlaşma 7-11-22 de yapıldı
B44: 30-09-2023 – 29-09-2024 Ödenen | D44: 96000
A45: 45237 | B45: tahliye etmek istediğini belirtti
B46: tahliye tarihinden itibaren 3 ay sonrasına kadar işyeri kiralanmazsa
...

Sheet SnH_yazıhane
A2: 2023 | B2: SnyH Yazıhane | D2: 300 m2 | F2: =SUM(F6:F55) -> 3999.1 | G2: =F2 -> 3999.1
A4: Tarih | B4: Açıklama | C4: Kira bedeli | D4: Ödeme | E4: Bakiye | F4: Masraf | G4: Bakiye
A6: 45321 | B6: Elektrik 1 | F6: 169.14 | G6: =G5+E6-F6 -> -169.14
A7: 45350 | B7: Elektrik 2- | F7: 67.09 | G7: =G6+E7-F7 -> -236.23
A8: 45381 | B8: Elektrik 3- | F8: 225.66 | G8: =G7+E8-F8 -> -461.89
A9: 45412 | B9: Elektrik 4- | F9: 286.72 | G9: =G8+E9-F9 -> -748.61
A10: 45442 | B10: Elektrik 5- | F10: 100 | G10: =G9+E10-F10 -> -848.61
A11: 45426 | B11: Bina Vergisi 1 | F11: 1415 | G11: =G10+E11-F11 -> -2263.61
A12: 45426 | B12: Kültür Vergisi 1 | F12: 141.5 | G12: =G11+E12-F12 -> -2405.11
A13: 45473 | B13: Elektrik 6– | F13: 37.49 | G13: =G12+E13-F13 -> -2442.6
A14: 45503 | B14: Elektrik 7– | G14: =G13+E14-F14 -> -2442.6
A15: 45534 | B15: Elektrik 8- | G15: =G14+E15-F15 -> -2442.6
A16: 45565 | B16: Elektrik 9- | G16: =G15+E16-F16 -> -2442.6
A17: 45595 | B17: Elektrik 10- | G17: =G16+E17-F17 -> -2442.6
A18: 45579 | B18: Bina Vergisi 2 | F18: 1415 | G18: =G17+E18-F18 -> -3857.6
A19: 45579 | B19: Kültür Vergisi 2 | F19: 141.5 | G19: =G18+E19-F19 -> -3999.1
A20: 45626 | B20: Elektrik 11- | G20: =G19+E20-F20 -> -3999.1
A21: 45656 | B21: Elektrik 12- | G21: =G20+E21-F21 -> -3999.1
B22: su | F22: 0 | G22: =G21+E22-F22 -> -3999.1

Sheet NAZAN_25
B2: 2025 YILI NAZAN BALCI
C3: Yapılacak | D3: Kalacak | E3: Yapılan | H3: Kalan
C4: Ödeme | D4: Bakiye | E4: Ödeme | H4: Bakiye
D5: 138749.71 | G5: 2024 yıl sonu nazan devreden kira geliri | H5: =D5 -> 138749.71
G6: 2025 yılı Toplam | H6: =H25*-1 -> 68261.36
H7: =H6+H5 -> 207011.07
A8: 45661 | C8: 15000 | D8: =H7-C8 -> 192011.07 | H8: =H7-E8 -> 207011.07
A9: 45689 | C9: =C8 -> 15000 | D9: =D8-C9 -> 177011.07 | H9: =H8-E9 -> 207011.07
A10: 45717 | C10: =C9 -> 15000 | D10: =D9-C10 -> 162011.07 | H10: =H9-E10 -> 207011.07
A11: 45748 | C11: =C10 -> 15000 | D11: =D10-C11 -> 147011.07 | H11: =H10-E11 -> 207011.07
A12: 45778 | C12: =C11 -> 15000 | D12: =D11-C12 -> 132011.07 | H12: =H11-E12 -> 207011.07
A13: 45809 | C13: =C12 -> 15000 | D13: =D12-C13 -> 117011.07 | H13: =H12-E13 -> 207011.07
A14: 45839 | C14: =C13 -> 15000 | D14: =D13-C14 -> 102011.07 | H14: =H13-E14 -> 207011.07
A15: 45870 | C15: =C14 -> 15000 | D15: =D14-C15 -> 87011.07 | H15: =H14-E15 -> 207011.07
A16: 45901 | C16: =C15 -> 15000 | D16: =D15-C16 -> 72011.07 | H16: =H15-E16 -> 207011.07
A17: 45931 | C17: =C16 -> 15000 | D17: =D16-C17 -> 57011.07 | H17: =H16-E17 -> 207011.07
A18: 45988 | B18: snyF | C18: =C17 -> 15000 | D18: =D17-C18 -> 42011.07 | H18: =H17-E18 -> 207011.07
A19: 45992 | B19: snyCD | C19: =C18 -> 15000 | D19: =D18-C19 -> 27011.07 | H19: =H18-E19 -> 207011.07
B23: Hisse Oranı | D23: 0.764616 | E23: =1-D23 -> 0.235384
A24: Tarih | B24: Açıklama | C24: snyA-H | D24: Oran % | E24: Oran TL Tutar | F24: Ödendi | G24: Oran TL | H24: Genel Toplam
B25: Toplam Gelir | C25: =SUBTOTAL(109,C26:C40) -> 290000 | D25: =SUBTOTAL(109,D26:D40) -> 290000 | E25: =SUM(E26:E40) -> 0 | G25: =SUBTOTAL(109,$G$26:$G$40) -> -68261.36 | H25: =H26 -> -68261.36
A26: 46021 | B26: snyH- Yazıhane | D26: =IF(F26=1,$C26,0) -> 0 | E26: =IF(F26=0,C26*$E$23*-1,0) -> 0 | F26: 0 | G26: =IF(F26=1,C26*$E$23*-1,0) -> 0 | H26: =H27+G26 -> -68261.36
D27: =IF(F27=1,$C27,0) -> 0 | E27: =IF(F27=0,C27*$E$23*-1,0) -> 0 | F27: 0 | G27: =IF(F27=1,C27*$E$23*-1,0) -> 0 | H27: =H28+G27 -> -68261.36
D28: =IF(F28=1,$C28,0) -> 0 | E28: =IF(F28=0,C28*$E$23*-1,0) -> 0 | F28: 0 | G28: =IF(F28=1,C28*$E$23*-1,0) -> 0 | H28: =H29+G28 -> -68261.36
D29: =IF(F29=1,$C29,0) -> 0 | E29: =IF(F29=0,C29*$E$23*-1,0) -> 0 | F29: 0 | G29: =IF(F29=1,C29*$E$23*-1,0) -> 0 | H29: =H30+G29 -> -68261.36
D30: =IF(F30=1,$C30,0) -> 0 | E30: =IF(F30=0,C30*$E$23*-1,0) -> 0 | F30: 0 | G30: =IF(F30=1,C30*$E$23*-1,0) -> 0 | H30: =H31+G30 -> -68261.36
D31: =IF(F31=1,$C31,0) -> 0 | E31: =IF(F31=0,C31*$E$23*-1,0) -> 0 | F31: 0 | G31: =IF(F31=1,C31*$E$23*-1,0) -> 0 | H31: =H32+G31 -> -68261.36
D32: =IF(F32=1,$C32,0) -> 0 | E32: =IF(F32=0,C32*$E$23*-1,0) -> 0 | F32: 0 | G32: =IF(F32=1,C32*$E$23*-1,0) -> 0 | H32: =H33+G32 -> -68261.36
D33: =IF(F33=1,$C33,0) -> 0 | E33: =IF(F33=0,C33*$E$23*-1,0) -> 0 | F33: 0 | G33: =IF(F33=1,C33*$E$23*-1,0) -> 0 | H33: =H34+G33 -> -68261.36
D34: =IF(F34=1,$C34,0) -> 0 | E34: =IF(F34=0,C34*$E$23*-1,0) -> 0 | F34: 0 | G34: =IF(F34=1,C34*$E$23*-1,0) -> 0 | H34: =H35+G34 -> -68261.36
D35: =IF(F35=1,$C35,0) -> 0 | E35: =IF(F35=0,C35*$E$23*-1,0) -> 0 | F35: 0 | G35: =IF(F35=1,C35*$E$23*-1,0) -> 0 | H35: =H36+G35 -> -68261.36
D36: =IF(F36=1,$C36,0) -> 0 | E36: =IF(F36=0,C36*$E$23*-1,0) -> 0 | F36: 0 | G36: =IF(F36=1,C36*$E$23*-1,0) -> 0 | H36: =H37+G36 -> -68261.36
D37: =IF(F37=1,$C37,0) -> 0 | E37: =IF(F37=0,C37*$E$23*-1,0) -> 0 | F37: 0 | G37: =IF(F37=1,C37*$E$23*-1,0) -> 0 | H37: =H38+G37 -> -68261.36
D38: =IF(F38=1,$C38,0) -> 0 | E38: =IF(F38=0,C38*$E$23*-1,0) -> 0 | F38: 0 | G38: =IF(F38=1,C38*$E$23*-1,0) -> 0 | H38: =H39+G38 -> -68261.36
D39: =IF(F39=1,$C39,0) -> 0 | E39: =IF(F39=0,C39*$E$23*-1,0) -> 0 | F39: 0 | G39: =IF(F39=1,C39*$E$23*-1,0) -> 0 | H39: =H40+G39 -> -68261.36
A40: 45660 | B40: snyB bankadan | C40: 290000 | D40: =IF(F40=1,$C40,0) -> 290000 | E40: =IF(F40=0,C40*$E$23*-1,0) -> 0 | F40: 1 | G40: =IF(F40=1,C40*$E$23*-1,0) -> -68261.36 | H40: =G40 -> -68261.36
C43: Toplam | D43: Hacı | E43: Nazan
B44: % | C44: 1 | D44: =D23 -> 0.764616 | E44: =1-D44 -> 0.235384
B45: Toplam Gelecek | C45: =$D$25*C44 -> 290000 | D45: =$D$25*D44 -> 221738.64 | E45: =$D$25*E44 -> 68261.36
B46: Gelen | C46: =D46+E46 -> 290000 | D46: =C45-E46 -> 221738.64 | E46: =$H$25*-1 -> 68261.36
...

Sheet NAZAN_24
B2: 2024 YILI NAZAN BALCI
C3: Yapılacak | D3: Kalacak | E3: Yapılan | H3: Kalan
C4: Ödeme | D4: Bakiye | E4: Ödeme | H4: Bakiye
D5: 121030.76 | G5: 2023 yıl sonu nazan kira geliri | H5: =D5 -> 121030.76
G6: 2024 yılı Toplam | H6: =H25*-1 -> 187718.95
H7: =H6+H5 -> 308749.71
A8: 45295 | C8: 10000 | D8: =H7-C8 -> 298749.71 | E8: 10000 | G8: nazan havale | H8: =H7-E8 -> 298749.71
A9: 45323 | C9: 10000 | D9: =D8-C9 -> 288749.71 | E9: 10000 | G9: nazan havale | H9: =H8-E9 -> 288749.71
A10: 45352 | C10: 10000 | D10: =D9-C10 -> 278749.71 | E10: 10000 | G10: nazan havale | H10: =H9-E10 -> 278749.71
A11: 45383 | C11: 10000 | D11: =D10-C11 -> 268749.71 | E11: 10000 | G11: nazan havale | H11: =H10-E11 -> 268749.71
A12: 45413 | C12: 10000 | D12: =D11-C12 -> 258749.71 | E12: 10000 | G12: nazan havale | H12: =H11-E12 -> 258749.71
A13: 45444 | C13: 10000 | D13: =D12-C13 -> 248749.71 | E13: 10000 | G13: nazan havale | H13: =H12-E13 -> 248749.71
A14: 45474 | C14: 10000 | D14: =D13-C14 -> 238749.71 | E14: 10000 | G14: nazan havale | H14: =H13-E14 -> 238749.71
A15: 45505 | C15: 10000 | D15: =D14-C15 -> 228749.71 | F15: ödenmedi | H15: =H14-E15 -> 238749.71
A16: 45536 | C16: 10000 | D16: =D15-C16 -> 218749.71 | F16: ödenmedi | H16: =H15-E16 -> 238749.71
A17: 45566 | C17: 10000 | D17: =D16-C17 -> 208749.71 | F17: ödenmedi | H17: =H16-E17 -> 238749.71
A18: 45623 | B18: snyF | C18: 10000 | D18: =D17-C18 -> 198749.71 | E18: 40000 | H18: =H17-E18 -> 198749.71
A19: 45627 | B19: snyCD | C19: 11030.76 | D19: =D18-C19 -> 187718.95 | E19: 60000 | G19: 2025 e DEVREDEN | H19: =H18-E19 -> 138749.71
D20: TOPLAM ÖDEME | E20: =SUM(E8:E19) -> 170000
B23: Hisse Oranı | D23: 0.764616 | E23: =1-D23 -> 0.235384
A24: Tarih | B24: Açıklama | C24: snyA-H | D24: Oran % | E24: Oran TL Tutar | F24: Ödendi | G24: Oran TL | H24: Genel Toplam
B25: Toplam Gelir | C25: =SUBTOTAL(109,C26:C40) -> 804500.9 | D25: =SUBTOTAL(109,D26:D40) -> 797500.9 | E25: =SUM(E26:E40) -> -1647.688 | G25: =SUBTOTAL(109,$G$26:$G$40) -> -187718.95 | H25: =H26 -> -187718.95
A26: 45656 | B26: snyH- Yazıhane | C26: -3999.1 | D26: =IF(F26=1,$C26,0) -> -3999.1 | E26: =IF(F26=0,C26*$E$23*-1,0) -> 0 | F26: 1 | G26: =IF(F26=1,C26*$E$23*-1,0) -> 941.32415 | H26: =H27+G26 -> -187718.95
D27: =IF(F27=1,$C27,0) -> 0 | E27: =IF(F27=0,C27*$E$23*-1,0) -> 0 | F27: 0 | G27: =IF(F27=1,C27*$E$23*-1,0) -> 0 | H27: =H28+G27 -> -188660.28
D28: =IF(F28=1,$C28,0) -> 0 | E28: =IF(F28=0,C28*$E$23*-1,0) -> 0 | F28: 0 | G28: =IF(F28=1,C28*$E$23*-1,0) -> 0 | H28: =H29+G28 -> -188660.28
A29: 45631 | B29: snyCD-işbank | C29: 219000 | D29: =IF(F29=1,$C29,0) -> 219000 | E29: =IF(F29=0,C29*$E$23*-1,0) -> 0 | F29: 1 | G29: =IF(F29=1,C29*$E$23*-1,0) -> -51549.096 | H29: =H30+G29 -> -188660.28
A30: 45607 | B30: snyF-icradan | C30: 148500 | D30: =IF(F30=1,$C30,0) -> 148500 | E30: =IF(F30=0,C30*$E$23*-1,0) -> 0 | F30: 1 | G30: =IF(F30=1,C30*$E$23*-1,0) -> -34954.524 | H30: =H31+G30 -> -137111.18
A31: 45405 | B31: snyE- işbanktan | C31: 33000 | D31: =IF(F31=1,$C31,0) -> 33000 | E31: =IF(F31=0,C31*$E$23*-1,0) -> 0 | F31: 1 | G31: =IF(F31=1,C31*$E$23*-1,0) -> -7767.672 | H31: =H32+G31 -> -102156.66
A32: 45405 | B32: snyE- Nakit Slmn | C32: 170000 | D32: =IF(F32=1,$C32,0) -> 170000 | E32: =IF(F32=0,C32*$E$23*-1,0) -> 0 | F32: 1 | G32: =IF(F32=1,C32*$E$23*-1,0) -> -40015.28 | H32: =H33+G32 -> -94388.984
A33: 45405 | B33: snyE İADE Chn | C33: -25000 | D33: =IF(F33=1,$C33,0) -> -25000 | E33: =IF(F33=0,C33*$E$23*-1,0) -> 0 | F33: 1 | G33: =IF(F33=1,C33*$E$23*-1,0) -> 5884.6 | H33: =H34+G33 -> -54373.704
A34: 45397 | B34: snyE Nakit Slmn | C34: 1000 | D34: =IF(F34=1,$C34,0) -> 1000 | E34: =IF(F34=0,C34*$E$23*-1,0) -> 0 | F34: 1 | G34: =IF(F34=1,C34*$E$23*-1,0) -> -235.384 | H34: =H35+G34 -> -60258.304
A35: 45397 | B35: snyF-işbanktan | C35: 85000 | D35: =IF(F35=1,$C35,0) -> 85000 | E35: =IF(F35=0,C35*$E$23*-1,0) -> 0 | F35: 1 | G35: =IF(F35=1,C35*$E$23*-1,0) -> -20007.64 | H35: =H36+G35 -> -60022.92
A36: 45321 | B36: SnyE- Nakit->nazana | C36: 7000 | D36: =IF(F36=1,$C36,0) -> 0 | E36: =IF(F36=0,C36*$E$23*-1,0) -> -1647.688 | F36: 0 | G36: =IF(F36=1,C36*$E$23*-1,0) -> 0 | H36: =H37+G36 -> -40015.28
B37: snyB- bankadan | C37: 24000 | D37: =IF(F37=1,$C37,0) -> 24000 | E37: =IF(F37=0,C37*$E$23*-1,0) -> 0 | F37: 1 | G37: =IF(F37=1,C37*$E$23*-1,0) -> -5649.216 | H37: =H38+G37 -> -40015.28
A38: 45296 | B38: snyB- nakit | C38: 26000 | D38: =IF(F38=1,$C38,0) -> 26000 | E38: =IF(F38=0,C38*$E$23*-1,0) -> 0 | F38: 1 | G38: =IF(F38=1,C38*$E$23*-1,0) -> -6119.984 | H38: =H39+G38 -> -34366.064
A39: 45295 | B39: snyB- nakit | C39: 120000 | D39: =IF(F39=1,$C39,0) -> 120000 | E39: =IF(F39=0,C39*$E$23*-1,0) -> 0 | F39: 1 | G39: =IF(F39=1,C39*$E$23*-1,0) -> -28246.08 | H39: =H40+G39 -> -28246.08
A40: 45292 | B40: snyF | D40: =IF(F40=1,$C40,0) -> 0 | E40: =IF(F40=0,C40*$E$23*-1,0) -> 0 | F40: 0 | G40: =IF(F40=1,C40*$E$23*-1,0) -> 0 | H40: =G40 -> 0
C43: Toplam | D43: Hacı | E43: Nazan
B44: % | C44: 1 | D44: =D23 -> 0.764616 | E44: =1-D44 -> 0.235384
B45: Toplam Gelecek | C45: =$D$25*C44 -> 797500.9 | D45: =$D$25*D44 -> 609781.95 | E45: =$D$25*E44 -> 187718.95
...
