Workbook

Sheet PERI_25
B2: 2025 | C2: hesaba yazılmayan | D2: hacı ödeme | E2: peri ödeme | F2: BAKİYE
A5: 45657 | B5: 2023 den devir PERİ BORÇLU | F5: 257330
F6: =F5 -> 257330
A7: 45667 | B7: 4 ad çeyrek *5000 | D7: 20000 | F7: =F6+D7-E7 -> 277330
A8: 45672 | B8: bankadan havale | E8: 25000 | F8: =F7+D8-E8 -> 252330
A9: 45672 | B9: Taksit 6/12 - 36500 | E9: 31000 | F9: =F8+D9-E9 -> 221330
A10: 45703 | B10: Taksit 7/12 - 36500 | F10: =F9+D10-E10 -> 221330
A11: 45709 | B11: havale | E11: 26000 | F11: =F10+D11-E11 -> 195330
A12: 45731 | B12: Taksit 8/12 - 36500 | F12: =F11+D12-E12 -> 195330
A13: 45762 | B13: Taksit 9/12 - 36500 | F13: =F12+D13-E13 -> 195330
A14: 45792 | B14: Taksit 10/12 - 36500 | F14: =F13+D14-E14 -> 195330
A15: 45823 | B15: Taksit 11/12 - 36500 | F15: =F14+D15-E15 -> 195330
A16: 45853 | B16: Taksit 12/12 - 36500 | F16: =F15+D16-E16 -> 195330
F17: =F16+D17-E17 -> 195330
F18: KALAN BAKİYE
B37: YASEMİN ARAÇ HESABI
F39: =F38+D39-E39 -> 0
B40: YASEMİN KAPORA | D40: 50000 | F40: =F39+D40-E40 -> 50000
B41: YASEMİN UMUTTAN OKUL PARASINDAN | D41: 140000 | F41: =F40+D41-E41 -> 190000
B42: YASEMİN OKUL PARASINDAN | D42: 195000 | F42: =F41+D42-E42 -> 385000
B43: YASEMİN OKUL PARASI | E43: 310000 | F43: =F42+D43-E43 -> 75000
B44: DERSANE+ ÖDEME | F44: =F43+D44-E44 -> 75000
B45: MAAŞTAN ÖDENECEK (okul parasından artan) | D45: =#REF!-F43 -> #REF! | F45: =F43+D45-E45 -> #REF!
E46: TOPLAM YASEMİNİN ARAÇ ÖDEMESİ | F46: =F45 -> #REF!

Sheet GNLK-_2025
C1: TAHMİNİ | F1: GERÇEKLEŞEN | K1: NZN | L1: HC | N1: NY
A2: -2024 | B2: GİRİŞ | C2: ÇIKIŞ | D2: BAKİYE | E2: GİRİŞ | F2: ÇIKIŞ | G2: BAKİYE | J2: kR | K2: 0.235384 | L2: =1-K2 -> 0.764616 | M2: Hc 1/1 | N2: =#REF!/1000 -> #REF!
A3: Ocak | B3: ='01_25'!D2 -> 398664 | C3: ='01_25'!E2 -> -55562.4 | D3: =B3+C3 -> 343101.6 | E3: ='01_25'!F2 -> 320054.88 | F3: ='01_25'!G2 -> -59018.87 | G3: =E3+F3 -> 261036.01 | I3: dgs | J3: 180 | M3: =J3 -> 180 | N3: ='01_25'!E133/1000 -> 0.96499
A4: Şubat | B4: ='02_25'!D2 -> 45000 | C4: ='02_25'!E2 -> -75400.4 | D4: =B4+C4+D3 -> 312701.2 | E4: ='02_25'!F2 -> 30054.88 | F4: ='02_25'!G2 -> -96628.72 | G4: =E4+F4+G3 -> 194462.17 | I4: sF | J4: 235 | K4: =J4*$K$2 -> 55.31524 | L4: =J4-K4 -> 179.68476 | N4: ='02_25'!E130/1000 -> 16.2
A5: Mart | B5: ='03_25'!D2 -> 15000 | C5: ='03_25'!E2 -> -79968.85 | D5: =B5+C5+D4 -> 247732.35 | E5: ='03_25'!F2 -> 0 | F5: ='03_25'!G2 -> -36002.02 | G5: =E5+F5+G4 -> 158460.15 | I5: tzg | M5: =J5 -> 0 | N5: ='03_25'!E144/1000 -> 0
A6: Nisan | B6: ='04_25'!D2 -> 15000 | C6: ='04_25'!E2 -> -167276.39 | D6: =B6+C6+D5 -> 95455.96 | E6: ='04_25'!F2 -> 0 | F6: ='04_25'!G2 -> -120979.33 | G6: =E6+F6+G5 -> 37480.82 | I6: maaş ocak-haziran | M6: =E18/1000 -> 15 | N6: ='04_25'!E111/1000 -> 0
A7: Mayıs | B7: ='05_25'!D2 -> 15000 | C7: ='05_25'!E2 -> -45906.84 | D7: =B7+C7+D6 -> 64549.12 | E7: ='05_25'!F2 -> 0 | F7: ='05_25'!G2 -> -989.78 | G7: =E7+F7+G6 -> 36491.04 | I7: maaş temmuz-aralık | M7: =E19/1000 -> 0 | N7: ='05_25'!E101/1000 -> 0
A8: Hazrn | B8: ='06_25'!D2 -> 15000 | C8: ='06_25'!E2 -> -53406.84 | D8: =B8+C8+D7 -> 26142.28 | E8: ='06_25'!F2 -> 0 | F8: ='06_25'!G2 -> -989.78 | G8: =E8+F8+G7 -> 35501.26 | I8: lise | J8: 225 | M8: =J8/4 -> 56.25 | N8: ='06_25'!E118/1000 -> 0
A9: Temmz | B9: ='07_25'!D2 -> 15000 | C9: ='07_25'!E2 -> -53406.84 | D9: =B9+C9+D8 -> -12264.56 | E9: ='07_25'!F2 -> 0 | F9: ='07_25'!G2 -> -989.78 | G9: =E9+F9+G8 -> 34511.48 | I9: sE | J9: 204 | K9: =J9*$K$2 -> 48.018336 | L9: =J9-K9 -> 155.98166 | N9: ='07_25'!E133/1000 -> 0
A10: Ağusts | B10: ='08_25'!D2 -> 15000 | C10: ='08_25'!E2 -> -53406.84 | D10: =B10+C10+D9 -> -50671.4 | E10: ='08_25'!F2 -> 0 | F10: ='08_25'!G2 -> -989.78 | G10: =E10+F10+G9 -> 33521.7 | I10: ap | J10: 0 | M10: =J10*0.13 -> 0 | N10: ='08_25'!E125/1000 -> 0
A11: Eylül | B11: ='09_25'!D2 -> 15000 | C11: ='09_25'!E2 -> -52417.06 | D11: =B11+C11+D10 -> -88088.46 | E11: ='09_25'!F2 -> 0 | F11: ='09_25'!G2 -> 0 | G11: =E11+F11+G10 -> 33521.7 | I11: sG | J11: 0 | K11: =J11*$K$2 -> 0 | L11: =J11-K11 -> 0 | N11: ='09_25'!E101/1000 -> 0
A12: Ekim | B12: ='10_25'!D2 -> 15000 | C12: ='10_25'!E2 -> -52417.06 | D12: =B12+C12+D11 -> -125505.52 | E12: ='10_25'!F2 -> 0 | F12: ='10_25'!G2 -> 0 | G12: =E12+F12+G11 -> 33521.7 | I12: sA | J12: 0 | K12: =J12*$K$2 -> 0 | L12: =J12-K12 -> 0 | N12: ='10_25'!E136/1000 -> 0
A13: Kasım | B13: ='11_25'!D2 -> 15000 | C13: ='11_25'!E2 -> -52417.06 | D13: =B13+C13+D12 -> -162922.58 | E13: ='11_25'!F2 -> 0 | F13: ='11_25'!G2 -> 0 | G13: =E13+F13+G12 -> 33521.7 | I13: sCD | J13: 219 | K13: =J13*$K$2 -> 51.549096 | L13: =J13-K13 -> 167.4509 | N13: ='11_25'!E111/1000 -> 0
A14: Aralık | B14: ='12_25'!D2 -> 15000 | C14: ='12_25'!E2 -> -52417.06 | D14: =B14+C14+D13 -> -200339.64 | E14: ='12_25'!F2 -> 0 | F14: ='12_25'!G2 -> 0 | G14: =E14+F14+G13 -> 33521.7 | I14: sB | J14: 290 | K14: =J14*$K$2 -> 68.26136 | L14: =J14-K14 -> 221.73864 | N14: ='12_25'!E125/1000 -> 0
A15: TPLM | B15: =SUM(B3:B14) -> 593664 | C15: =SUM(C3:C14) -> -794003.64 | D15: =B15+C15 -> -200339.64 | E15: =SUM(E3:E14) -> 350109.76 | F15: =SUM(F3:F14) -> -316588.06 | G15: =E15+F15 -> 33521.7 | J15: =SUM(J3:J14) -> 1353 | K15: =SUM(K4:K14) -> 223.14403 | L15: =SUM(L4:L14) -> 724.85597 | M15: =M10+M8+M6+M5+M3+M7 -> 251.25
A16: 12 | B16: =B15/A16 -> 49472 | C16: =C15/A16 -> -66166.97 | E16: =E15/A16 -> 29175.813 | F16: =F15/A16 -> -26382.338 | G16: =G15/A16 -> 2793.475 | J16: =J15/12 -> 112.75 | K16: =K15/12 -> 18.595336 | L16: =L15/12 -> 60.404664 | M16: =M15/12 -> 20.9375 | N16: =AVERAGE(N2:N15) -> #REF!
K17: TPLM | L17: =L15+M15 -> 976.10597
D18: ocak-haziran maaş toplamı | E18: ='01_25'!F32+'02_25'!F14+'02_25'!F26+'03_25'!F22+'04_25'!F41+'05_25'!F22+'06_25'!F19+'06_25'!F31+'04_25'!F15 -> 15000 | K18: AYLK | M18: =L17/12 -> 81.342164
D19: temmuz-aralık maaş toplamı | E19: ='07_25'!F30+'08_25'!F25+'09_25'!F19+'10_25'!F29+'11_25'!F34+'12_25'!F22 -> 0
D20: Toplam ;Emekli maaşı | E20: =SUM(E18:E19) -> 15000
B21: 44896
B22: 6986.25 | C22: 0.375785 | D22: 0.4925919
B23: =B22*C22 -> 2625.328 | C23: ocak artış % | D23: =B22*D22 -> 3441.3702
B24: =SUM(B22:B23) -> 9611.578 | C24: ocak 23 maaş | D24: =D23+B22 -> 10427.62
C25: =(D27/D25)-1 -> #DIV/0!
C26: temmuz artış
C27: temmuz 23 maaş | D27: 13006.38

Sheet 12_25
F1: GİRİŞ | G1: ÇIKIŞ | H1: BAKİYE
A2: - EKİM 2025 | C2: TOPLAM | D2: =SUM(D4:D33) -> 15000 | E2: =SUM(E4:E33) -> -52417.06 | F2: =SUM(F4:F33) -> 0 | G2: =SUM(G4:G33) -> 0 | H2: =F2+G2 -> 0
H4: =H3+F4+G4 -> 0
H5: =H4+F5+G5 -> 0
H6: =H5+F6+G6 -> 0
B7: KK 4876 İşbank | E7: =E39 -> 0 | G7: =E7 -> 0 | H7: =H6+F7+G7 -> 0
B8: KK 5165 Denizbank | E8: =E54 -> 0 | G8: =E8 -> 0 | H8: =H7+F8+G8 -> 0
H9: =H8+F9+G9 -> 0
B10: Aidat Marmara Royal Site 9/12 | E10: -2117.06 | H10: =H9+F10+G10 -> 0
B11: Kira Adem Özen 7/12 Mrmr Ryl A Blok 82 | E11: -25000 | H11: =H10+F11+G11 -> 0
B12: Elektrik 9522138254 Sanayi | E12: 0 | H12: =H11+F12+G12 -> 0
H13: =H12+F13+G13 -> 0
H14: =H13+F14+G14 -> 0
B15: Doğalgaz 800004222954 Kümbet D10 | E15: -1000 | H15: =H14+F15+G15 -> 0
B16: Doğalgaz 800004222959 Kümbet D09 | E16: -200 | H16: =H15+F16+G16 -> 0
B17: Doğalgaz Marmara Royal Ablok D:82 | E17: -200 | H17: =H16+F17+G17 -> 0
B18: maaş | D18: 15000 | H18: =H17+F18+G18 -> 0
B19: yasemin | E19: -7500 | H19: =H18+F19+G19 -> 0
B20: umut | E20: -7500 | H20: =H19+F20+G20 -> 0
B21: Genel Masraf | E21: -7500 | H21: =H20+F21+G21 -> 0
H22: =H21+F22+G22 -> 0
H23: =H22+F23+G23 -> 0
H24: =H23+F24+G24 -> 0
B25: Elektrik 5847500300 Kümbet D09 | E25: -600 | H25: =H24+F25+G25 -> 0
B26: Elektrik 8222520300 Kümbet D10 | E26: -800 | H26: =H25+F26+G26 -> 0
H27: =H26+F27+G27 -> 0
H28: =H27+F28+G28 -> 0
B29: TUSDATA 2025 30/30 8845 - 8845 = 0 | H29: =H28+F29+G29 -> 0
H30: =H29+F30+G30 -> 0
H31: =H30+F31+G31 -> 0
B39: İşbank 4876 KK | E39: =SUM(E40:E51) -> 0
E40: HESAP KESİM
B54: Denizbank 5165 kk | E54: =SUM(E55:E73) -> 0
E68: HESAP KESİM

Sheet 11_25
F1: GİRİŞ | G1: ÇIKIŞ | H1: BAKİYE
A2: - EKİM 2025 | C2: TOPLAM | D2: =SUM(D4:D33) -> 15000 | E2: =SUM(E4:E33) -> -52417.06 | F2: =SUM(F4:F33) -> 0 | G2: =SUM(G4:G33) -> 0 | H2: =F2+G2 -> 0
H4: =H3+F4+G4 -> 0
H5: =H4+F5+G5 -> 0
H6: =H5+F6+G6 -> 0
B7: KK 4876 İşbank | E7: =E39 -> 0 | G7: =E7 -> 0 | H7: =H6+F7+G7 -> 0
B8: KK 5165 Denizbank | E8: =E54 -> 0 | G8: =E8 -> 0 | H8: =H7+F8+G8 -> 0
H9: =H8+F9+G9 -> 0
B10: Aidat Marmara Royal Site 9/12 | E10: -2117.06 | H10: =H9+F10+G10 -> 0
B11: Kira Adem Özen 6/12 Mrmr Ryl A Blok 82 | E11: -25000 | H11: =H10+F11+G11 -> 0
B12: Elektrik 9522138254 Sanayi | E12: 0 | H12: =H11+F12+G12 -> 0
H13: =H12+F13+G13 -> 0
H14: =H13+F14+G14 -> 0
B15: Doğalgaz 800004222954 Kümbet D10 | E15: -1000 | H15: =H14+F15+G15 -> 0
B16: Doğalgaz 800004222959 Kümbet D09 | E16: -200 | H16: =H15+F16+G16 -> 0
B17: Doğalgaz Marmara Royal Ablok D:82 | E17: -200 | H17: =H16+F17+G17 -> 0
B18: maaş | D18: 15000 | H18: =H17+F18+G18 -> 0
B19: yasemin | E19: -7500 | H19: =H18+F19+G19 -> 0
B20: umut | E20: -7500 | H20: =H19+F20+G20 -> 0
B21: Genel Masraf | E21: -7500 | H21: =H20+F21+G21 -> 0
H22: =H21+F22+G22 -> 0
H23: =H22+F23+G23 -> 0
H24: =H23+F24+G24 -> 0
B25: Elektrik 5847500300 Kümbet D09 | E25: -600 | H25: =H24+F25+G25 -> 0
B26: Elektrik 8222520300 Kümbet D10 | E26: -800 | H26: =H25+F26+G26 -> 0
H27: =H26+F27+G27 -> 0
H28: =H27+F28+G28 -> 0
B29: TUSDATA 2025 30/30 8845 - 8845 = 0 | H29: =H28+F29+G29 -> 0
H30: =H29+F30+G30 -> 0
H31: =H30+F31+G31 -> 0
B39: İşbank 4876 KK | E39: =SUM(E40:E51) -> 0
E40: HESAP KESİM
B54: Denizbank 5165 kk | E54: =SUM(E55:E73) -> 0
E68: HESAP KESİM

Sheet 10_25
F1: GİRİŞ | G1: ÇIKIŞ | H1: BAKİYE
A2: - EKİM 2025 | C2: TOPLAM | D2: =SUM(D4:D33) -> 15000 | E2: =SUM(E4:E33) -> -52417.06 | F2: =SUM(F4:F33) -> 0 | G2: =SUM(G4:G33) -> 0 | H2: =F2+G2 -> 0
H4: =H3+F4+G4 -> 0
H5: =H4+F5+G5 -> 0
H6: =H5+F6+G6 -> 0
B7: KK 4876 İşbank | E7: =E39 -> 0 | G7: =E7 -> 0 | H7: =H6+F7+G7 -> 0
B8: KK 5165 Denizbank | E8: =E54 -> 0 | G8: =E8 -> 0 | H8: =H7+F8+G8 -> 0
H9: =H8+F9+G9 -> 0
B10: Aidat Marmara Royal Site 9/12 | E10: -2117.06 | H10: =H9+F10+G10 -> 0
B11: Kira Adem Özen 5/12 Mrmr Ryl A Blok 82 | E11: -25000 | H11: =H10+F11+G11 -> 0
B12: Elektrik 9522138254 Sanayi | E12: 0 | H12: =H11+F12+G12 -> 0
H13: =H12+F13+G13 -> 0
H14: =H13+F14+G14 -> 0
B15: Doğalgaz 800004222954 Kümbet D10 | E15: -1000 | H15: =H14+F15+G15 -> 0
B16: Doğalgaz 800004222959 Kümbet D09 | E16: -200 | H16: =H15+F16+G16 -> 0
B17: Doğalgaz Marmara Royal Ablok D:82 | E17: -200 | H17: =H16+F17+G17 -> 0
B18: maaş | D18: 15000 | H18: =H17+F18+G18 -> 0
B19: yasemin | E19: -7500 | H19: =H18+F19+G19 -> 0
B20: umut | E20: -7500 | H20: =H19+F20+G20 -> 0
B21: Genel Masraf | E21: -7500 | H21: =H20+F21+G21 -> 0
H22: =H21+F22+G22 -> 0
H23: =H22+F23+G23 -> 0
H24: =H23+F24+G24 -> 0
B25: Elektrik 5847500300 Kümbet D09 | E25: -600 | H25: =H24+F25+G25 -> 0
B26: Elektrik 8222520300 Kümbet D10 | E26: -800 | H26: =H25+F26+G26 -> 0
H27: =H26+F27+G27 -> 0
H28: =H27+F28+G28 -> 0
B29: TUSDATA 2025 30/30 8845 - 8845 = 0 | H29: =H28+F29+G29 -> 0
H30: =H29+F30+G30 -> 0
H31: =H30+F31+G31 -> 0
B39: İşbank 4876 KK | E39: =SUM(E40:E51) -> 0
E40: HESAP KESİM
B54: Denizbank 5165 kk | E54: =SUM(E55:E73) -> 0
E68: HESAP KESİM

Sheet 09_25
F1: GİRİŞ | G1: ÇIKIŞ | H1: BAKİYE
A2: - EYLÜL 2025 | C2: TOPLAM | D2: =SUM(D4:D34) -> 15000 | E2: =SUM(E4:E34) -> -52417.06 | F2: =SUM(F4:F34) -> 0 | G2: =SUM(G4:G33) -> 0 | H2: =F2+G2 -> 0
H4: =H3+F4+G4 -> 0
H5: =H4+F5+G5 -> 0
H6: =H5+F6+G6 -> 0
B7: KK 4876 İşbank | E7: =E39 -> 0 | G7: =E7 -> 0 | H7: =H6+F7+G7 -> 0
B8: KK 5165 Denizbank | E8: =E54 -> 0 | G8: =E8 -> 0 | H8: =H7+F8+G8 -> 0
H9: =H8+F9+G9 -> 0
B10: Aidat Marmara Royal Site 9/12 | E10: -2117.06 | H10: =H9+F10+G10 -> 0
B11: Kira Adem Özen 4/12 Mrmr Ryl A Blok 82 | E11: -25000 | H11: =H10+F11+G11 -> 0
B12: Elektrik 9522138254 Sanayi | E12: 0 | H12: =H11+F12+G12 -> 0
H13: =H12+F13+G13 -> 0
H14: =H13+F14+G14 -> 0
B15: Doğalgaz 800004222954 Kümbet D10 | E15: -1000 | H15: =H14+F15+G15 -> 0
B16: Doğalgaz 800004222959 Kümbet D09 | E16: -200 | H16: =H15+F16+G16 -> 0
B17: Doğalgaz Marmara Royal Ablok D:82 | E17: -200 | H17: =H16+F17+G17 -> 0
B18: maaş | D18: 15000 | H18: =H17+F18+G18 -> 0
B19: yasemin | E19: -7500 | H19: =H18+F19+G19 -> 0
B20: umut | E20: -7500 | H20: =H19+F20+G20 -> 0
B21: Genel Masraf | E21: -7500 | H21: =H20+F21+G21 -> 0
H22: =H21+F22+G22 -> 0
H23: =H22+F23+G23 -> 0
H24: =H23+F24+G24 -> 0
B25: Elektrik 5847500300 Kümbet D09 | E25: -600 | H25: =H24+F25+G25 -> 0
B26: Elektrik 8222520300 Kümbet D10 | E26: -800 | H26: =H25+F26+G26 -> 0
H27: =H26+F27+G27 -> 0
H28: =H27+F28+G28 -> 0
B29: TUSDATA 2025 29/30 17690 - 8845 = 8845 | H29: =H28+F29+G29 -> 0
H30: =H29+F30+G30 -> 0
H31: =H30+F31+G31 -> 0
B39: İşbank 4876 KK | E39: =SUM(E40:E51) -> 0
E40: HESAP KESİM
B54: Denizbank 5165 kk | E54: =SUM(E55:E73) -> 0
E68: HESAP KESİM

Sheet 08_25
F1: GİRİŞ | G1: ÇIKIŞ | H1: BAKİYE
A2: - AĞUSTOS 2025 | C2: TOPLAM | D2: =SUM(D4:D32) -> 15000 | E2: =SUM(E4:E32) -> -53406.84 | F2: =SUM(F4:F32) -> 0 | G2: =SUM(G4:G32) -> -989.78 | H2: =F2+G2 -> -989.78
H4: =H3+F4+G4 -> 0
H5: =H4+F5+G5 -> 0
H6: =H5+F6+G6 -> 0
B7: KK 4876 İşbank | E7: =E35 -> 0 | G7: =E7 -> 0 | H7: =H6+F7+G7 -> 0
B8: KK 5165 Denizbank | E8: =E50 -> -989.78 | G8: =E8 -> -989.78 | H8: =H7+F8+G8 -> -989.78
H9: =H8+F9+G9 -> -989.78
B10: Aidat Marmara Royal Site 9/12 | E10: -2117.06 | H10: =H9+F10+G10 -> -989.78
B11: Kira Adem Özen 3/12 Mrmr Ryl A Blok 82 | E11: -25000 | H11: =H10+F11+G11 -> -989.78
B12: Elektrik 9522138254 Sanayi | E12: 0 | H12: =H11+F12+G12 -> -989.78
H13: =H12+F13+G13 -> -989.78
H14: =H13+F14+G14 -> -989.78
B15: Doğalgaz 800004222954 Kümbet D10 | E15: -1000 | H15: =H14+F15+G15 -> -989.78
B16: Doğalgaz 800004222959 Kümbet D09 | E16: -200 | H16: =H15+F16+G16 -> -989.78
B17: Doğalgaz Marmara Royal Ablok D:82 | E17: -200 | H17: =H16+F17+G17 -> -989.78
B18: maaş | D18: 15000 | H18: =H17+F18+G18 -> -989.78
B19: yasemin | E19: -7500 | H19: =H18+F19+G19 -> -989.78
B20: umut | E20: -7500 | H20: =H19+F20+G20 -> -989.78
B21: Genel Masraf | E21: -7500 | H21: =H20+F21+G21 -> -989.78
H22: =H21+F22+G22 -> -989.78
H23: =H22+F23+G23 -> -989.78
H24: =H23+F24+G24 -> -989.78
B25: Elektrik 5847500300 Kümbet D09 | E25: -600 | H25: =H24+F25+G25 -> -989.78
B26: Elektrik 8222520300 Kümbet D10 | E26: -800 | H26: =H25+F26+G26 -> -989.78
H27: =H26+F27+G27 -> -989.78
H28: =H27+F28+G28 -> -989.78
B29: TUSDATA 2025 28/30 26535 - 8845 = 17690 | H29: =H28+F29+G29 -> -989.78
H30: =H29+F30+G30 -> -989.78
H31: =H30+F31+G31 -> -989.78
B35: İşbank 4876 KK | E35: =SUM(E36:E47) -> 0
E36: HESAP KESİM
B50: Denizbank 5165 kk | E50: =SUM(E51:E69) -> -989.78
A52: 45715 | B52: turknet 12 aylık internet | C52: 5938.68 | D52: 6 - 6 | E52: -989.78
E64: HESAP KESİM

Sheet 07_25
F1: GİRİŞ | G1: ÇIKIŞ | H1: BAKİYE
A2: - TEMMUZ 2025 | C2: TOPLAM | D2: =SUM(D4:D31) -> 15000 | E2: =SUM(E4:E31) -> -53406.84 | F2: =SUM(F4:F31) -> 0 | G2: =SUM(G4:G31) -> -989.78 | H2: =F2+G2 -> -989.78
H4: =H3+F4+G4 -> 0
H5: =H4+F5+G5 -> 0
H6: =H5+F6+G6 -> 0
B7: KK 4876 İşbank | E7: =E35 -> 0 | G7: =E7 -> 0 | H7: =H6+F7+G7 -> 0
B8: KK 5165 Denizbank | E8: =E50 -> -989.78 | G8: =E8 -> -989.78 | H8: =H7+F8+G8 -> -989.78
H9: =H8+F9+G9 -> -989.78
B10: Aidat Marmara Royal Site 9/12 | E10: -2117.06 | H10: =H9+F10+G10 -> -989.78
B11: Kira Adem Özen 2/12 Mrmr Ryl A Blok 82 | E11: -25000 | H11: =H10+F11+G11 -> -989.78
B12: Elektrik 9522138254 Sanayi | E12: 0 | H12: =H11+F12+G12 -> -989.78
H13: =H12+F13+G13 -> -989.78
H14: =H13+F14+G14 -> -989.78
B15: Doğalgaz 800004222954 Kümbet D10 | E15: -1000 | H15: =H14+F15+G15 -> -989.78
B16: Doğalgaz 800004222959 Kümbet D09 | E16: -200 | H16: =H15+F16+G16 -> -989.78
B17: Doğalgaz Marmara Royal Ablok D:82 | E17: -200 | H17: =H16+F17+G17 -> -989.78
B18: maaş | D18: 15000 | H18: =H17+F18+G18 -> -989.78
B19: yasemin | E19: -7500 | H19: =H18+F19+G19 -> -989.78
B20: umut | E20: -7500 | H20: =H19+F20+G20 -> -989.78
B21: Genel Masraf | E21: -7500 | H21: =H20+F21+G21 -> -989.78
H22: =H21+F22+G22 -> -989.78
H23: =H22+F23+G23 -> -989.78
H24: =H23+F24+G24 -> -989.78
B25: Elektrik 5847500300 Kümbet D09 | E25: -600 | H25: =H24+F25+G25 -> -989.78
B26: Elektrik 8222520300 Kümbet D10 | E26: -800 | H26: =H25+F26+G26 -> -989.78
H27: =H26+F27+G27 -> -989.78
H28: =H27+F28+G28 -> -989.78
B29: TUSDATA 2025 27/30 35380 - 8845 = 26535 | H29: =H28+F29+G29 -> -989.78
H30: =H29+F30+G30 -> -989.78
H31: =H30+F31+G31 -> -989.78
B35: İşbank 4876 KK | E35: =SUM(E36:E47) -> 0
E36: HESAP KESİM
B50: Denizbank 5165 kk | E50: =SUM(E51:E69) -> -989.78
A52: 45715 | B52: turknet 12 aylık internet | C52: 5938.68 | D52: 5 - 6 | E52: -989.78
E64: HESAP KESİM

Sheet 06_25
F1: GİRİŞ | G1: ÇIKIŞ | H1: BAKİYE
A2: - HAZİRAN 2025 | C2: TOPLAM | D2: =SUM(D4:D31) -> 15000 | E2: =SUM(E4:E31) -> -53406.84 | F2: =SUM(F4:F31) -> 0 | G2: =SUM(G4:G31) -> -989.78 | H2: =F2+G2 -> -989.78
H4: =H3+F4+G4 -> 0
H5: =H4+F5+G5 -> 0
H6: =H5+F6+G6 -> 0
B7: KK 4876 İşbank | E7: =E35 -> 0 | G7: =E7 -> 0 | H7: =H6+F7+G7 -> 0
B8: KK 5165 Denizbank | E8: =E50 -> -989.78 | G8: =E8 -> -989.78 | H8: =H7+F8+G8 -> -989.78
H9: =H8+F9+G9 -> -989.78
B10: Aidat Marmara Royal Site 9/12 | E10: -2117.06 | H10: =H9+F10+G10 -> -989.78
B11: Kira Adem Özen 1/12 Mrmr Ryl A Blok 82 | E11: -25000 | H11: =H10+F11+G11 -> -989.78
B12: Elektrik 9522138254 Sanayi | E12: 0 | H12: =H11+F12+G12 -> -989.78
H13: =H12+F13+G13 -> -989.78
H14: =H13+F14+G14 -> -989.78
B15: Doğalgaz 800004222954 Kümbet D10 | E15: -1000 | H15: =H14+F15+G15 -> -989.78
B16: Doğalgaz 800004222959 Kümbet D09 | E16: -200 | H16: =H15+F16+G16 -> -989.78
B17: Doğalgaz Marmara Royal Ablok D:82 | E17: -200 | H17: =H16+F17+G17 -> -989.78
B18: maaş | D18: 15000 | H18: =H17+F18+G18 -> -989.78
B19: yasemin | E19: -7500 | H19: =H18+F19+G19 -> -989.78
B20: umut | E20: -7500 | H20: =H19+F20+G20 -> -989.78
B21: Genel Masraf | E21: -7500 | H21: =H20+F21+G21 -> -989.78
H22: =H21+F22+G22 -> -989.78
H23: =H22+F23+G23 -> -989.78
H24: =H23+F24+G24 -> -989.78
B25: Elektrik 5847500300 Kümbet D09 | E25: -600 | H25: =H24+F25+G25 -> -989.78
B26: Elektrik 8222520300 Kümbet D10 | E26: -800 | H26: =H25+F26+G26 -> -989.78
H27: =H26+F27+G27 -> -989.78
H28: =H27+F28+G28 -> -989.78
B29: TUSDATA 2025 26/30 44225 - 8845 = 35380 | H29: =H28+F29+G29 -> -989.78
H30: =H29+F30+G30 -> -989.78
H31: =H30+F31+G31 -> -989.78
B35: İşbank 4876 KK | E35: =SUM(E36:E47) -> 0
E36: HESAP KESİM
B50: Denizbank 5165 kk | E50: =SUM(E51:E69) -> -989.78
A52: 45715 | B52: turknet 12 aylık internet | C52: 5938.68 | D52: 4 - 6 | E52: -989.78
E64: HESAP KESİM

Sheet 05_25
F1: GİRİŞ | G1: ÇIKIŞ | H1: BAKİYE
A2: - MAYIS 2025 | C2: TOPLAM | D2: =SUM(D4:D31) -> 15000 | E2: =SUM(E4:E31) -> -45906.84 | F2: =SUM(F4:F31) -> 0 | G2: =SUM(G4:G31) -> -989.78 | H2: =F2+G2 -> -989.78
H4: =H3+F4+G4 -> 0
H5: =H4+F5+G5 -> 0
H6: =H5+F6+G6 -> 0
B7: KK 4876 İşbank | E7: =E37 -> 0 | G7: =E7 -> 0 | H7: =H6+F7+G7 -> 0
B8: KK 5165 Denizbank | E8: =E52 -> -989.78 | G8: =E8 -> -989.78 | H8: =H7+F8+G8 -> -989.78
H9: =H8+F9+G9 -> -989.78
B10: Aidat Marmara Royal Site 9/12 | E10: -2117.06 | H10: =H9+F10+G10 -> -989.78
B11: Kira Adem Özen 12/12 Mrmr Ryl A Blok 82 | E11: -17500 | H11: =H10+F11+G11 -> -989.78
B12: Elektrik 9522138254 Sanayi | E12: 0 | H12: =H11+F12+G12 -> -989.78
H13: =H12+F13+G13 -> -989.78
H14: =H13+F14+G14 -> -989.78
B15: Doğalgaz 800004222954 Kümbet D10 | E15: -1000 | H15: =H14+F15+G15 -> -989.78
B16: Doğalgaz 800004222959 Kümbet D09 | E16: -200 | H16: =H15+F16+G16 -> -989.78
B17: Doğalgaz Marmara Royal Ablok D:82 | E17: -200 | H17: =H16+F17+G17 -> -989.78
B18: maaş | D18: 15000 | H18: =H17+F18+G18 -> -989.78
B19: yasemin | E19: -7500 | H19: =H18+F19+G19 -> -989.78
B20: umut | E20: -7500 | H20: =H19+F20+G20 -> -989.78
B21: Genel Masraf | E21: -7500 | H21: =H20+F21+G21 -> -989.78
H22: =H21+F22+G22 -> -989.78
H23: =H22+F23+G23 -> -989.78
H24: =H23+F24+G24 -> -989.78
B25: Elektrik 5847500300 Kümbet D09 | E25: -600 | H25: =H24+F25+G25 -> -989.78
B26: Elektrik 8222520300 Kümbet D10 | E26: -800 | H26: =H25+F26+G26 -> -989.78
H27: =H26+F27+G27 -> -989.78
H28: =H27+F28+G28 -> -989.78
B29: TUSDATA 2025 25/30 53070 - 8845 = 44225 | H29: =H28+F29+G29 -> -989.78
H30: =H29+F30+G30 -> -989.78
H31: =H30+F31+G31 -> -989.78
B37: İşbank 4876 KK | E37: =SUM(E38:E49) -> 0
E38: HESAP KESİM
B52: Denizbank 5165 kk | E52: =SUM(E53:E71) -> -989.78
A55: 45715 | B55: turknet 12 aylık internet | C55: 5938.68 | D55: 3 - 6 | E55: -989.78
E66: HESAP KESİM

Sheet 04_25
F1: GİRİŞ | G1: ÇIKIŞ | H1: BAKİYE
A2: - NİSAN 2025 | C2: TOPLAM | D2: =SUM(D4:D32) -> 15000 | E2: =SUM(E4:E32) -> -167276.39 | F2: =SUM(F4:F32) -> 0 | G2: =SUM(G4:G32) -> -120979.33 | H2: =F2+G2 -> -120979.33
H4: =H3+F4+G4 -> 0
H5: =H4+F5+G5 -> 0
H6: =H5+F6+G6 -> 0
B7: KK 4876 İşbank | E7: =E35 -> -119989.55 | G7: =E7 -> -119989.55 | H7: =H6+F7+G7 -> -119989.55
B8: KK 5165 Denizbank | E8: =E50 -> -989.78 | G8: =E8 -> -989.78 | H8: =H7+F8+G8 -> -120979.33
H9: =H8+F9+G9 -> -120979.33
B10: Aidat Marmara Royal Site 9/12 | E10: -2117.06 | H10: =H9+F10+G10 -> -120979.33
B11: Kira Adem Özen 11/12 Mrmr Ryl A Blok 82 | E11: -17500 | H11: =H10+F11+G11 -> -120979.33
B12: Elektrik 9522138254 Sanayi | E12: 0 | H12: =H11+F12+G12 -> -120979.33
H13: =H12+F13+G13 -> -120979.33
H14: =H13+F14+G14 -> -120979.33
B15: Doğalgaz 800004222954 Kümbet D10 | E15: -1000 | H15: =H14+F15+G15 -> -120979.33
B16: Doğalgaz 800004222959 Kümbet D09 | E16: -200 | H16: =H15+F16+G16 -> -120979.33
B17: Doğalgaz Marmara Royal Ablok D:82 | E17: -200 | H17: =H16+F17+G17 -> -120979.33
B18: maaş | D18: 15000 | H18: =H17+F18+G18 -> -120979.33
B19: yasemin | E19: -7500 | H19: =H18+F19+G19 -> -120979.33
B20: umut | E20: -7500 | H20: =H19+F20+G20 -> -120979.33
B21: Genel Masraf | E21: -7500 | H21: =H20+F21+G21 -> -120979.33
H22: =H21+F22+G22 -> -120979.33
H23: =H22+F23+G23 -> -120979.33
A24: 45776 | B24: SANAYI BELEDIYE SAYC UCRETI | C24: 2024 / 9 son | E24: -1380 | H24: =H23+F24+G24 -> -120979.33
B25: Elektrik 5847500300 Kümbet D09 | E25: -600 | H25: =H24+F25+G25 -> -120979.33
B26: Elektrik 8222520300 Kümbet D10 | E26: -800 | H26: =H25+F26+G26 -> -120979.33
H27: =H26+F27+G27 -> -120979.33
H28: =H27+F28+G28 -> -120979.33
B29: TUSDATA 2025 24/30 61915 - 8845 = 53070 | H29: =H28+F29+G29 -> -120979.33
H30: =H29+F30+G30 -> -120979.33
H31: =H30+F31+G31 -> -120979.33
B35: İşbank 4876 KK | E35: =SUM(E36:E47) -> -119989.55
E36: HESAP KESİM
B38: DAU yasemin okul | E38: -1023.05
B39: DAU yasemin okul | E39: -118966.5
B50: Denizbank 5165 kk | E50: =SUM(E51:E69) -> -989.78
A53: 45715 | B53: turknet 12 aylık internet | C53: 5938.68 | D53: 2 - 6 | E53: -989.78
E64: HESAP KESİM

Sheet 03_25
F1: GİRİŞ | G1: ÇIKIŞ | H1: BAKİYE
A2: - MART 2025 | C2: TOPLAM | D2: =SUM(D4:D36) -> 15000 | E2: =SUM(E4:E36) -> -79968.85 | F2: =SUM(F4:F36) -> 0 | G2: =SUM(G4:G36) -> -36002.02 | H2: =F2+G2 -> -36002.02
H4: =H3+F4+G4 -> 0
H5: =H4+F5+G5 -> 0
A6: 45718 | B6: vodafone 2240 | G6: -213.25 | H6: =H5+F6+G6 -> -213.25
B7: Elektrik 9522138254 Sanayi | E7: 0 | H7: =H6+F7+G7 -> -213.25
A8: 45721 | B8: Aidat Marmara Royal Site 9/12 | E8: -2117.06 | G8: -2116.98 | H8: =H7+F8+G8 -> -2330.23
A9: 45722 | B9: KK 5165 Denizbank | E9: =E64 -> -14628.18 | G9: =E9 -> -14628.18 | H9: =H8+F9+G9 -> -16958.41
A10: 45723 | B10: KK 4876 İşbank | E10: =E40 -> -19043.61 | G10: =E10 -> -19043.61 | H10: =H9+F10+G10 -> -36002.02
H11: =H10+F11+G11 -> -36002.02
H12: =H11+F12+G12 -> -36002.02
H13: =H12+F13+G13 -> -36002.02
A14: 45723 | B14: Kira Adem Özen 10/12 Mrmr Ryl A Blok 82 | E14: -17500 | H14: =H13+F14+G14 -> -36002.02
H15: =H14+F15+G15 -> -36002.02
H16: =H15+F16+G16 -> -36002.02
H17: =H16+F17+G17 -> -36002.02
B18: Doğalgaz 800004222954 Kümbet D10 | E18: -1000 | H18: =H17+F18+G18 -> -36002.02
B19: Doğalgaz 800004222959 Kümbet D09 | E19: -200 | H19: =H18+F19+G19 -> -36002.02
B20: Doğalgaz Marmara Royal Ablok D:82 | E20: -200 | H20: =H19+F20+G20 -> -36002.02
B21: maaş | D21: 15000 | H21: =H20+F21+G21 -> -36002.02
B22: yasemin | E22: -7500 | H22: =H21+F22+G22 -> -36002.02
B23: umut | E23: -7500 | H23: =H22+F23+G23 -> -36002.02
B24: Genel Masraf | E24: -7500 | H24: =H23+F24+G24 -> -36002.02
H25: =H24+F25+G25 -> -36002.02
H26: =H25+F26+G26 -> -36002.02
A27: 45716 | B27: SANAYI BELEDIYE SAYC UCRETI | C27: 2024 / 8/9 | E27: -1380 | H27: =H26+F27+G27 -> -36002.02
B28: Elektrik 5847500300 Kümbet D09 | E28: -600 | H28: =H27+F28+G28 -> -36002.02
B29: Elektrik 8222520300 Kümbet D10 | E29: -800 | H29: =H28+F29+G29 -> -36002.02
H30: =H29+F30+G30 -> -36002.02
H31: =H30+F31+G31 -> -36002.02
B32: TUSDATA 2025 23/30 70760 - 8845 = 61915 | H32: =H31+F32+G32 -> -36002.02
H33: =H32+F33+G33 -> -36002.02
H34: =H33+F34+G34 -> -36002.02
B40: İşbank 4876 KK | E40: =SUM(E41:E58) -> -19043.61
A42: 45715 | B42: turknet 12 aylık internet | C42: 5938.7 | D42: 1 - 6 | E42: -989.78 | F42: 0
A43: 45715 | B43: BELEDİYE sanayi sayaç 5-6 taksitler | E43: -2820 | F43: 0
A44: 45715 | B44: belediye hmb 2024 emlak-su | E44: -3196.34 | F44: 0
A45: 45715 | B45: belediye ayşe balcı | E45: -467.95 | F45: 0
A46: 45715 | B46: BELEDİYE PERİ BORÇ YOK
A48: 45691 | B48: elmacıoğlu iskender | E48: -1580 | F48: 0
...

Sheet 02_25
F1: GİRİŞ | G1: ÇIKIŞ | H1: BAKİYE
A2: - ŞUBAT 2025 | C2: TOPLAM | D2: =SUM(D4:D31) -> 45000 | E2: =SUM(E4:E32) -> -75400.4 | F2: =SUM(F4:F32) -> 30054.88 | G2: =SUM(G4:G32) -> -96628.72 | H2: =F2+G2 -> -66573.84
H4: =H3+F4+G4 -> 0
H5: =H4+F5+G5 -> 0
H6: =H5+F6+G6 -> 0
A7: 45692 | B7: KK 4876 İşbank | E7: =E37 -> 0 | G7: =E7 -> 0 | H7: =H6+F7+G7 -> 0
A8: 45691 | B8: KK 5165 Denizbank | E8: =E52 -> -29103.34 | G8: =E8 -> -29103.34 | H8: =H7+F8+G8 -> -29103.34
A9: 45873 | B9: emrullah özere - ali demirel avukatlık ücreti | G9: -18000 | H9: =H8+F9+G9 -> -47103.34
A10: 45692 | B10: Aidat Marmara Royal Site 9/12 | E10: -2117.06 | G10: -2116.98 | H10: =H9+F10+G10 -> -49220.32
A11: 45699 | B11: Kira Adem Özen 9/12 Mrmr Ryl A Blok 82 | E11: -17500 | G11: -17500 | H11: =H10+F11+G11 -> -66720.32
A12: 45699 | B12: Doğalgaz Marmara Royal Ablok D:82 | E12: -200 | G12: -391.01 | H12: =H11+F12+G12 -> -67111.33
B13: Elektrik 9522138254 Sanayi | E13: 0 | H13: =H12+F13+G13 -> -67111.33
A14: 45705 | B14: Doğuş Kira 6/12-2025-26 | D14: 15000 | F14: 15000 | H14: =H13+F14+G14 -> -52111.33
A15: 45705 | B15: Doğalgaz 800004222954 Kümbet D10 | E15: -1000 | G15: -2305 | H15: =H14+F15+G15 -> -54416.33
A16: 45705 | B16: Doğalgaz 800004222959 Kümbet D09 | E16: -200 | G16: -40 | H16: =H15+F16+G16 -> -54456.33
A17: 45709 | B17: ali demirel ihtar noter msrf için av. Emrullaha havale | G17: -2391.39 | H17: =H16+F17+G17 -> -56847.72
H18: =H17+F18+G18 -> -56847.72
B19: maaş | D19: 15000 | F19: 15054.88 | H19: =H18+F19+G19 -> -41792.84
B20: yasemin | E20: -7500 | G20: -7502 | H20: =H19+F20+G20 -> -49294.84
B21: umut | E21: -7500 | G21: -7502 | H21: =H20+F21+G21 -> -56796.84
B22: Genel Masraf | E22: -7500 | G22: -7502 | H22: =H21+F22+G22 -> -64298.84
H23: =H22+F23+G23 -> -64298.84
H24: =H23+F24+G24 -> -64298.84
A25: 45716 | B25: SANAYI BELEDIYE SAYC UCRETI | C25: 2024 / 7/9 iş kk | E25: -1380 | G25: -1380 | H25: =H24+F25+G25 -> -65678.84
A26: 45716 | B26: Elektrik 5847500300 Kümbet D09 | E26: -600 | G26: -325 | H26: =H25+F26+G26 -> -66003.84
A27: 45716 | B27: Elektrik 8222520300 Kümbet D10 | E27: -800 | G27: -570 | H27: =H26+F27+G27 -> -66573.84
B28: Doğuş Kira 7/12-2025-26 | D28: 15000 | H28: =H27+F28+G28 -> -66573.84
H29: =H28+F29+G29 -> -66573.84
B30: TUSDATA 2025 22/30 79605 - 8845 = 70760 | H30: =H29+F30+G30 -> -66573.84
H31: =H30+F31+G31 -> -66573.84
H32: =H31+F32+G32 -> -66573.84
H35: 15000
G36: 2025 01 tüfe | H36: 0.5635
B37: İşbank 4876 KK | E37: =SUM(E38:E49) -> 0 | H37: =H36*H35 -> 8452.5
E38: HESAP KESİM | G38: doğuş | H38: =SUM(H37+H35) -> 23452.5
B52: Denizbank 5165 kk | E52: =SUM(E53:E98) -> -29103.34
A56: 46018 | B56: cevizli | E56: -135
A57: 46016 | B57: kkasap | E57: -240
A58: 46015 | B58: pideci mustafa | E58: -550
A59: 46020 | B59: pegasus kıbrıs umut mezuniyet peri-atila-hc kysr | E59: -12762 | F59: 0
...

Sheet 01_25
F1: GİRİŞ | G1: ÇIKIŞ | H1: BAKİYE
A2: - OCAK 2025 | C2: TOPLAM | D2: =SUM(D4:D44) -> 398664 | E2: =SUM(E4:E44) -> -55562.4 | F2: =SUM(F4:F44) -> 320054.88 | G2: =SUM(G4:G44) -> -59018.87 | H2: =F2+G2 -> 261036.01
H4: =H3+F4+G4 -> 0
H5: =H4+F5+G5 -> 0
A6: 45660 | B6: SnyB salih ant 16 asgari ücret * 22104 = 353664 | H6: =H5+F6+G6 -> 0
A7: 45660 | B7: SnyB salih ant bankadan | D7: 353664 | F7: 290000 | H7: =H6+F7+G7 -> 290000
B8: umut banka hesabı – hmb hesaba havale – 801 – 209 nazan | H8: =H7+F8+G8 -> 290000
A9: 45660 | B9: KK 4876 İşbank | E9: =E67 -> 0 | G9: =E9 -> 0 | H9: =H8+F9+G9 -> 290000
A10: 45660 | B10: KK 5165 Denizbank | E10: =E82 -> -7885.34 | G10: =E10 -> -7885.34 | H10: =H9+F10+G10 -> 282114.66
H11: =H10+F11+G11 -> 282114.66
B12: Aidat Marmara Royal Site 9/12 | E12: -2117.06 | G12: =E12 -> -2117.06 | H12: =H11+F12+G12 -> 279997.6
B13: Kira Adem Özen 8/12 Mrmr Ryl A Blok 82 | E13: -17500 | G13: =E13 -> -17500 | H13: =H12+F13+G13 -> 262497.6
B14: Elektrik 9522138254 Sanayi | E14: 0 | G14: 0 | H14: =H13+F14+G14 -> 262497.6
A15: 45671 | B15: Doğuş Kira 5/12-2025-26 bankadan | D15: 15000 | F15: 15000 | H15: =H14+F15+G15 -> 277497.6
H16: =H15+F16+G16 -> 277497.6
A17: 45677 | B17: Doğalgaz 800004222954 Kümbet D10 | E17: -1000 | G17: -2390 | H17: =H16+F17+G17 -> 275107.6
A18: 45677 | B18: Doğalgaz 800004222959 Kümbet D09 | E18: -200 | G18: -25 | H18: =H17+F18+G18 -> 275082.6
A19: 45677 | B19: Doğalgaz Marmara Royal Ablok D:82 | E19: -200 | G19: -288.97 | H19: =H18+F19+G19 -> 274793.63
H20: =H19+F20+G20 -> 274793.63
A21: 45684 | B21: yasemin 24 ocak için | G21: -4000 | H21: =H20+F21+G21 -> 270793.63
A22: 45684 | B22: yasemin | E22: -7500 | G22: -7501 | H22: =H21+F22+G22 -> 263292.63
A23: 45684 | B23: umut | E23: -7500 | G23: -7501 | H23: =H22+F23+G23 -> 255791.63
A24: 45684 | B24: Genel Masraf | E24: -7500 | G24: -7500 | H24: =H23+F24+G24 -> 248291.63
A25: 45684 | B25: ahmet alp karne | G25: -1000 | H25: =H24+F25+G25 -> 247291.63
A26: 45655 | B26: SANAYI BELEDIYE SAYC UCRETI | C26: 2024 / 5/9 | E26: -1380 | H26: =H25+F26+G26 -> 247291.63
A27: 45686 | B27: SANAYI BELEDIYE SAYC UCRETI | C27: 2024 / 6/9 | E27: -1380 | H27: =H26+F27+G27 -> 247291.63
A28: 45684 | B28: emlak vergileri İŞ KK İLE ÖDENDİ AYŞE-HMB - PERİ BORC YOK | H28: =H27+F28+G28 -> 247291.63
B29: turknet yıllık internet | C29: dnz kk | H29: =H28+F29+G29 -> 247291.63
H30: =H29+F30+G30 -> 247291.63
A31: 45688 | B31: Elektrik 5847500300 Kümbet D09 | E31: -600 | G31: -425 | H31: =H30+F31+G31 -> 246866.63
A32: 45688 | B32: Elektrik 8222520300 Kümbet D10 | E32: -800 | G32: -680 | H32: =H31+F32+G32 -> 246186.63
A33: 45688 | B33: voda 2240 | G33: -205.5 | H33: =H32+F33+G33 -> 245981.13
B34: Doğuş Kira 6/12-2025-26 | D34: 15000 | H34: =H33+F34+G34 -> 245981.13
B35: maaş | D35: 15000 | F35: 15054.88 | H35: =H34+F35+G35 -> 261036.01
B36: TUSDATA 2025 21/30 1*8595 = 8595-250 = 8345 | H36: =H35+F36+G36 -> 261036.01
H37: =H36+F37+G37 -> 261036.01
B47: TUSDATA 2023 8/30 8*250 = 2000 ÖDENDİ
B48: TUSDATA 2024 9/30 – 20/30 12*250 = 3000 ÖDENDİ + 250 TL fazla ödeme yapıldı
B49: TUSDATA 2025 21/30 1*8595 = 8595
B50: TUSDATA 2025 22/30-30/30 9*8845 = 79605
...

Sheet PERI_24
B2: 2024 | C2: hesaba yazılmayan | D2: hacı ödeme | E2: peri ödeme | F2: BAKİYE
A5: 45291 | B5: 2023 den devir PERİ BORÇLU | F5: 1072
A6: 45306 | B6: aliden kredi için alınan 15/01/2024 taksidi | E6: 3450 | F6: =F5+D6-E6 -> -2378
A7: 45309 | B7: audi mtv 2024-1 | D7: 899 | F7: =F6+D7-E7 -> -1479
A8: 45309 | B8: trafik cezası maliyeden | D8: 1093.65 | F8: =F7+D8-E8 -> -385.35
A9: 45310 | B9: ankaraya giderken nakit (umut) | D9: 1000 | F9: =F8+D9-E9 -> 614.65
A10: 45319 | B10: trafik cezası muhtardan | C10: 713.25 | F10: =F9+D10-E10 -> 614.65
B11: kayseri otobüs bileti | D11: 1200 | F11: =F10+D11-E11 -> 1814.65
A12: 45366 | B12: 1 adet çeyrek | D12: 4100 | F12: =F11+D12-E12 -> 5914.65
A13: 45366 | B13: işbanktan hacıya havale | E13: 6300 | F13: =F12+D13-E13 -> -385.35
A14: 45366 | B14: işbanktan periye havale kred iiçin | D14: 3450 | F14: =F13+D14-E14 -> 3064.65
A15: 45366 | B15: ziraat kredi ödemesi | E15: 3461 | F15: =F14+D15-E15 -> -396.35
A16: 45371 | B16: audi teker porya-yazlık lastik değişimi | C16: 3350 | F16: =F15+D16-E16 -> -396.35
A17: 45412 | B17: panter testere 1/9 | E17: 500 | F17: =F16+D17-E17 -> -896.35
A18: 45398 | B18: işbanktan periye havale kred iiçin | D18: 3467 | E18: 3461 | F18: =F17+D18-E18 -> -890.35
B19: azaerbaycan otel için 240 usd *32 | E19: 7680 | F19: =F18+D19-E19 -> -8570.35
A20: 45427 | B20: ali kredi için -ali bankaya yatırmış | F20: =F19+D20-E20 -> -8570.35
A21: 45442 | B21: panter testere 2/9 | E21: 500 | F21: =F20+D21-E21 -> -9070.35
A22: 45442 | B22: audi kaza için alınan | E22: 120000 | F22: =F21+D22-E22 -> -129070.35
A23: 45442 | B23: audi kaza için harcanan | D23: 21000 | F23: =F22+D23-E23 -> -108070.35
A24: 45458 | B24: aliden kredi için alınan 15/06/2024 taksidi | D24: 3450 | F24: =F23+D24-E24 -> -104620.35
A25: 45458 | B25: ziraate havale kredi için bayram öncesi | E25: 3467 | F25: =F24+D25-E25 -> -108087.35
A26: 45453 | B26: benzin | C26: 1500 | F26: =F25+D26-E26 -> -108087.35
B27: trafik cezaı yıldızeli | C27: 1300 | F27: =F26+D27-E27 -> -108087.35
A28: 45470 | B28: çeyrek 5 ad. 4030 * 5 | D28: 20150 | F28: =F27+D28-E28 -> -87937.35
A29: 45473 | B29: panter testere 3/9 | E29: 500 | F29: =F28+D29-E29 -> -88437.35
A30: 45487 | B30: elden nakit aliden alınan kredi için | D30: 3500 | F30: =F29+D30-E30 -> -84937.35
A31: 45487 | B31: peri ziraat kredi ödemesi taksit 76 | E31: 3465.81 | F31: =F30+D31-E31 -> -88403.16
A32: 45503 | B32: panter testere 4/9 -9/9 6 taksit | E32: 3000 | F32: =F31+D32-E32 -> -91403.16
B33: ARACI ALMADAN ÖNCE HACI BORÇ TOPLAMI | F33: =F32+D33-E33 -> -91403.16
B35: tcross 12-8-2024 | D35: 1466500 | F35: =D35-E35 -> 1466500
B36: sigorta | D36: 11631 | F36: =F35+D36-E36 -> 1478131
B37: kasko | D37: 15500 | F37: =F36+D37-E37 -> 1493631
B38: ARAÇ TOPLAM MALİYET | F38: =F37+D38-E38 -> 1493631
F39: =F38+D39-E39 -> 1493631
B40: ARAÇ ÖNCESİ HESAP | E40: =F33*-1 -> 91403.16 | F40: =F39+D40-E40 -> 1402227.8
B41: TRAFİK SİGORTASI | E41: 11631 | F41: =F40+D41-E41 -> 1390596.8
B42: KASKO 9 taksitte ödenecek peri kk | E42: 15500 | F42: =F41+D42-E42 -> 1375096.8
B43: atiladan yasemine araba için | E43: 100000 | F43: =F42+D43-E43 -> 1275096.8
B44: Yasemin + dersanedwn | E44: 75000 | F44: =F43+D44-E44 -> 1200096.8
...

Sheet cross
E2: gr | F2: 2513
E3: çeyrek | F3: 4100
E4: s1 | F4: 26.15
E5: iş 801
D7: adet | E7: fiyat | F7: tutar | H7: bakiye
A8: gelen | B8: 44562 | C8: 94,25 gr bilezik * 2400 TL/gr (22 ayar) | D8: 94.25 | E8: 2400 | F8: 225000
A9: altın | B9: 44562 | C9: 78 çeyrek * 4200 | D9: 78 | E9: 4200 | F9: 325000
B11: 45509 | C11: iş 801 | D11: 779 | E11: 710.60565 | F11: =E11*D11 -> 553561.8 | G11: =F11 -> 553561.8 | H11: =G11 -> 553561.8
A14: pervin | B14: 45509 | C14: pervin 13 ad çeyrek *4200 benim kasada | D14: 13 | E14: =$F$3 -> 4100 | F14: =E14*D14 -> 53300 | H14: =H11+F14 -> 606861.8
B15: 45357 | C15: pervin 6 ad çeyrek *4200 benim kasada | D15: 6 | E15: =$F$3 -> 4100 | F15: =E15*D15 -> 24600 | H15: =H14+F15 -> 631461.8
C16: pervin 1 ad tam *16200 benim kasada | D16: 1 | E16: 16000 | F16: =E16*D16 -> 16000 | H16: =H15+F16 -> 647461.8
C17: pervin 1 ad gram *2500 benim kasada | D17: 1 | E17: =$F$2 -> 2513 | F17: =E17*D17 -> 2513 | H17: =H16+F17 -> 649974.8
C18: pervin banka 10 kasada | D18: 10 | E18: =$F$3 -> 4100 | F18: =E18*D18 -> 41000 | G18: =SUM(F14:F18) -> 137413 | H18: =H17+F18 -> 690974.8
A20: hacı | B20: 45509 | C20: okul parasından gelecek (nakit) | D20: 1 | E20: 60000 | F20: =E20*D20 -> 60000 | H20: =H18+F20 -> 750974.8
C21: gr altın 5 * 2500 OKUL PARASI KALSIN | D21: 5 | E21: =$F$2 -> 2513 | F21: =E21*D21 -> 12565
C22: gr altın 36 * 2500 (audi) | D22: 32 | E22: =$F$2 -> 2513 | F22: =E22*D22 -> 80416 | H22: =H20+F22 -> 831390.8 | I22: BOZ
C23: gr altın 94 * 2520 | D23: 93 | E23: =$F$2 -> 2513 | F23: =E23*D23 -> 233709 | H23: =H22+F23 -> 1065099.8 | I23: BOZ
C24: dolsr 850 *32 OKUL PARASI KALSIN | D24: 850 | E24: 31 | F24: =E24*D24 -> 26350 | I24: BOZ
C25: s1 25,93*7500 | D25: 7500 | E25: =$F$4 -> 26.15 | F25: =E25*D25 -> 196125 | G25: =SUM(F20:F25) -> 609165 | H25: =H23+F25 -> 1261224.8 | I25: BOZ
A27: yasemin | B27: satıldı | C27: s1 | D27: 471 | E27: =$F$4 -> 26.15 | F27: =E27*D27 -> 12316.65 | H27: =H25+F27 -> 1273541.4 | I27: boz
C28: ytr 801 | D28: 31 | E28: 709 | F28: =E28*D28 -> 21979 | H28: =H27+F28 -> 1295520.4 | I28: ASIL HESAP
B29: satıldı | C29: ytr 808 722 adet deil TL imiş | D29: 30 | E29: 722 | F29: =E29*D29 -> 21660 | H29: =H28+F29 -> 1317180.4 | I29: boz
C30: ytr 812 | D30: 3680 | E30: 0.85 | F30: =E30*D30 -> 3128 | H30: =H29+F30 -> 1320308.4 | I30: KALSIN
B31: satıldı | C31: gr OKUL PARASI KALSIN | D31: 77.3 | E31: =$F$2 -> 2513 | F31: =E31*D31 -> 194254.9 | G31: =SUM(F27:F31) -> 253338.55
H32: =H30+F32 -> 1320308.4
A33: Atila | C33: nakit | F33: 100000 | G33: =F33 -> 100000 | H33: =H32+F33 -> 1420308.4 | I33: GELECEK
A34: Ali | C34: nakit | F34: 68000 | G34: 68000 | H34: =H33+F34 -> 1488308.4 | I34: GELECEK
G42: ÖDEME | J42: KALAN
J43: 1500000
C44: uyasemin iş 801 | F44: 22058 | H44: =H43+F44-G44 -> 22058
A45: yasemin | C45: umut okul parasından umut -> peri > yasemin havale edildi | F45: 155000 | H45: =H44+F45-G45 -> 177058
C46: kaparo için doğuş otoya yaseminden havale | G46: 50000 | H46: =H45+F46-G46 -> 127058 | I46: ÖDENDİ | J46: =J43-G46 -> 1450000
C47: yasemin 808 den gelen | F47: 722 | H47: =H46+F47-G47 -> 127780 | I47: HESAPTA
H48: =H47+F48-G48 -> 127780
H49: =H48+F49-G49 -> 127780
C50: yasemin s1 den gelecek ÇARŞAMBA SATILDI | F50: 12290 | H50: =H49+F50-G50 -> 140070 | I50: GELECEK | J50: =J46-G50 -> 1450000
J51: =J50-H50 -> 1309930
B55: 45509 | C55: hacı iş 801 | D55: 779 | E55: 711.5756 | F55: =E55*D55 -> 554317.39 | H55: =H54+F55-G55 -> 554317.39 | I55: HESAPTA
H56: =H55+F56-G56 -> 554317.39
C57: gr | D57: 125 | E57: 2510 | F57: =E57*D57 -> 313750 | H57: =H56+F57-G57 -> 868067.39 | I57: GELECEK
...

Sheet GNLK-_2024
C1: TAHMİNİ | F1: GERÇEKLEŞEN | K1: NZN | L1: HC | N1: NY
A2: -2024 | B2: GİRİŞ | C2: ÇIKIŞ | D2: BAKİYE | E2: GİRİŞ | F2: ÇIKIŞ | G2: BAKİYE | J2: kR | K2: 0.235384 | L2: =1-K2 -> 0.764616 | M2: Hc 1/1 | N2: =F115/1000 -> 698.2203
A3: Ocak | B3: ='01_24'!D2 -> 340464.6 | C3: ='01_24'!E2 -> -52469.76 | D3: =B3+C3 -> 287994.84 | E3: ='01_24'!F2 -> 194911.58 | F3: ='01_24'!G2 -> -66377.21 | G3: =E3+F3 -> 128534.37 | I3: dgs | J3: 180 | M3: =J3 -> 180 | N3: ='01_24'!E118/1000 -> 813.15151
A4: Şubat | B4: ='02_24'!D2 -> 19300 | C4: ='02_24'!E2 -> -65325.85 | D4: =B4+C4+D3 -> 241968.99 | E4: ='02_24'!F2 -> 20543.64 | F4: ='02_24'!G2 -> -69834.74 | G4: =E4+F4+G3 -> 79243.27 | I4: sF | J4: 235 | K4: =J4*$K$2 -> 55.31524 | L4: =J4-K4 -> 179.68476 | N4: ='02_24'!E111/1000 -> 809.24983
A5: Mart | B5: ='03_24'!D2 -> 12800 | C5: ='03_24'!E2 -> -114592.82 | D5: =B5+C5+D4 -> 140176.17 | E5: ='03_24'!F2 -> 19667.49 | F5: ='03_24'!G2 -> -116144.16 | G5: =E5+F5+G4 -> -17233.4 | I5: tzg | M5: =J5 -> 0 | N5: ='03_24'!E108/1000 -> 745.85205
A6: Nisan | B6: ='04_24'!D2 -> 40000 | C6: ='04_24'!E2 -> -51710.3 | D6: =B6+C6+D5 -> 128465.87 | E6: ='04_24'!F2 -> 332427.62 | F6: ='04_24'!G2 -> -86892.22 | G6: =E6+F6+G5 -> 228302 | I6: maaş ocak-haziran | M6: =E18/1000 -> 68.50557 | N6: ='04_24'!E111/1000 -> 774.28774
A7: Mayıs | B7: ='05_24'!D2 -> 25000 | C7: ='05_24'!E2 -> -64525.01 | D7: =B7+C7+D6 -> 88940.86 | E7: ='05_24'!F2 -> 25427.62 | F7: ='05_24'!G2 -> -64483.92 | G7: =E7+F7+G6 -> 189245.7 | I7: maaş temmuz-aralık | M7: =E19/1000 -> 77.93537 | N7: ='05_24'!E101/1000 -> 1018.9679
A8: Hazrn | B8: ='06_24'!D2 -> 33500 | C8: ='06_24'!E2 -> -77377.564 | D8: =B8+C8+D7 -> 45063.296 | E8: ='06_24'!F2 -> 13427.62 | F8: ='06_24'!G2 -> -97778.154 | G8: =E8+F8+G7 -> 104895.17 | I8: lise | J8: 225 | M8: =J8/4 -> 56.25 | N8: ='06_24'!E118/1000 -> 794.30216
A9: Temmz | B9: ='07_24'!D2 -> 51000 | C9: ='07_24'!E2 -> -85166.06 | D9: =B9+C9+D8 -> 10897.236 | E9: ='07_24'!F2 -> 27984.15 | F9: ='07_24'!G2 -> -87971.62 | G9: =E9+F9+G8 -> 44907.696 | I9: sE | J9: 204 | K9: =J9*$K$2 -> 48.018336 | L9: =J9-K9 -> 155.98166 | N9: ='07_24'!E133/1000 -> 981.30373
A10: Ağusts | B10: ='08_24'!D2 -> 195484.15 | C10: ='08_24'!E2 -> -88440.67 | D10: =B10+C10+D9 -> 117940.72 | E10: ='08_24'!F2 -> 28006.38 | F10: ='08_24'!G2 -> -88381.87 | G10: =E10+F10+G9 -> -15467.794 | I10: ap | J10: 500 | M10: =J10*0.13 -> 65 | N10: ='08_24'!E125/1000 -> 981.30373
A11: Eylül | B11: ='09_24'!D2 -> 36484.15 | C11: ='09_24'!E2 -> -81364.9 | D11: =B11+C11+D10 -> 73059.966 | E11: ='09_24'!F2 -> 98006.38 | F11: ='09_24'!G2 -> -69863.54 | G11: =E11+F11+G10 -> 12675.046 | I11: sG | J11: 0 | K11: =J11*$K$2 -> 0 | L11: =J11-K11 -> 0 | N11: ='09_24'!E101/1000 -> 749.1966
A12: Ekim | B12: ='10_24'!D2 -> 27984.15 | C12: ='10_24'!E2 -> -126233.27 | D12: =B12+C12+D11 -> -25189.154 | E12: ='10_24'!F2 -> 64006.38 | F12: ='10_24'!G2 -> -123041.59 | G12: =E12+F12+G11 -> -46360.164 | I12: sA | J12: 0 | K12: =J12*$K$2 -> 0 | L12: =J12-K12 -> 0 | N12: ='10_24'!E136/1000 -> 726.0586
A13: Kasım | B13: ='11_24'!D2 -> 277984.15 | C13: ='11_24'!E2 -> -182434.39 | D13: =B13+C13+D12 -> 70360.606 | E13: ='11_24'!F2 -> 212306.38 | F13: ='11_24'!G2 -> -220559.32 | G13: =E13+F13+G12 -> -54613.104 | I13: sCD | J13: 219 | K13: =J13*$K$2 -> 51.549096 | L13: =J13-K13 -> 167.4509 | N13: ='11_24'!E111/1000 -> 695.35238
A14: Aralık | B14: ='12_24'!D2 -> 27984.15 | C14: ='12_24'!E2 -> -62202.76 | D14: =B14+C14+D13 -> 36141.996 | E14: ='12_24'!F2 -> 246925.7 | F14: ='12_24'!G2 -> -130909.76 | G14: =E14+F14+G13 -> 61402.836 | I14: sB | J14: 170 | K14: =J14*$K$2 -> 40.01528 | L14: =J14-K14 -> 129.98472 | N14: ='12_24'!E125/1000 -> 674.75338
A15: TPLM | B15: =SUM(B3:B14) -> 1087985.4 | C15: =SUM(C3:C14) -> -1051843.4 | D15: =B15+C15 -> 36141.996 | E15: =SUM(E3:E14) -> 1283640.9 | F15: =SUM(F3:F14) -> -1222238.1 | G15: =E15+F15 -> 61402.836 | J15: =SUM(J3:J14) -> 1733 | K15: =SUM(K4:K14) -> 194.89795 | L15: =SUM(L4:L14) -> 633.10205 | M15: =M10+M8+M6+M5+M3+M7 -> 447.69094
A16: 12 | B16: =B15/A16 -> 90665.446 | C16: =C15/A16 -> -87653.613 | E16: =E15/A16 -> 106970.08 | F16: =F15/A16 -> -101853.18 | G16: =G15/A16 -> 5116.903 | J16: =J15/12 -> 144.41667 | K16: =K15/12 -> 16.241496 | L16: =L15/12 -> 52.758504 | M16: =M15/12 -> 37.307578 | N16: =AVERAGE(N2:N15) -> 804.76922
K17: TPLM | L17: =L15+M15 -> 1080.793
D18: ocak-haziran maaş toplamı | E18: ='01_24'!F27+'02_24'!F14+'02_24'!F25+'03_24'!F19+'04_24'!F41+'05_24'!F22+'06_24'!F19+'06_24'!F31+'04_24'!F15 -> 68505.57 | K18: AYLK | M18: =L17/12 -> 90.066082
D19: temmuz-aralık maaş toplamı | E19: ='07_24'!F30+'08_24'!F25+'09_24'!F19+'10_24'!F29+'11_24'!F34+'12_24'!F22 -> 77935.37
D20: Toplam ;Emekli maaşı | E20: =SUM(E18:E19) -> 146440.94
B21: 44896
B22: 6986.25 | C22: 0.375785 | D22: 0.4925919
B23: =B22*C22 -> 2625.328 | C23: ocak artış % | D23: =B22*D22 -> 3441.3702
B24: =SUM(B22:B23) -> 9611.578 | C24: ocak 23 maaş | D24: =D23+B22 -> 10427.62
C25: =(D27/D24)-1 -> 0.2473009
C26: temmuz artış
C27: temmuz 23 maaş | D27: 13006.38
B30: MAHKEME
C31: DEMİREL ARABULUCULUK
C32: MERDAL TAKİP
B34: FATURA
C35: ELEKTRİK
C36: KREDİ
B37: TZG
C38: ÖLÇÜM
C39: SINIR TESPİTİ
C40: DUVAR VE KAPI YAPIMI
C41: ELEKTRİK-SU ABONE İŞLEMLERİ
C42: ELEKTRİK TESİSAT
B43: BAHÇE
...

Sheet 12_24
F1: GİRİŞ | G1: ÇIKIŞ | H1: BAKİYE
A2: - ARALIK 2024 | C2: TOPLAM | D2: =SUM(D4:D40) -> 27984.15 | E2: =SUM(E4:E41) -> -62202.76 | F2: =SUM(F4:F40) -> 246925.7 | G2: =SUM(G4:G36) -> -130909.76 | H2: =F2+G2 -> 116015.94
H4: =H3+F4+G4 -> 0
A5: 45631 | B5: KK 4876 İşbank | E5: =E76 -> -1797.23 | G5: =E5 -> -1797.23 | H5: =H4+F5+G5 -> -1797.23
A6: 45630 | B6: KK 5165 Denizbank | E6: =E91 -> -9239.03 | G6: =E6 -> -9239.03 | H6: =H5+F6+G6 -> -11036.26
A7: 45630 | B7: Aidat Marmara Royal Site 9/12 | E7: -1500 | G7: -1512.13 | H7: =H6+F7+G7 -> -12548.39
B8: Kira Adem Özen 7/12 Mrmr Ryl A Blok 82 | E8: -17500 | G8: -17500 | H8: =H7+F8+G8 -> -30048.39
B9: Elektrik 9522138254 Sanayi | E9: =E71*-1 -> 0 | H9: =H8+F9+G9 -> -30048.39
H10: =H9+F10+G10 -> -30048.39
A11: 45630 | B11: SANAYI BELEDIYE SAYC UCRETI | C11: 2024 / 3 | D11: dnxkk | E11: -1380 | H11: =H10+F11+G11 -> -30048.39
A12: 45630 | B12: SANAYI BELEDIYE SAYC UCRETI | C12: 2024 / 4 | D12: dnxkk | E12: -1380 | H12: =H11+F12+G12 -> -30048.39
A13: 45630 | B13: BİNA VERGİSİ | D13: dnxkk | E13: -1415 | H13: =H12+F13+G13 -> -30048.39
A14: 45630 | B14: KÜLTÜR VERGİSİ | D14: dnxkk | E14: -141.5 | H14: =H13+F14+G14 -> -30048.39
B15: Nazan Kira ödemesi 12+ | G15: -60000 | H15: =H14+F15+G15 -> -90048.39
B16: umut kiradan | G16: -19000 | H16: =H15+F16+G16 -> -109048.39
B17: snyB Ali Demirel bankadan | F17: 219000 | H17: =H16+F17+G17 -> 109951.61
B18: Doğuş Kira 4/12-2025-26 | F18: 15000 | H18: =H17+F18+G18 -> 124951.61
A19: 45642 | B19: Doğalgaz 800004222954 Kümbet D10 | C19: devlet | E19: -300 | G19: -2035 | H19: =H18+F19+G19 -> 122916.61
A20: 45642 | B20: Doğalgaz 800004222959 Kümbet D09 | C20: devlet | E20: -100 | G20: -40 | H20: =H19+F20+G20 -> 122876.61
A21: 45638 | B21: Doğalgaz Marmara Royal Ablok D:82 | C21: devlet | E21: -150 | G21: -262.37 | H21: =H20+F21+G21 -> 122614.24
A22: 45653 | B22: maaş | D22: 12984.15 | F22: 12925.7 | H22: =H21+F22+G22 -> 135539.94
B23: yasemin | E23: -6500 | G23: -6512 | H23: =H22+F23+G23 -> 129027.94
B24: umut | E24: -6500 | G24: -6512 | H24: =H23+F24+G24 -> 122515.94
B25: Genel Masraf | E25: -6500 | G25: -6500 | H25: =H24+F25+G25 -> 116015.94
H26: =H25+F26+G26 -> 116015.94
H27: =H26+F27+G27 -> 116015.94
B28: Elektrik 5847500300 Kümbet D09 | E28: -400 | H28: =H27+F28+G28 -> 116015.94
B29: Elektrik 8222520300 Kümbet D10 | E29: -500 | H29: =H28+F29+G29 -> 116015.94
A30: 45671 | B30: Doğuş Kira 5/12-2025-26 | D30: 15000 | H30: =H29+F30+G30 -> 116015.94
H31: =H30+F31+G31 -> 116015.94
H32: =H31+F32+G32 -> 116015.94
H33: =H32+F33+G33 -> 116015.94
H34: =H33+F34+G34 -> 116015.94
A36: 45655 | B36: SANAYI BELEDIYE SAYC UCRETI | C36: 2024 / 5 | E36: -1380
A37: 45686 | B37: SANAYI BELEDIYE SAYC UCRETI | C37: 2024 / 6 | E37: -1380
A38: 45716 | B38: SANAYI BELEDIYE SAYC UCRETI | C38: 2024 / 7 | E38: -1380
A39: 45745 | B39: SANAYI BELEDIYE SAYC UCRETI | C39: 2024 / 8 | E39: -1380
A40: 45776 | B40: SANAYI BELEDIYE SAYC UCRETI | C40: 2024 / 9 | E40: -1380
B43: TUSDATA 2023 8/30 8*250 = 2000 ÖDENDİ
B44: TUSDATA 2024 9/30 – 20/30 12*250 = 3000 ÖDENDİ + 250 TL fazla ödeme yapıldı
...

Sheet 11_24
F1: GİRİŞ | G1: ÇIKIŞ | H1: BAKİYE
A2: - KASIM 2024 | C2: TOPLAM | D2: =SUM(D4:D38) -> 277984.15 | E2: =SUM(E4:E38) -> -182434.39 | F2: =SUM(F4:F38) -> 212306.38 | G2: =SUM(G4:G38) -> -220559.32 | H2: =F2+G2 -> -8252.94
E4: 0 | H4: =H3+F4+G4 -> 0
E5: 0 | H5: =H4+F5+G5 -> 0
B6: TUSDATA 19/30 | C6: 17-2-24 de toplu ödendi | E6: -250 | H6: =H5+F6+G6 -> 0
A7: 45596 | B7: KK 5165 Denizbank | E7: =E69 -> -129000.63 | G7: -129000.63 | H7: =H6+F7+G7 -> -129000.63
A8: 45597 | B8: Aidat Marmara Royal Site 9/12 | G8: -1512.13 | H8: =H7+F8+G8 -> -130512.76
A9: 45569 | B9: KK 4876 İşbank | E9: =E54 -> -1797.26 | G9: -1797.26 | H9: =H8+F9+G9 -> -132310.02
B10: Elektrik 9522138254 Sanayi | E10: =E49*-1 -> 0 | H10: =H9+F10+G10 -> -132310.02
A11: 45604 | B11: Kira Adem Özen 6/12 Mrmr Ryl A Blok 82 | E11: -17500 | G11: -17500 | H11: =H10+F11+G11 -> -149810.02
A12: 45605 | B12: Doğuş Kira 3/12-2025-26 | F12: 15000 | H12: =H11+F12+G12 -> -134810.02
A13: 45600 | B13: 2240 VODAFONE fatura | G13: -206.3 | H13: =H12+F13+G13 -> -135016.32
B14: Elektrik 5847500300 Kümbet D09 | E14: -400 | H14: =H13+F14+G14 -> -135016.32
B15: Elektrik 8222520300 Kümbet D10 | E15: -500 | H15: =H14+F15+G15 -> -135016.32
A16: 45607 | B16: snyF merdal kipel icra yoluyla avukattan | F16: 148500 | H16: =H15+F16+G16 -> 13483.68
H17: =H16+F17+G17 -> 13483.68
A18: 45617 | B18: Doğalgaz Marmara Royal Ablok D:82 | E18: -150 | G18: -146 | H18: =H17+F18+G18 -> 13337.68
A19: 45614 | B19: Doğalgaz 800004222954 Kümbet D10 | E19: -300 | G19: -850 | H19: =H18+F19+G19 -> 12487.68
A20: 45614 | B20: Doğalgaz 800004222959 Kümbet D09 | E20: -100 | G20: -25 | H20: =H19+F20+G20 -> 12462.68
H21: =H20+F21+G21 -> 12462.68
A22: 45620 | B22: tcross pervinden 7 | F22: 35800 | H22: =H21+F22+G22 -> 48262.68
A23: 45623 | B23: Nazan Kira ödemesi 11 + 8 + 9+ 10 | E23: -10000 | G23: -40000 | H23: =H22+F23+G23 -> 8262.68
A24: 45625 | B24: SANAYI BELEDIYE SAYC UCRETI | C24: 2024 / 4 | E24: -1380 | H24: =H23+F24+G24 -> 8262.68
A25: 45626 | B25: BİNA VERGİSİ | E25: -1415 | H25: =H24+F25+G25 -> 8262.68
A26: 45626 | B26: KÜLTÜR VERGİSİ | E26: -141.5 | H26: =H25+F26+G26 -> 8262.68
H27: =H26+F27+G27 -> 8262.68
B28: yasemin winter | G28: -5000 | H28: =H27+F28+G28 -> 3262.68
B29: yasemin | E29: -6500 | G29: -6511 | H29: =H28+F29+G29 -> -3248.32
B30: umut winter | G30: -5000 | H30: =H29+F30+G30 -> -8248.32
B31: umut | E31: -6500 | G31: -6511 | H31: =H30+F31+G31 -> -14759.32
B32: Genel Masraf | E32: -6500 | G32: -6500 | H32: =H31+F32+G32 -> -21259.32
H33: =H32+F33+G33 -> -21259.32
B34: maaş | D34: 12984.15 | F34: 13006.38 | H34: =H33+F34+G34 -> -8252.94
B35: Doğuş Kira 4/12-2025-26 | D35: 15000 | H35: =H34+F35+G35 -> -8252.94
B36: snyCD | C36: 0.234011 | D36: 250000 | H36: =H35+F36+G36 -> -8252.94
B40: --------------------------------------------------------------------------------------------------------------------------------------------------
A41: KALAN BAKİYELER
A43: 44929 | B43: 9522138254 Sanayi Elektrik | D43: =SUM(D44:D49) -> 0 | E43: =SUM(E44:E49) -> 0
B44: Salih Ant Elektrik
B45: Hurdacı Elektrik
...

Sheet 10_24
F1: GİRİŞ | G1: ÇIKIŞ | H1: BAKİYE
A2: - EKİM 2024 | C2: TOPLAM | D2: =SUM(D4:D35) -> 27984.15 | E2: =SUM(E4:E35) -> -126233.27 | F2: =SUM(F4:F35) -> 64006.38 | G2: =SUM(G4:G35) -> -123041.59 | H2: =F2+G2 -> -59035.21
H4: =H3+F4+G4 -> 0
B5: TUSDATA 18/30 | C5: 17-2-24 de toplu ödendi | E5: -250 | H5: =H4+F5+G5 -> 0
A6: 45568 | B6: Aidat Marmara Royal Site 9/12 | E6: -1500 | G6: -1513.12 | H6: =H5+F6+G6 -> -1513.12
A7: 45569 | B7: KK 5165 Denizbank | E7: =E66 -> -71389.3 | G7: -71389.3 | H7: =H6+F7+G7 -> -72902.42
A8: 45572 | B8: KK 4876 İşbank | E8: =E51 -> -3066.57 | G8: -3066.57 | H8: =H7+F8+G8 -> -75968.99
B9: Elektrik 9522138254 Sanayi | E9: =E46*-1 -> 0 | G9: 0 | H9: =H8+F9+G9 -> -75968.99
A10: 45573 | B10: Kira Adem Özen 5/12 Mrmr Ryl A Blok 82 | E10: -17500 | G10: -17500 | H10: =H9+F10+G10 -> -93468.99
A11: 45573 | B11: ali demirel keşif için avukata denizbank havale | G11: -7080.3 | H11: =H10+F11+G11 -> -100549.29
A12: 45574 | B12: Doğuş Kira 2/12-2025-26 | C12: bankadan | F12: 15000 | H12: =H11+F12+G12 -> -85549.29
H13: =H12+F13+G13 -> -85549.29
A14: 45580 | B14: tcross pervinden 5 | F14: 30000 | H14: =H13+F14+G14 -> -55549.29
A15: 45595 | B15: Elektrik 5847500300 Kümbet D09 | E15: -400 | G15: -435 | H15: =H14+F15+G15 -> -55984.29
A16: 45595 | B16: Elektrik 8222520300 Kümbet D10 | E16: -500 | G16: -785 | H16: =H15+F16+G16 -> -56769.29
A17: 45579 | B17: Elektrik 8758480300 BAHÇE | G17: -65 | H17: =H16+F17+G17 -> -56834.29
B18: Doğalgaz Marmara Royal Ablok D:82 | C18: devlet | E18: -150 | H18: =H17+F18+G18 -> -56834.29
A19: 45582 | B19: Doğalgaz 800004222954 Kümbet D10 | C19: devlet | E19: -300 | G19: -78 | H19: =H18+F19+G19 -> -56912.29
A20: 45582 | B20: Doğalgaz 800004222959 Kümbet D09 | C20: devlet | E20: -100 | G20: -43 | H20: =H19+F20+G20 -> -56955.29
H21: =H20+F21+G21 -> -56955.29
B22: yasemin okul kk denizbnk -120000 | H22: =H21+F22+G22 -> -56955.29
A23: 45594 | B23: SANAYI BELEDIYE SAYC UCRETI | C23: 2024 / 3 | D23: kk | E23: -1380 | G23: -1380 | H23: =H22+F23+G23 -> -58335.29
A24: 45595 | B24: 2240 vodafon | E24: -197.4 | G24: -206.3 | H24: =H23+F24+G24 -> -58541.59
A25: 45593 | B25: yasemin | E25: -6500 | G25: -6500 | H25: =H24+F25+G25 -> -65041.59
A26: 45593 | B26: umut | E26: -6500 | G26: -6500 | H26: =H25+F26+G26 -> -71541.59
B27: Genel Masraf | E27: -6500 | G27: -6500 | H27: =H26+F27+G27 -> -78041.59
H28: =H27+F28+G28 -> -78041.59
A29: 45592 | B29: maaş | D29: 12984.15 | F29: 13006.38 | H29: =H28+F29+G29 -> -65035.21
A30: 45590 | B30: tcross pervinden 6 | F30: 6000 | H30: =H29+F30+G30 -> -59035.21
B31: Doğuş Kira 3/12-2025-26 | D31: 15000 | H31: =H30+F31+G31 -> -59035.21
H32: =H31+F32+G32 -> -59035.21
B33: snyA 120000 | C33: 0.234011 | H33: =H32+F33+G33 -> -59035.21
B34: Nazan Kira ödemesi | E34: -10000
B37: --------------------------------------------------------------------------------------------------------------------------------------------------
A38: KALAN BAKİYELER
A40: 44929 | B40: 9522138254 Sanayi Elektrik | D40: =SUM(D41:D46) -> 0 | E40: =SUM(E41:E46) -> 0
B41: Salih Ant Elektrik
B42: Hurdacı Elektrik
B43: Cihan Elektrik
B44: Merdal
...

Sheet 09_24
F1: GİRİŞ | G1: ÇIKIŞ | H1: BAKİYE
A2: - EYLÜL 2024 | C2: TOPLAM | D2: =SUM(D4:D28) -> 36484.15 | E2: =SUM(E4:E28) -> -81364.9 | F2: =SUM(F4:F28) -> 98006.38 | G2: =SUM(G4:G28) -> -69863.54 | H2: =F2+G2 -> 28142.84
A4: 45534 | B4: 2240 Turkcell fatura | E4: -152 | G4: -162.11 | H4: =H3+F4+G4 -> -162.11
B5: TUSDATA 17/30 | C5: 17-2-24 de toplu ödendi | E5: -250 | H5: =H4+F5+G5 -> -162.11
A6: 45538 | B6: KK 5165 Denizbank | E6: =E61 -> -21576.4 | G6: =E6 -> -21576.4 | H6: =H5+F6+G6 -> -21738.51
A7: 45539 | B7: KK 4876 İşbank | E7: =E46 -> -8037.9 | G7: =E7 -> -8037.9 | H7: =H6+F7+G7 -> -29776.41
B8: Aidat Marmara Royal Site 9/12 | E8: -1500 | G8: -1514.73 | H8: =H7+F8+G8 -> -31291.14
B9: Kira Adem Özen 4/12 Mrmr Ryl A Blok 82 | E9: -17500 | G9: -17500 | H9: =H8+F9+G9 -> -48791.14
B10: Elektrik 9522138254 Sanayi | E10: =E41*-1 -> 0 | G10: -5 | H10: =H9+F10+G10 -> -48796.14
A11: 45544 | B11: Doğuş Kira 1/12-2025-26 | C11: BANKADAN | F11: 15000 | H11: =H10+F11+G11 -> -33796.14
A12: 45551 | B12: Doğalgaz 800004222954 Kümbet D10 | C12: devlet | E12: -300 | G12: -76 | H12: =H11+F12+G12 -> -33872.14
A13: 45551 | B13: Doğalgaz 800004222959 Kümbet D09 | C13: devlet | E13: -100 | G13: -34 | H13: =H12+F13+G13 -> -33906.14
A14: 45552 | B14: yasemin 2 maaş 17000*2 | F14: 34000 | H14: =H13+F14+G14 -> 93.86
A15: 45550 | B15: tcross pervinden 3 | F15: 30000 | H15: =H14+F15+G15 -> 30093.86
B16: yasemin | E16: -6500 | G16: -6500 | H16: =H15+F16+G16 -> 23593.86
B17: umut | E17: -6500 | G17: -6500 | H17: =H16+F17+G17 -> 17093.86
B18: Genel Masraf | E18: -6500 | G18: -6500 | H18: =H17+F18+G18 -> 10593.86
B19: maaş | D19: 12984.15 | F19: 13006.38 | H19: =H18+F19+G19 -> 23600.24
B20: Elektrik 5847500300 Kümbet D09 | E20: -400 | G20: -455 | H20: =H19+F20+G20 -> 23145.24
A21: 45565 | B21: Elektrik 8222520300 Kümbet D10 | E21: -500 | G21: -805 | H21: =H20+F21+G21 -> 22340.24
A22: 45564 | B22: SANAYI BELEDIYE SAYC UCRETI | C22: 2024 / 2 | D22: deniz kk | E22: -1398.6 | H22: =H21+F22+G22 -> 22340.24
A23: 45564 | B23: tcross pervinden 4 | F23: 6000 | H23: =H22+F23+G23 -> 28340.24
A24: 45565 | B24: 2240 vodafone | G24: -197.4 | H24: =H23+F24+G24 -> 28142.84
B25: Doğuş Kira 7/12-2024-25 15000 - 6500 (07/03) 29-Şubattan | D25: 8500 | H25: =H24+F25+G25 -> 28142.84
A26: 45574 | B26: Doğuş Kira 2/12-2025-26 | D26: 15000 | H26: =H25+F26+G26 -> 28142.84
B27: Nazan Kira ödemesi | E27: -10000 | H27: =H26+F27+G27 -> 28142.84
B28: Doğalgaz Marmara Royal Ablok D:82 | C28: devlet | E28: -150 | H28: =H27+F28+G28 -> 28142.84
A29: 45574 | B29: t-cross kurban sinana | G29: -10000 | H29: =H28+F29+G29 -> 18142.84
B30: snyG | C30: 0.234011 | D30: 144000 | H30: =H29+F30+G30 -> 18142.84
B32: --------------------------------------------------------------------------------------------------------------------------------------------------
A33: KALAN BAKİYELER
A35: 44929 | B35: 9522138254 Sanayi Elektrik | D35: =SUM(D36:D41) -> 0 | E35: =SUM(E36:E41) -> 0
B36: Salih Ant Elektrik
B37: Hurdacı Elektrik
B38: Cihan Elektrik
B39: Merdal
B40: Metin
B41: Hacı Elektrik
B46: İşbank 4876 KK | E46: =SUM(E47:E58) -> -8037.9
A48: 45348 | B48: Atasun Gözlük | C48: 1406 | D48: 6 – 6 | E48: -234.35
...

Sheet 08_24
F1: GİRİŞ | G1: ÇIKIŞ | H1: BAKİYE
A2: - AĞUSTOS 2024 | C2: TOPLAM | D2: =SUM(D4:D46) -> 195484.15 | E2: =SUM(E4:E46) -> -88440.67 | F2: =SUM(F4:F47) -> 28006.38 | G2: =SUM(G4:G47) -> -88381.87 | H2: =F2+G2 -> -60375.49
A4: 45500 | B4: 2240 Turkcell fatura | C4: iş | E4: -152 | G4: -166.9 | H4: =H3+F4+G4 -> -166.9
B5: TUSDATA 16/30 | C5: 17-2-24 de toplu ödendi | E5: -250 | H5: =H4+F5+G5 -> -166.9
A6: 45509 | B6: Aidat Marmara Royal Site 9/12 | E6: -1500 | G6: -1532.3 | H6: =H5+F6+G6 -> -1699.2
A7: 45509 | B7: KK 4876 İşbank | E7: =E63 -> -8154.2 | G7: -8154.2 | H7: =H6+F7+G7 -> -9853.4
A8: 45509 | B8: KK 5165 Denizbank | E8: =E78 -> -21980.09 | G8: -21980.09 | H8: =H7+F8+G8 -> -31833.49
B9: umut s24 | G9: -10000 | H9: =H8+F9+G9 -> -41833.49
H10: =H9+F10+G10 -> -41833.49
A11: 45510 | B11: Doğuş Kira 12/12- Mart 2024- Mart 25 Ödenmiş oldu | D11: 15000 | F11: 15000 | H11: =H10+F11+G11 -> -26833.49
A12: 45511 | B12: Kira Adem Özen 3/12 Mrmr Ryl A Blok 82 | E12: -17500 | G12: -17500 | H12: =H11+F12+G12 -> -44333.49
B13: Elektrik 9522138254 Sanayi | E13: =E58*-1 -> 0 | G13: -50 | H13: =H12+F13+G13 -> -44383.49
A14: 45519 | B14: tcross pervinden 1 - 30000 | H14: =H13+F14+G14 -> -44383.49
A15: 45520 | B15: Elektrik 8758480300 Bahçe | G15: -95 | H15: =H14+F15+G15 -> -44478.49
A16: 45523 | B16: Doğalgaz 800004222954 Kümbet D10 | C16: devlet | E16: -300 | G16: -56 | H16: =H15+F16+G16 -> -44534.49
A17: 45523 | B17: Doğalgaz 800004222959 Kümbet D09 | C17: devlet | E17: -100 | G17: -28 | H17: =H16+F17+G17 -> -44562.49
A18: 45533 | B18: Elektrik 5847500300 Kümbet D09 | E18: -400 | G18: -500 | H18: =H17+F18+G18 -> -45062.49
A19: 45533 | B19: Elektrik 8222520300 Kümbet D10 | E19: -500 | G19: -865 | H19: =H18+F19+G19 -> -45927.49
B20: yasemin | H20: =H19+F20+G20 -> -45927.49
B21: yasemin | E21: -6500 | G21: -6500 | H21: =H20+F21+G21 -> -52427.49
B22: umut | E22: -6500 | G22: -6500 | H22: =H21+F22+G22 -> -58927.49
B23: Genel Masraf | E23: -6500 | G23: -6500 | H23: =H22+F23+G23 -> -65427.49
H24: =H23+F24+G24 -> -65427.49
B25: maaş | D25: 12984.15 | F25: 13006.38 | H25: =H24+F25+G25 -> -52421.11
H26: =H25+F26+G26 -> -52421.11
H27: =H26+F27+G27 -> -52421.11
A28: 45531 | B28: 3074 usulsuzluk 2024071001FCp0000016 | D28: ali balcı | E28: -750 | G28: =E28 -> -750 | H28: =H27+F28+G28 -> -53171.11
A29: 45531 | B29: 3074 usulsuzluk 2024071001FCp0000017 | D29: ali balcı | E29: -2137.5 | G29: =E29 -> -2137.5 | H29: =H28+F29+G29 -> -55308.61
A30: 45531 | B30: 3074 usulsuzluk 2024071001FCp0000018 | D30: ali balcı | E30: -925 | G30: =E30 -> -925 | H30: =H29+F30+G30 -> -56233.61
A31: 45531 | B31: 3074 usulsuzluk 2024071001FCp0000019 | D31: ali balcı | E31: -625 | G31: =E31 -> -625 | H31: =H30+F31+G31 -> -56858.61
A32: 45531 | B32: 3074 usulsuzluk 2024071001FCp0000020 | D32: ali balcı | E32: -1075 | G32: =E32 -> -1075 | H32: =H31+F32+G32 -> -57933.61
A33: 45531 | B33: 3074 usulsuzluk 2024071001FCp0000021 | D33: ali balcı | E33: -1825 | G33: =E33 -> -1825 | H33: =H32+F33+G33 -> -59758.61
H34: =H33+F34+G34 -> -59758.61
A35: 45531 | B35: 3074 DV 2024071001FCp0000022 | C35: ali balcı | D35: 19-09 ödeme | E35: -136.08 | G35: -136.08 | H35: =H34+F35+G35 -> -59894.69
A36: 45531 | B36: 3074 DV 2024071001FCp0000023 | C36: ali balcı | D36: 19-09 ödeme | E36: -258.61 | G36: -258.61 | H36: =H35+F36+G36 -> -60153.3
A37: 45531 | B37: 3074 DV 2024071001FCp0000024 | C37: ali balcı | D37: 19-09 ödeme | E37: -119.07 | G37: -119.07 | H37: =H36+F37+G37 -> -60272.37
A38: 45531 | B38: 3074 DV 2024071901FCp0000005 | C38: ali balcı | D38: 19-09 ödeme | E38: -103.12 | G38: -103.12 | H38: =H37+F38+G38 -> -60375.49
H39: =H38+F39+G39 -> -60375.49
A40: 45535 | B40: tcross pervinden 2 -5600 | H40: =H39+F40+G40 -> -60375.49
H41: =H40+F41+G41 -> -60375.49
...

Sheet 07_24
F1: GİRİŞ | G1: ÇIKIŞ | H1: BAKİYE
A2: - TEMMUZ 2024 | C2: TOPLAM | D2: =SUM(D4:D39) -> 51000 | E2: =SUM(E4:E39) -> -85166.06 | F2: =SUM(F4:F39) -> 27984.15 | G2: =SUM(G4:G39) -> -87971.62 | H2: =F2+G2 -> -59987.47
A4: 45468 | B4: 2240 Turkcell fatura | E4: -152 | G4: -167 | H4: =H3+F4+G4 -> -167
H5: =H4+F5+G5 -> -167
A6: 45474 | B6: Elektrik 5847500300 Kümbet D09 | E6: -400 | G6: -275 | H6: =H5+F6+G6 -> -442
A7: 45474 | B7: Elektrik 8222520300 Kümbet D10 | E7: -500 | G7: -520 | H7: =H6+F7+G7 -> -962
