Workbook

Sheet Sayfa2
E1: Toplam Yatırım | I1: Satış | K1: NET TL
B2: 45408 | K2: =SUM(K5:K6) -> 269021.68
B3: 43803 | C3: =B2-B3 -> 1605 | D3: =K2/C3 -> 167.61476
D5: Mevcut | E5: =SUBTOTAL(109,E10:E28) -> 343252.62 | I5: =SUM(I11:I27) -> 605826.9 | K5: =SUBTOTAL(109,K10:K28) -> 250521.5 | L5: =K5/E5 -> 0.72984587 | M5: =SUBTOTAL(101,M10:M18) -> -0.041340983 | N5: =SUBTOTAL(101,N10:N18) -> #DIV/0!
D6: Satılan | E6: =SUBTOTAL(109,E31:E78) -> 472117.66 | I6: =SUBTOTAL(109,I31:I78) -> 483665.72 | K6: =SUBTOTAL(109,K31:K77) -> 18500.177 | L6: =K6/E6 -> 0.039185523
B8: ALIŞ | C8: ALIŞ | D8: ALIŞ | E8: ALIŞ | F8: SATIŞ | G8: SATIŞ | H8: SATIŞ | I8: SATIŞ | J8: FARK | K8: FARK | L8: GÜN | M8: GÜN | N8: AY
A9: Açıklama | B9: tarih | C9: adet | D9: birim fiyat | E9: Tutar | F9: Tarih2 | G9: Miktar | H9: Fiyat | I9: Tutar3 | J9: Miktar3 | K9: Tutar2 | L9: Mktr | M9: % | N9: %
A11: Mevcut | O11: =SUM(O12:O28) -> 250521.5
A14: ALTIN.S1 | B14: 45408 | C14: 2500 | D14: 25.12 | E14: =Sayfa2!$D14*Sayfa2!$C14 -> 62800 | F14: =$B$2 -> 45408 | G14: =Tablo2[[#This Row],[adet]] -> 2500 | H14: =Sayfa4!I5 -> 25.11 | I14: =Sayfa2!$H14*Sayfa2!$G14 -> 62775 | J14: =H14-D14 -> -0.01 | K14: =Sayfa2!$J14*Sayfa2!$C14 -> -25 | L14: =F14-B14 -> 0 | M14: =K14/E14 -> -0.00039808917 | N14: =M14/L14*30 -> #DIV/0! | P14: 240426000157372
A15: ALTIN.S1 | J15: komisyon-bsmv | K15: -131.88 | P15: 240426000157372
A16: RGYAS | B16: 45404 | C16: 10 | D16: 135 | E16: =Sayfa2!$D16*Sayfa2!$C16 -> 1350 | F16: =$B$2 -> 45408 | G16: =Tablo2[[#This Row],[adet]] -> 10 | H16: =Sayfa4!Y5 -> 148.5 | I16: =Sayfa2!$H16*Sayfa2!$G16 -> 1485 | J16: =H16-D16 -> 13.5 | K16: =Sayfa2!$J16*Sayfa2!$C16 -> 135 | L16: =F16-B16 -> 4 | M16: =K16/E16 -> 0.1 | N16: =M16/L16*30 -> 0.75
A17: TTE Fon | B17: 45348 | C17: 75000 | D17: 1.064435 | E17: =Sayfa2!$D17*Sayfa2!$C17 -> 79832.625 | F17: =$B$2 -> 45408 | G17: =Tablo2[[#This Row],[adet]] -> 75000 | H17: =Sayfa4!K5 -> 0.89607 | I17: =Sayfa2!$H17*Sayfa2!$G17 -> 67205.25 | J17: =H17-D17 -> -0.168365 | K17: =Sayfa2!$J17*Sayfa2!$C17 -> -12627.375 | L17: =F17-B17 -> 60 | M17: =K17/E17 -> -0.15817312 | N17: =M17/L17*30 -> -0.079086558
A18: TTE Fon | B18: 45344 | C18: 50000 | D18: 1.003205 | E18: =Sayfa2!$D18*Sayfa2!$C18 -> 50160.25 | F18: =$B$2 -> 45408 | G18: =Tablo2[[#This Row],[adet]] -> 50000 | H18: =H17 -> 0.89607 | I18: =Sayfa2!$H18*Sayfa2!$G18 -> 44803.5 | J18: =H18-D18 -> -0.107135 | K18: =Sayfa2!$J18*Sayfa2!$C18 -> -5356.75 | L18: =F18-B18 -> 64 | M18: =K18/E18 -> -0.10679273 | N18: =M18/L18*30 -> -0.050059092 | O18: =SUM(K13:K18) -> -18006.005
A20: XAU | B20: 45219 | C20: 45 | D20: 1826.53 | E20: =Sayfa2!$D20*Sayfa2!$C20 -> 82193.85 | F20: =$B$2 -> 45408 | G20: 50 | H20: =Sayfa4!G10 -> 2384.18 | I20: =Sayfa2!$H20*Sayfa2!$G20 -> 119209 | J20: =H20-D20 -> 557.65 | K20: =Sayfa2!$J20*Sayfa2!$C20 -> 25094.25 | L20: =F20-B20 -> 189 | M20: =K20/E20 -> 0.30530569 | N20: =M20/L20*30 -> 0.04846122 | P20: =Tablo2[[#This Row],[Tutar3]] -> 119209 | Q20: 2000 | R20: =P20/Q20 -> 59.6045
A21: XAU | B21: 44244 | C21: 11 | D21: 402.1 | E21: =Sayfa2!$D21*Sayfa2!$C21 -> 4423.1 | F21: =$B$2 -> 45408 | G21: 11 | H21: =H20 -> 2384.18 | I21: =Sayfa2!$H21*Sayfa2!$G21 -> 26225.98 | J21: =H21-D21 -> 1982.08 | K21: =Sayfa2!$J21*Sayfa2!$C21 -> 21802.88 | L21: =F21-B21 -> 1164 | M21: =K21/E21 -> 4.9293211 | N21: =M21/L21*30 -> 0.12704436 | P21: =Tablo2[[#This Row],[Tutar3]] -> 26225.98 | Q21: 2000 | R21: =P21/Q21 -> 13.11299
A22: XAU | B22: 44084 | C22: 50 | D22: 468.86 | E22: =Sayfa2!$D22*Sayfa2!$C22 -> 23443 | F22: =$B$2 -> 45408 | G22: 50 | H22: =H21 -> 2384.18 | I22: =Sayfa2!$H22*Sayfa2!$G22 -> 119209 | J22: =H22-D22 -> 1915.32 | K22: =Sayfa2!$J22*Sayfa2!$C22 -> 95766 | L22: =F22-B22 -> 1324 | M22: =K22/E22 -> 4.0850574 | N22: =M22/L22*30 -> 0.092561723 | P22: =Tablo2[[#This Row],[Tutar3]] -> 119209 | Q22: 2000 | R22: =P22/Q22 -> 59.6045
A23: XAU | B23: 44020 | C23: 25 | D23: 399.87 | E23: =Sayfa2!$D23*Sayfa2!$C23 -> 9996.75 | F23: =$B$2 -> 45408 | G23: =Tablo2[[#This Row],[adet]] -> 25 | H23: =H22 -> 2384.18 | I23: =Sayfa2!$H23*Sayfa2!$G23 -> 59604.5 | J23: =H23-D23 -> 1984.31 | K23: =Sayfa2!$J23*Sayfa2!$C23 -> 49607.75 | L23: =F23-B23 -> 1388 | M23: =K23/E23 -> 4.9623878 | N23: =M23/L23*30 -> 0.10725622 | R23: =SUM(R20:R22) -> 132.32199
A24: XAU | B24: 43803 | C24: 24 | D24: 273.81 | E24: =Sayfa2!$D24*Sayfa2!$C24 -> 6571.44 | F24: =$B$2 -> 45408 | G24: =Tablo2[[#This Row],[adet]] -> 24 | H24: =H23 -> 2384.18 | I24: =Sayfa2!$H24*Sayfa2!$G24 -> 57220.32 | J24: =H24-D24 -> 2110.37 | K24: =Sayfa2!$J24*Sayfa2!$C24 -> 50648.88 | L24: =F24-B24 -> 1605 | M24: =K24/E24 -> 7.7074249 | N24: =M24/L24*30 -> 0.14406402
A25: XAU | B25: 43803 | C25: 1 | D25: 237.59 | E25: =Sayfa2!$D25*Sayfa2!$C25 -> 237.59 | F25: =$B$2 -> 45408 | G25: =Tablo2[[#This Row],[adet]] -> 1 | H25: =H24 -> 2384.18 | I25: =Sayfa2!$H25*Sayfa2!$G25 -> 2384.18 | J25: =H25-D25 -> 2146.59 | K25: =Sayfa2!$J25*Sayfa2!$C25 -> 2146.59 | L25: =F25-B25 -> 1605 | M25: =K25/E25 -> 9.03485 | N25: =M25/L25*30 -> 0.1688757 | P25: =SUM(P20:P24) -> 264643.98 | R25: =P25/2220.32 -> 119.19182
A26: Euro | B26: 44784 | C26: 298.8 | D26: 18.7216 | E26: =Sayfa2!$D26*Sayfa2!$C26 -> 5594.0141 | F26: =$B$2 -> 45408 | G26: =Tablo2[[#This Row],[adet]] -> 298.8 | H26: =Sayfa4!E5 -> 34.2801 | I26: =Sayfa2!$H26*Sayfa2!$G26 -> 10242.894 | J26: =H26-D26 -> 15.5585 | K26: =Sayfa2!$J26*Sayfa2!$C26 -> 4648.8798 | L26: =F26-B26 -> 624 | M26: =K26/E26 -> 0.83104542 | N26: =M26/L26*30 -> 0.039954107 | P26: =P25*Q26 -> 26464.398 | Q26: 0.1 | T26: 2300
A27: USD | B27: 44774 | C27: 1110 | D27: 15 | E27: =Sayfa2!$D27*Sayfa2!$C27 -> 16650 | F27: =$B$2 -> 45408 | G27: =Tablo2[[#This Row],[adet]] -> 1110 | H27: =Sayfa4!C5 -> 31.948 | I27: =Sayfa2!$H27*Sayfa2!$G27 -> 35462.28 | J27: =H27-D27 -> 16.948 | K27: =Sayfa2!$J27*Sayfa2!$C27 -> 18812.28 | L27: =F27-B27 -> 634 | M27: =K27/E27 -> 1.1298667 | N27: =M27/L27*30 -> 0.053463722 | O27: =SUM(K20:K27) -> 268527.51 | P27: =SUM(P25:P26) -> 291108.38 | R27: =P27/2000 -> 145.55419 | T27: =P25/T26 -> 115.0626
R28: =1-(R27/R25) -> -0.221176
R30: =R27*2220.32 -> 323176.88
A31: Satılan | N31: NET | O31: =SUM(O33:O77) -> 18500.177
A33: Euro satış MOGAN | B33: 44784 | C33: 23.19 | D33: 18.7216 | E33: =Sayfa2!$D33*Sayfa2!$C33 -> 434.1539 | F33: 45350 | G33: 23.19 | H33: 33.2229 | I33: =Sayfa2!$H33*Sayfa2!$G33 -> 770.43905 | J33: =H33-D33 -> 14.5013 | K33: =Sayfa2!$J33*Sayfa2!$C33 -> 336.28515 | L33: =F33-B33 -> 566 | M33: =K33/E33 -> 0.77457589 | N33: =M33/L33*30 -> 0.041055259
A34: Euro satış LMKDC için | B34: 44784 | C34: 18.01 | D34: 18.7216 | E34: =Sayfa2!$D34*Sayfa2!$C34 -> 337.17602 | F34: 45341 | G34: 18.01 | H34: 32.382 | I34: =Sayfa2!$H34*Sayfa2!$G34 -> 583.19982 | J34: =H34-D34 -> 13.6604 | K34: =Sayfa2!$J34*Sayfa2!$C34 -> 246.0238 | L34: =F34-B34 -> 557 | M34: =K34/E34 -> 0.72965986 | N34: =M34/L34*30 -> 0.039299454 | O34: =SUM(K33:K34) -> 582.30895
A36: XAU | B36: 45219 | C36: 5 | D36: 1826.53 | E36: =Sayfa2!$D36*Sayfa2!$C36 -> 9132.65 | F36: 45384 | G36: 5 | H36: 2282.83 | I36: =Sayfa2!$H36*Sayfa2!$G36 -> 11414.15 | J36: =H36-D36 -> 456.3 | K36: =Sayfa2!$J36*Sayfa2!$C36 -> 2281.5 | L36: =F36-B36 -> 165 | M36: =K36/E36 -> 0.24981796 | N36: =M36/L36*30 -> 0.045421447 | O36: =Tablo2[[#This Row],[Tutar2]] -> 2281.5
A38: MOGAN halkaarz | B38: 45350 | C38: 68 | D38: 11.33 | E38: =Sayfa2!$D38*Sayfa2!$C38 -> 770.44 | F38: 45370 | G38: 68 | H38: 19.69 | I38: =Sayfa2!$H38*Sayfa2!$G38 -> 1338.92 | J38: =H38-D38 -> 8.36 | K38: =Sayfa2!$J38*Sayfa2!$C38 -> 568.48 | L38: =F38-B38 -> 20 | M38: =K38/E38 -> 0.73786408 | N38: =M38/L38*30 -> 1.1067961
A39: MOGAN halkaarz | K39: -2.81
A40: OBAMS halkaarz | B40: 45344 | C40: 15 | D40: 39.24 | E40: =Sayfa2!$D40*Sayfa2!$C40 -> 588.6 | F40: 45362 | G40: 15 | H40: 55.6 | I40: =Sayfa2!$H40*Sayfa2!$G40 -> 834 | J40: =H40-D40 -> 16.36 | K40: =Sayfa2!$J40*Sayfa2!$C40 -> 245.4 | L40: =F40-B40 -> 18 | M40: =K40/E40 -> 0.41692151 | N40: =M40/L40*30 -> 0.69486918
A41: OBAMS komisyon | K41: -1.75
A42: ALVES halkaarz | B42: 45344 | C42: 12 | D42: 19.45 | E42: =Sayfa2!$D42*Sayfa2!$C42 -> 233.4 | F42: 45364 | G42: 12 | H42: 45.72 | I42: =Sayfa2!$H42*Sayfa2!$G42 -> 548.64 | J42: =H42-D42 -> 26.27 | K42: =Sayfa2!$J42*Sayfa2!$C42 -> 315.24 | L42: =F42-B42 -> 20 | M42: =K42/E42 -> 1.3506427 | N42: =M42/L42*30 -> 2.025964
A43: ALVES komisyon | K43: -1.16
A44: LMKDC halkaarz | B44: 45341 | C44: 36 | D44: 16.2 | E44: =Sayfa2!$D44*Sayfa2!$C44 -> 583.2 | F44: 45356 | G44: 36 | H44: 38 | I44: =Sayfa2!$H44*Sayfa2!$G44 -> 1368 | J44: =H44-D44 -> 21.8 | K44: =Sayfa2!$J44*Sayfa2!$C44 -> 784.8 | L44: =F44-B44 -> 15 | M44: =K44/E44 -> 1.345679 | N44: =M44/L44*30 -> 2.691358
A45: LMKDC komisyon | K45: -2.88
A46: TABGD ALIŞ | B46: 45222 | C46: 9 | D46: 130 | E46: =Sayfa2!$D46*Sayfa2!$C46 -> 1170 | F46: 45334 | G46: 9 | H46: 145.5 | I46: =Sayfa2!$H46*Sayfa2!$G46 -> 1309.5 | J46: =H46-D46 -> 15.5 | K46: =Sayfa2!$J46*Sayfa2!$G46 -> 139.5 | L46: =F46-B46 -> 112 | M46: =K46/E46 -> 0.11923077 | N46: =K46/E46 -> 0.11923077
A47: TABGD ALIŞ | B47: 45271 | C47: 10 | D47: 144.001 | E47: =Sayfa2!$D47*Sayfa2!$C47 -> 1440.01 | F47: 45334 | G47: 10 | H47: 145.5 | I47: =Sayfa2!$H47*Sayfa2!$G47 -> 1455 | J47: =H47-D47 -> 1.499 | K47: =Sayfa2!$J47*Sayfa2!$G47 -> 14.99 | L47: =F47-B47 -> 63 | M47: =K47/E47 -> 0.01040965 | N47: =K47/E47 -> 0.01040965
A48: TABGD ALIŞ | B48: 45288 | C48: 20 | D48: 115.34 | E48: =Sayfa2!$D48*Sayfa2!$C48 -> 2306.8 | F48: 45334 | G48: 20 | H48: 145.5 | I48: =Sayfa2!$H48*Sayfa2!$G48 -> 2910 | J48: =H48-D48 -> 30.16 | K48: =Sayfa2!$J48*Sayfa2!$G48 -> 603.2 | L48: =F48-B48 -> 46 | M48: =K48/E48 -> 0.26148778 | N48: =K48/E48 -> 0.26148778
A49: GUBRF alış | B49: 45335 | C49: 313 | D49: 190.8 | E49: =Sayfa2!$D49*Sayfa2!$C49 -> 59720.4 | F49: 45337 | G49: 313 | H49: 203.3 | I49: =Sayfa2!$H49*Sayfa2!$G49 -> 63632.9 | J49: =H49-D49 -> 12.5 | K49: =Sayfa2!$J49*Sayfa2!$G49 -> 3912.5 | L49: =F49-B49 -> 2 | M49: =K49/E49 -> 0.065513627 | N49: =M49/L49*30 -> 0.9827044
A50: komisyon | E50: =Sayfa2!$D50*Sayfa2!$C50 -> 0 | I50: =Sayfa2!$H50*Sayfa2!$G50 -> 0 | J50: -133.63 | K50: =Sayfa2!$J50*Sayfa2!$G50 -> 0
...

Sheet Sayfa4
A5: =A10 -> 45408 | C5: =C10 -> 31.948 | E5: =E10 -> 34.2801 | G5: =G10 -> 2384.18 | I5: =I10 -> 25.11 | K5: =K10 -> 0.89607 | M5: =K10 -> 0.89607 | O5: =Sayfa2!D3 -> 167.61476 | P5: =Sayfa2!K2 -> 269021.68 | Y5: =Y10 -> 148.5 | AA5: =AA10 -> 0 | AC5: =AC10 -> 0 | AE5: =AE10 -> 0 | AG5: =AG10 -> 0 | AI5: =AI32 -> 19.69
C6: USD | E6: EUR | G6: GAU | I6: ALTIN.S1 | K6: TTE | M6: TTE | N6: TPL | O6: GNLK | P6: TPLM | Q6: XU100 | S6: Toplam Kar | T6: Gün Sayısı (01-03-2024) | U6: Aylık Ortalama Kar | Y6: RGYAS | AA6: LMKDC | AC6: 801 | AE6: ALVES | AG6: OBAMS | AI6: MOGAN
A10: 45408 | B10: =B44 -> 1110 | C10: 31.948 | D10: =D44 -> 321.99 | E10: 34.2801 | F10: 156 | G10: 2384.18 | H10: 2500 | I10: 25.11 | J10: =J44 -> 50000 | K10: 0.89607 | L10: =L44 -> 75000 | M10: =K10 -> 0.89607 | N10: =(F10*G10)+(B10*C10)+(D10*E10)+(J10*K10)+(L10*M10)+(H10*I10) -> 593215.96 | O10: 167.61 | P10: 269021.68 | Q10: 9720 | R10: =(1-(Q15/Q10)) -> 0.0041358025 | S10: =(N10/$N$38)-1 -> 0.1183367 | T10: =(A10-$A$38) -> 46 | U10: =((N10/$N$38)-1)/T10*30 -> 0.077176109 | X10: 10 | Y10: 148.5
A11: 45407 | B11: =B45 -> 1110 | C11: 32.0291 | D11: =D45 -> 321.99 | E11: 34.3223 | F11: 156 | G11: 2368.47 | J11: =J45 -> 50000 | K11: 0.906097 | L11: =L45 -> 75000 | M11: =K11 -> 0.906097 | N11: =(F11*G11)+(B11*C11)+(D11*E11)+(J11*K11)+(L11*M11) -> 529347.18 | O11: 167.13 | P11: 268083.81 | Q11: 9720 | R11: =(1-(Q16/Q11)) -> -0.0096872428 | S11: =(N11/$N$38)-1 -> -0.0020693588 | T11: =(A11-$A$38) -> 45 | U11: =((N11/$N$38)-1)/T11*30 -> -0.0013795725 | X11: 10 | Y11: 135
A12: 45406 | B12: =B45 -> 1110 | C12: 31.9287 | D12: =D45 -> 321.99 | E12: 33.972 | F12: 156 | G12: 2380.13 | J12: =J45 -> 50000 | K12: 0.88806 | L12: =L45 -> 75000 | M12: 0.91166 | N12: =(F12*G12)+(B12*C12)+(D12*E12)+(J12*K12)+(L12*M12) -> 530457.28 | O12: 166.96 | P12: 267307.03 | Q12: 9722.09 | R12: =(1-(Q16/Q12)) -> -0.0094701859 | S12: =(N12/$N$38)-1 -> 2.3408957e-05 | T12: =(A12-$A$38) -> 44 | U12: =((N12/$N$38)-1)/T12*30 -> 1.5960652e-05 | X12: 10 | Y12: 135
A13: 45404 | B13: =B45 -> 1110 | C13: 31.9287 | D13: =D45 -> 321.99 | E13: 33.972 | F13: 156 | G13: 2380.13 | J13: =J45 -> 50000 | K13: 0.88806 | L13: =L45 -> 75000 | M13: =K13 -> 0.88806 | N13: =(F13*G13)+(B13*C13)+(D13*E13)+(J13*K13)+(L13*M13) -> 528687.28 | O13: 166.96 | P13: 267307.03 | Q13: 9645.02 | R13: =(1-(Q16/Q13)) -> -0.017536511 | S13: =(N13/$N$38)-1 -> -0.0033134129 | T13: =(A13-$A$38) -> 42 | U13: =((N13/$N$38)-1)/T13*30 -> -0.0023667235 | X13: 10 | Y13: 135
A14: 45401 | B14: =B45 -> 1110 | C14: 31.804 | D14: =D45 -> 321.99 | E14: 33.9284 | F14: 156 | G14: 2427.62 | J14: =J45 -> 50000 | K14: 0.873518 | L14: =L45 -> 75000 | M14: =K14 -> 0.873518 | N14: =(F14*G14)+(B14*C14)+(D14*E14)+(J14*K14)+(L14*M14) -> 534125.52 | O14: 170.57 | P14: 272736.27 | Q14: 9693.46 | R14: =(1-(Q16/Q14)) -> -0.012451694 | S14: =(N14/$N$38)-1 -> 0.0069388011 | T14: =(A14-$A$38) -> 39 | U14: =((N14/$N$38)-1)/T14*30 -> 0.0053375393 | X14: ad | Y14: satış
A15: 45397 | B15: =B45 -> 1110 | C15: 31.8634 | D15: =D45 -> 321.99 | E15: 33.9631 | F15: 156 | G15: 2387.51 | J15: =J45 -> 50000 | K15: 0.897914 | L15: =L45 -> 75000 | M15: =K15 -> 0.897914 | N15: =(F15*G15)+(B15*C15)+(D15*E15)+(J15*K15)+(L15*M15) -> 530994.96 | O15: 169.14 | P15: 269604.92 | Q15: 9679.8 | R15: =(1-(Q16/Q15)) -> -0.013880452 | S15: =(N15/$N$38)-1 -> 0.0010370511 | T15: =(A15-$A$38) -> 35 | U15: =((N15/$N$38)-1)/T15*30 -> 0.00088890098 | Y15: alış
A16: 45391 | B16: =B45 -> 1110 | C16: 31.4123 | D16: =D45 -> 321.99 | E16: 34.0918 | F16: 156 | G16: 2352.21 | J16: =J45 -> 50000 | K16: 0.895298 | L16: =L45 -> 75000 | M16: =K16 -> 0.895298 | N16: =(F16*G16)+(B16*C16)+(D16*E16)+(J16*K16)+(L16*M16) -> 524701.88 | O16: 165.81 | P16: 263308.85 | Q16: 9814.16 | R16: =(1-(Q17/Q16)) -> 0.0058558246 | S16: =(N16/$N$38)-1 -> -0.010826728 | T16: =(A16-$A$38) -> 29 | U16: =((N16/$N$38)-1)/T16*30 -> -0.011200064 | X16: TL | Y16: 135
A17: 45390 | B17: =B45 -> 1110 | C17: 31.5198 | D17: =D45 -> 321.99 | E17: 34.1549 | F17: 156 | G17: 2344.37 | J17: =J45 -> 50000 | K17: 0.818581 | L17: =L45 -> 75000 | M17: =K17 -> 0.818581 | N17: =(F17*G17)+(B17*C17)+(D17*E17)+(J17*K17)+(L17*M17) -> 514028.86 | O17: 159.19 | P17: 252634.37 | Q17: 9756.69 | R17: =(1-(Q18/Q17)) -> 0.014129792 | S17: =(N17/$N$38)-1 -> -0.030947618 | T17: =(A17-$A$38) -> 28 | U17: =((N17/$N$38)-1)/T17*30 -> -0.033158162 | Y17: =Sayfa2!K4 -> 0
A18: 45387 | B18: =B45 -> 1110 | C18: 31.407 | D18: =D45 -> 321.99 | E18: 34.0389 | F18: 156 | G18: 2289.27 | J18: =J45 -> 50000 | K18: 0.824246 | L18: =L45 -> 75000 | M18: =K18 -> 0.824246 | N18: =(F18*G18)+(B18*C18)+(D18*E18)+(J18*K18)+(L18*M18) -> 505978.83 | O18: 154.41 | P18: 244587.02 | Q18: 9618.83 | R18: =(1-(Q19/Q18)) -> 0.050921994 | S18: =(N18/$N$38)-1 -> -0.046123623 | T18: =(A18-$A$38) -> 25 | U18: =((N18/$N$38)-1)/T18*30 -> -0.055348347 | X18: Alş | Y18: =Y16*X13 -> 1350
A19: 45386 | B19: =B45 -> 1110 | C19: 31.3998 | D19: =D45 -> 321.99 | E19: 34.0531 | F19: 156 | G19: 2292.57 | J19: =J45 -> 50000 | K19: 0.829139 | L19: =L45 -> 75000 | M19: =K19 -> 0.829139 | N19: =(F19*G19)+(B19*C19)+(D19*E19)+(J19*K19)+(L19*M19) -> 507101.83 | O19: 155.22 | P19: 245709.7 | Q19: 9129.02 | R19: =(1-(Q20/Q19)) -> 0.020070062 | S19: =(N19/$N$38)-1 -> -0.044006522 | T19: =(A19-$A$38) -> 24 | U19: =((N19/$N$38)-1)/T19*30 -> -0.055008152 | X19: + | Y19: =(X10*Y5)-(X10*Y16) -> 135
A20: 45385 | B20: =B45 -> 1110 | C20: 31.3998 | D20: =D45 -> 321.99 | E20: 34.0531 | F20: 156 | G20: 2292.57 | J20: =J45 -> 50000 | K20: 0.829139 | L20: =L45 -> 75000 | M20: =K20 -> 0.829139 | N20: =(F20*G20)+(B20*C20)+(D20*E20)+(J20*K20)+(L20*M20) -> 507101.83 | O20: 155.22 | P20: 245709.7 | Q20: 8945.8 | R20: =(1-(Q21/Q20)) -> -0.010627333 | S20: =(N20/$N$38)-1 -> -0.044006522 | T20: =(A20-$A$38) -> 23 | U20: =((N20/$N$38)-1)/T20*30 -> -0.057399811
A21: 45384 | B21: =B45 -> 1110 | C21: 31.5369 | D21: =D45 -> 321.99 | E21: 33.9588 | F21: 156 | G21: 2287.73 | J21: =J45 -> 50000 | K21: 0.855611 | L21: =L45 -> 75000 | M21: =K21 -> 0.855611 | N21: =(F21*G21)+(B21*C21)+(D21*E21)+(J21*K21)+(L21*M21) -> 509777.61 | O21: 157.11 | P21: 248387.66 | Q21: 9040.87 | R21: =(1-(Q22/Q21)) -> -0.012904732 | S21: =(N21/$N$38)-1 -> -0.038962119 | T21: =(A21-$A$38) -> 22 | U21: =((N21/$N$38)-1)/T21*30 -> -0.053130163
A22: 45383 | B22: =B45 -> 1110 | C22: 31.8793 | D22: =D45 -> 321.99 | E22: 34.3914 | F22: 161 | G22: 2308.43 | J22: =J45 -> 50000 | K22: 0.880976 | L22: =L45 -> 75000 | M22: =K22 -> 0.880976 | N22: =(F22*G22)+(B22*C22)+(D22*E22)+(J22*K22)+(L22*M22) -> 528238.94 | O22: 161.66 | P22: 255424.81 | Q22: 9157.54 | R22: =(1-(Q23/Q22)) -> 0.0016532824 | S22: =(N22/$N$38)-1 -> -0.0041586306 | T22: =(A22-$A$38) -> 21 | U22: =((N22/$N$38)-1)/T22*30 -> -0.0059409008
A23: 45381 | B23: =B45 -> 1110 | C23: 31.8793 | D23: =D45 -> 321.99 | E23: 34.3914 | F23: 161 | G23: 2308.43 | J23: =J45 -> 50000 | K23: 0.880976 | L23: =L45 -> 75000 | M23: =K23 -> 0.880976 | N23: =(F23*G23)+(B23*C23)+(D23*E23)+(J23*K23)+(L23*M23) -> 528238.94 | O23: 161.66 | P23: 255424.81 | Q23: 9142.4 | R23: =(1-(Q24/Q23)) -> 0 | S23: =(N23/$N$38)-1 -> -0.0041586306 | T23: =(A23-$A$38) -> 19 | U23: =((N23/$N$38)-1)/T23*30 -> -0.0065662588
A24: 45380 | B24: =B45 -> 1110 | C24: 31.8308 | D24: =D45 -> 321.99 | E24: 34.3699 | F24: 161 | G24: 2273.32 | J24: =J45 -> 50000 | K24: 0.852431 | L24: =L45 -> 75000 | M24: =K24 -> 0.852431 | N24: =(F24*G24)+(B24*C24)+(D24*E24)+(J24*K24)+(L24*M24) -> 518957.35 | O24: 156.08 | P24: 246143.72 | Q24: 9142.4 | R24: =(1-(Q25/Q24)) -> 0.0068286227 | S24: =(N24/$N$38)-1 -> -0.021656383 | T24: =(A24-$A$38) -> 18 | U24: =((N24/$N$38)-1)/T24*30 -> -0.036093971
A25: 45379 | B25: =B45 -> 1110 | C25: 31.8707 | D25: =D45 -> 321.99 | E25: 34.4808 | F25: 161 | G25: 2240.09 | J25: =J45 -> 50000 | K25: 0.864732 | L25: =L45 -> 75000 | M25: =K25 -> 0.864732 | N25: =(F25*G25)+(B25*C25)+(D25*E25)+(J25*K25)+(L25*M25) -> 515224.94 | O25: 153.81 | P25: 242408.74 | Q25: 9079.97 | R25: =(1-(Q26/Q25)) -> 0.030093712 | S25: =(N25/$N$38)-1 -> -0.028692755 | T25: =(A25-$A$38) -> 17 | U25: =((N25/$N$38)-1)/T25*30 -> -0.050634273
A26: 45378 | B26: =B45 -> 1110 | C26: 31.822 | D26: =D45 -> 321.99 | E26: 34.5045 | F26: 161 | G26: 2227.25 | J26: =J45 -> 50000 | K26: 0.859 | L26: =L45 -> 75000 | M26: =K26 -> 0.859 | N26: =(F26*G26)+(B26*C26)+(D26*E26)+(J26*K26)+(L26*M26) -> 512394.77 | O26: 154.24 | P26: 242616.68 | Q26: 8806.72 | R26: =(1-(Q27/Q26)) -> -7.4942771e-05 | S26: =(N26/$N$38)-1 -> -0.034028212 | T26: =(A26-$A$38) -> 16 | U26: =((N26/$N$38)-1)/T26*30 -> -0.063802897
A27: 45377 | B27: =B46 -> 1110 | C27: 31.531 | D27: =D46 -> 321.99 | E27: 34.1259 | F27: 161 | G27: 2227.25 | J27: =J46 -> 50000 | K27: 0.890316 | L27: =L46 -> 75000 | M27: =K27 -> 0.890316 | N27: =(F27*G27)+(B27*C27)+(D27*E27)+(J27*K27)+(L27*M27) -> 515864.36 | O27: 154.24 | P27: 242616.68 | Q27: 8807.38 | R27: =(1-(Q28/Q27)) -> -0.025206134 | S27: =(N27/$N$38)-1 -> -0.027487316 | T27: =(A27-$A$38) -> 15 | U27: =((N27/$N$38)-1)/T27*30 -> -0.054974632
A28: 45376 | B28: =B45 -> 1110 | C28: 31.7862 | D28: =D45 -> 321.99 | E28: 34.3863 | F28: 161 | G28: 2214.31 | J28: =J45 -> 50000 | K28: 0.918891 | L28: =L45 -> 75000 | M28: =K28 -> 0.918891 | N28: =(F28*G28)+(B28*C28)+(D28*E28)+(J28*K28)+(L28*M28) -> 517720.01 | O28: 155.99 | P28: 244906 | Q28: 9029.38 | R28: =(1-(Q29/Q28)) -> -0.0090947551 | S28: =(N28/$N$38)-1 -> -0.02398902 | T28: =(A28-$A$38) -> 14 | U28: =((N28/$N$38)-1)/T28*30 -> -0.051405043
A29: 45373 | B29: =B45 -> 1110 | C29: 31.7107 | D29: =D45 -> 321.99 | E29: 34.3363 | F29: 161 | G29: 2212.11 | J29: =J45 -> 50000 | K29: 0.930621 | L29: =L45 -> 75000 | M29: =K29 -> 0.930621 | N29: =(F29*G29)+(B29*C29)+(D29*E29)+(J29*K29)+(L29*M29) -> 518732.16 | O29: 156.64 | P29: 245919.31 | Q29: 9111.5 | R29: =(1-(Q30/Q29)) -> -0.0032047413 | S29: =(N29/$N$38)-1 -> -0.022080913 | T29: =(A29-$A$38) -> 11 | U29: =((N29/$N$38)-1)/T29*30 -> -0.060220672
A30: 45372 | B30: =B45 -> 1110 | C30: 32.0639 | D30: =D45 -> 321.99 | E30: 35.0651 | F30: 161 | G30: 2267.61 | J30: =J45 -> 50000 | K30: 0.941665 | L30: =L45 -> 75000 | M30: =K30 -> 0.941665 | N30: =(F30*G30)+(B30*C30)+(D30*E30)+(J30*K30)+(L30*M30) -> 529674.88 | O30: 163.91 | P30: 256845.12 | Q30: 9140.7 | R30: =(1-(Q31/Q30)) -> 0.020302603 | S30: =(N30/$N$38)-1 -> -0.0014515902 | T30: =(A30-$A$38) -> 10 | U30: =((N30/$N$38)-1)/T30*30 -> -0.0043547706
A31: 45371 | B31: =B45 -> 1110 | C31: 32.0288 | D31: =D45 -> 321.99 | E31: 34.8088 | F31: 161 | G31: 2220.92 | J31: =J45 -> 50000 | K31: 0.934706 | L31: =L45 -> 75000 | M31: =K31 -> 0.934706 | N31: =(F31*G31)+(B31*C31)+(D31*E31)+(J31*K31)+(L31*M31) -> 521166.42 | O31: 158.48 | P31: 248342.62 | Q31: 8955.12 | R31: =(1-(Q32/Q31)) -> 0.0028184994 | S31: =(N31/$N$38)-1 -> -0.01749181 | T31: =(A31-$A$38) -> 9 | U31: =((N31/$N$38)-1)/T31*30 -> -0.058306032
A32: 45370 | B32: =B45 -> 1110 | C32: 32.0878 | D32: =D45 -> 321.99 | E32: 34.7991 | F32: 161 | G32: 2219.02 | J32: =J45 -> 50000 | K32: 0.900336 | L32: =L45 -> 75000 | M32: =K32 -> 0.900336 | N32: =(F32*G32)+(B32*C32)+(D32*E32)+(J32*K32)+(L32*M32) -> 516626.64 | O32: 155.59 | P32: 243803.06 | Q32: 8929.88 | R32: =(1-(Q33/Q32)) -> 0.023714764 | S32: =(N32/$N$38)-1 -> -0.026050255 | T32: =(A32-$A$38) -> 8 | U32: =((N32/$N$38)-1)/T32*30 -> -0.097688456 | AH32: 68 | AI32: 19.69
A33: 45369 | B33: =B45 -> 1110 | C33: 31.9499 | D33: =D45 -> 321.99 | E33: 34.8125 | F33: 161 | G33: 2212.35 | J33: =J45 -> 50000 | K33: 0.938879 | L33: =L45 -> 75000 | M33: 0.938879 | N33: =(F33*G33)+(B33*C33)+(D33*E33)+(J33*K33)+(L33*M33) -> 520221.89 | O33: 155.44 | P33: 247623.17 | Q33: 8718.11 | R33: =(1-(Q34/Q33)) -> -0.012685089 | S33: =(N33/$N$38)-1 -> -0.019272452 | T33: =(A33-$A$38) -> 7 | U33: =((N33/$N$38)-1)/T33*30 -> -0.082596223 | AH33: 68 | AI33: 22.96
A34: 45366 | B34: =B45 -> 1110 | C34: 31.7963 | D34: =D45 -> 321.99 | E34: 34.6197 | F34: 161 | G34: 2213.54 | J34: =J45 -> 50000 | K34: 0.948386 | L34: =L45 -> 75000 | M34: 0.948386 | N34: =(F34*G34)+(B34*C34)+(D34*E34)+(J34*K34)+(L34*M34) -> 521369.28 | O34: 156.13 | P34: 248712.47 | Q34: 8828.7 | R34: =(1-(Q35/Q34)) -> -0.0062092947 | S34: =(N34/$N$38)-1 -> -0.017109382 | T34: =(A34-$A$38) -> 4 | U34: =((N34/$N$38)-1)/T34*30 -> -0.12832037 | AH34: 68 | AI34: 22.04
A35: 45365 | B35: =B45 -> 1110 | C35: 31.7757 | D35: =D45 -> 321.99 | E35: 34.7625 | F35: 161 | G35: 2222.88 | J35: =J45 -> 50000 | K35: 0.951007 | L35: =L45 -> 75000 | M35: 0.951007 | N35: =(F35*G35)+(B35*C35)+(D35*E35)+(J35*K35)+(L35*M35) -> 523223.76 | O35: 157.21 | P35: 250427.64 | Q35: 8883.52 | R35: =(1-(Q36/Q35)) -> -0.003006691 | S35: =(N35/$N$38)-1 -> -0.013613299 | T35: =(A35-$A$38) -> 3 | U35: =((N35/$N$38)-1)/T35*30 -> -0.13613299 | AH35: 68 | AI35: 20.4
A36: 45364 | B36: =B45 -> 1110 | C36: 32 | D36: =D45 -> 321.99 | E36: 35 | F36: 161 | G36: 2220.32 | J36: =J45 -> 50000 | K36: 0.957233 | L36: =L45 -> 75000 | M36: 0.957233 | N36: =(F36*G36)+(B36*C36)+(D36*E36)+(J36*K36)+(L36*M36) -> 523915.3 | O36: 160.79 | P36: 250989.9 | Q36: 8910.23 | R36: =(1-(Q37/Q36)) -> -0.017822211 | S36: =(N36/$N$38)-1 -> -0.012309609 | T36: =(A36-$A$38) -> 2 | U36: =((N36/$N$38)-1)/T36*30 -> -0.18464414 | AH36: 68 | AI36: 18.22
A37: 45363 | B37: =B45 -> 1110 | C37: 31.5164 | D37: =D45 -> 321.99 | E37: 34.4632 | F37: 161 | G37: 2220.32 | J37: =J45 -> 50000 | K37: 0.979213 | L37: =L45 -> 75000 | M37: 0.979213 | N37: =(F37*G37)+(B37*C37)+(D37*E37)+(J37*K37)+(L37*M37) -> 525953.15 | O37: 161.95 | P37: 252645.61 | Q37: 9069.03 | R37: =(1-(Q38/Q37)) -> -0.0068684303 | S37: =(N37/$N$38)-1 -> -0.0084678157 | T37: =(A37-$A$38) -> 1 | U37: =((N37/$N$38)-1)/T37*30 -> -0.25403447 | AH37: 68 | AI37: 16.57
A38: 45362 | B38: =B45 -> 1110 | C38: 31.5714 | D38: =D45 -> 321.99 | E38: 34.5581 | F38: 161 | G38: 2232.66 | J38: =J45 -> 50000 | K38: 0.9985199 | L38: =L45 -> 75000 | M38: 0.9985199 | N38: =(F38*G38)+(B38*C38)+(D38*E38)+(J38*K38)+(L38*M38) -> 530444.86 | O38: 164.91 | P38: 257088.48 | Q38: 9131.32 | R38: =(1-(Q39/Q38)) -> -0.0026283166 | S38: =(N38/$N$38)-1 -> 0 | T38: =(A38-$A$38) -> 0 | AD38: 12 | AE38: 41.58 | AF38: =AF45 -> 15 | AG38: 55.55 | AH38: 68 | AI38: 15.07
A39: 45359 | B39: =B45 -> 1110 | C39: 31.403 | D39: =D45 -> 321.99 | E39: 34.3643 | F39: 161 | G39: 2198.16 | J39: =J45 -> 50000 | K39: 0.991159 | L39: =L45 -> 75000 | M39: 0.991159 | N39: =(F39*G39)+(B39*C39)+(D39*E39)+(J39*K39)+(L39*M39) -> 523720.93 | O39: 160.9 | Q39: 9155.32 | R39: =(1-(Q40/Q39)) -> 0.011047129 | AD39: 12 | AE39: 37.8 | AF39: =AF45 -> 15 | AG39: 57.75 | AH39: 68 | AI39: 13.7
A40: 45358 | B40: =B45 -> 1110 | C40: 31.297 | D40: =D45 -> 321.99 | E40: 34.1106 | F40: 161 | G40: 2184.79 | J40: =J45 -> 50000 | K40: 0.945214 | L40: =L45 -> 75000 | M40: 0.945214 | N40: =(F40*G40)+(B40*C40)+(D40*E40)+(J40*K40)+(L40*M40) -> 515625.88 | O40: 155.75 | Q40: 9054.18 | R40: =(1-(Q41/Q40)) -> 0.034194151 | AD40: 12 | AE40: 34.38 | AF40: =AF45 -> 15 | AG40: 63.1 | AH40: 68 | AI40: 12.46
A41: 45357 | B41: =B45 -> 1110 | C41: 31.2934 | D41: =D45 -> 321.99 | E41: 34.0065 | F41: 161 | G41: 2150.9 | J41: =J45 -> 50000 | K41: 0.993971 | L41: =L45 -> 75000 | M41: 0.993971 | N41: =(F41*G41)+(B41*C41)+(D41*E41)+(J41*K41)+(L41*M41) -> 516226.7 | O41: 156.16 | Q41: 8744.58 | R41: =(1-(Q42/Q41)) -> -0.013258498 | AB41: =AB45 -> 57 | AC41: 580.05925 | AD41: 12 | AE41: 31.26 | AF41: =AF45 -> 15 | AG41: 57.4 | AH41: 68 | AI41: 11.33
A42: 45356 | B42: =B45 -> 1110 | C42: 31.0799 | D42: =D45 -> 321.99 | E42: 33.7217 | F42: 161 | G42: 2116.34 | J42: =J45 -> 50000 | K42: 1.016031 | L42: =L45 -> 75000 | M42: 1.016031 | N42: =(F42*G42)+(B42*C42)+(D42*E42)+(J42*K42)+(L42*M42) -> 513091.35 | O42: 154.23 | Q42: 8860.52 | R42: =(1-(Q43/Q42)) -> -0.0053191009 | Z42: =Z45 -> 36 | AA42: 38.15 | AB42: =AB45 -> 57 | AC42: 579.36172 | AD42: =AD45 -> 12 | AE42: 28.42 | AF42: =AF45 -> 15 | AG42: 52.2 | AH42: 68 | AI42: 11.33
A43: 45355 | B43: =B45 -> 1110 | C43: 30.906 | D43: =D45 -> 321.99 | E43: 33.5423 | F43: 161 | G43: 2072.52 | J43: =J45 -> 50000 | K43: 1.041954 | L43: =L45 -> 75000 | M43: 1.041954 | N43: =(F43*G43)+(B43*C43)+(D43*E43)+(J43*K43)+(L43*M43) -> 509025.92 | Q43: 8907.65 | R43: =(1-(Q44/Q43)) -> -0.021273849 | Z43: =Z45 -> 36 | AA43: 34.66 | AB43: =AB45 -> 57 | AC43: 578.6606 | AD43: =AD45 -> 12 | AE43: 25.84 | AF43: =AF45 -> 15 | AG43: 47.46 | AH43: 68 | AI43: 11.33
A44: 45352 | B44: =B45 -> 1110 | C44: 30.7361 | D44: =D45 -> 321.99 | E44: 33.2257 | F44: 161 | G44: 2018.91 | J44: =J45 -> 50000 | K44: 1.034036 | L44: =L45 -> 75000 | M44: 1.034036 | N44: =(F44*G44)+(B44*C44)+(D44*E44)+(J44*K44)+(L44*M44) -> 499114.42 | Q44: 9097.15 | R44: =(1-(Q45/Q44)) -> -0.010612115 | Z44: =Z45 -> 36 | AA44: 31.52 | AB44: =AB45 -> 57 | AC44: 576.58807 | AD44: =AD45 -> 12 | AE44: 23.5 | AF44: =AF45 -> 15 | AG44: 43.16 | AH44: 68 | AI44: 11.33
A45: 45351 | B45: =B46 -> 1110 | C45: 30.7361 | D45: =D46 -> 321.99 | E45: 33.2257 | F45: 161 | G45: 2018.91 | J45: =J46 -> 50000 | K45: 1.010337 | L45: =L46 -> 75000 | M45: 1.010337 | N45: =(F45*G45)+(B45*C45)+(D45*E45)+(J45*K45)+(L45*M45) -> 496152.05 | Q45: 9193.69 | R45: =(1-(Q46/Q45)) -> 0.014284798 | Z45: =Z46 -> 36 | AA45: 28.66 | AB45: =AB46 -> 57 | AC45: 576.58807 | AD45: =AD46 -> 12 | AE45: 21.38 | AF45: 15 | AG45: 39.24 | AI45: =AI44 -> 11.33
A46: 45350 | B46: 1110 | C46: 30.7361 | D46: 321.99 | E46: 33.2257 | F46: 161 | G46: 2018.91 | J46: =J47 -> 50000 | K46: 1.067704 | L46: =L47 -> 75000 | M46: 1.067704 | N46: =(F46*G46)+(B46*C46)+(D46*E46)+(J46*K46)+(L46*M46) -> 503322.92 | Q46: 9062.36 | R46: =(1-(Q47/Q46)) -> -0.012923786 | Z46: =Z47 -> 36 | AA46: 26.06 | AB46: 57 | AC46: 576.58807 | AD46: 12 | AE46: 19.45 | AG46: =AG45 -> 39.24 | AI46: alış
A47: 45349 | B47: 1110 | C47: 30.7361 | D47: 321.99 | E47: 33.2257 | F47: 161 | G47: 2018.91 | J47: =J48 -> 50000 | K47: 1.064435 | L47: 75000 | M47: 1.064435 | N47: =(F47*G47)+(B47*C47)+(D47*E47)+(J47*K47)+(L47*M47) -> 502914.3 | Q47: 9179.48 | R47: =(1-(Q48/Q47)) -> -0.01684736 | Z47: 36 | AA47: 23.7 | AB47: 57 | AC47: 576.58807 | AE47: =AE46 -> 19.45 | AG47: alış | AI47: satış
...

Sheet Yasemin
B2: YASEMİN
E4: Toplam Yatırım | I4: Satış | K4: NET TL
B5: 45402 | K5: =SUM(K8:K9) -> 160.835
B6: 45273
B7: =B5-B6 -> 129 | D7: Toplam | E7: =SUM(E8:E9) -> 6767.52 | I7: =SUM(I8:I9) -> 6931.165 | J7: =I7-E7 -> 163.645 | K7: =SUM(K8:K9) -> 160.835 | L7: =K7/E7 -> 0.023765722
B8: =K5/B7 -> 1.2467829 | D8: Mevcut | E8: =SUBTOTAL(109,E13:E20) -> 5997.08 | I8: =SUBTOTAL(109,I13:I20) -> 5592.245 | J8: =I8-E8 -> -404.835 | K8: =SUBTOTAL(109,K13:K20) -> -404.835 | L8: =K8/E8 -> -0.067505353 | M8: =SUBTOTAL(101,M13:M19) -> -0.054714848 | N8: =SUBTOTAL(101,N13:N19) -> -0.019956903
D9: Satılan | E9: =SUBTOTAL(109,E23:E32) -> 770.44 | I9: =SUBTOTAL(109,I23:I32) -> 1338.92 | J9: =I9-E9 -> 568.48 | K9: =SUBTOTAL(109,K23:K31) -> 565.67 | L9: =K9/E9 -> 0.73421681 | N9: =L9/(B7/30) -> 0.1707481
B11: ALIŞ | C11: ALIŞ | D11: ALIŞ | E11: ALIŞ | F11: SATIŞ | G11: SATIŞ | H11: SATIŞ | I11: SATIŞ | J11: FARK | K11: FARK | L11: GÜN | M11: GÜN | N11: AY
A12: Açıklama | B12: tarih | C12: adet | D12: birim fiyat | E12: Tutar | F12: Tarih2 | G12: Miktar | H12: Fiyat | I12: Tutar3 | J12: Miktar3 | K12: Tutar2 | L12: Mktr | M12: % | N12: %
A14: Mevcut | N14: Mevcut | O14: =SUM(O15:O18) -> -404.835
A16: AVPGY Halka Arz | B16: 45273 | C16: 26 | D16: 55.08 | E16: =Tablo23[[#This Row],[adet]]*Tablo23[[#This Row],[birim fiyat]] -> 1432.08 | F16: =B5 -> 45402 | G16: 26 | H16: 46 | I16: =Tablo23[[#This Row],[Fiyat]]*Tablo23[[#This Row],[Miktar]] -> 1196 | J16: =H16-D16 -> -9.08 | K16: =Tablo23[[#This Row],[Miktar3]]*Tablo23[[#This Row],[adet]] -> -236.08 | L16: =F16-B16 -> 129 | M16: =K16/E16 -> -0.16485113 | N16: =M16/L16*30 -> -0.038337471
A17: TABGD | B17: 45273 | C17: 9 | D17: 130 | E17: =Tablo23[[#This Row],[adet]]*Tablo23[[#This Row],[birim fiyat]] -> 1170 | F17: =$B$5 -> 45402 | G17: 9 | H17: 140 | I17: =Tablo23[[#This Row],[Fiyat]]*Tablo23[[#This Row],[Miktar]] -> 1260 | J17: =H17-D17 -> 10 | K17: =Tablo23[[#This Row],[Miktar3]]*Tablo23[[#This Row],[adet]] -> 90 | L17: =F17-B17 -> 129 | M17: =K17/E17 -> 0.076923077 | N17: =M17/L17*30 -> 0.017889088
A18: TTE Fon | B18: 45344 | C18: 3500 | D18: 0.97 | E18: =Tablo23[[#This Row],[adet]]*Tablo23[[#This Row],[birim fiyat]] -> 3395 | F18: =B5 -> 45402 | G18: 3500 | H18: =Sayfa4!M10 -> 0.89607 | I18: =Tablo23[[#This Row],[Fiyat]]*Tablo23[[#This Row],[Miktar]] -> 3136.245 | J18: =H18-D18 -> -0.07393 | K18: =Tablo23[[#This Row],[Miktar3]]*Tablo23[[#This Row],[adet]] -> -258.755 | L18: =F18-B18 -> 58 | M18: =K18/E18 -> -0.076216495 | N18: =M18/L18*30 -> -0.039422325 | O18: =SUM(K15:K18) -> -404.835
M21: Satılan | N21: NET | O21: =SUM(O22:O32) -> 565.67
A23: Satılan
A27: MOGAN halkaarz | B27: 45350 | C27: 68 | D27: 11.33 | E27: =Tablo23[[#This Row],[adet]]*Tablo23[[#This Row],[birim fiyat]] -> 770.44 | F27: 45370 | G27: 68 | H27: 19.69 | I27: =Tablo23[[#This Row],[Fiyat]]*Tablo23[[#This Row],[Miktar]] -> 1338.92 | J27: =H27-D27 -> 8.36 | K27: =Tablo23[[#This Row],[Miktar3]]*Tablo23[[#This Row],[adet]] -> 568.48 | L27: =F27-B27 -> 20 | M27: =K27/E27 -> 0.73786408 | N27: =M27/L27*30 -> 1.1067961
A28: MOGAN komisyon | K28: -2.81
O29: =SUM(K24:K29) -> 565.67

Sheet 801
A1: Tarih | B1: Fiyat | C1: Değişim | D1: Değişim Oranı (%) | E1: Küm.Oran (%)
A2: 45289 | B2: 538.78971 | C2: 0.000000 | D2: 0 | E2: 0.00
A3: 45294 | B3: 539.40629 | C3: 0.616584 | D3: 0.0011 | E3: =D2+D3 -> 0.0011
A4: 45295 | B4: 540.00004 | C4: 0.593753 | D4: 0.0011 | E4: =D3+D4 -> 0.0022
A5: 45296 | B5: 540.60111 | C5: 0.601064 | D5: 0.0011 | E5: =E4+D5 -> 0.0033
A6: 45299 | B6: 542.4345 | C6: 1833394 | D6: 0.0033 | E6: =E5+D6 -> 0.0066
A7: 45300 | B7: 543.04311 | C7: 0.608605 | D7: 0.0011 | E7: =E6+D7 -> 0.0077
A8: 45301 | B8: 543.64739 | C8: 0.604285 | D8: 0.0011 | E8: =E7+D8 -> 0.0088
A9: 45302 | B9: 544.25189 | C9: 0.604500 | D9: 0.0011 | E9: =E8+D9 -> 0.0099
A10: 45303 | B10: 544.85274 | C10: 0.600845 | D10: 0.0011 | E10: =E9+D10 -> 0.011
A11: 45306 | B11: 546.6564 | C11: 1803661 | D11: 0.0033 | E11: =E10+D11 -> 0.0143
A12: 45307 | B12: 547.2559 | C12: 0.599500 | D12: 0.001 | E12: =E11+D12 -> 0.0153
A13: 45308 | B13: 547.85337 | C13: 0.597470 | D13: 0.001 | E13: =E12+D13 -> 0.0163
A14: 45309 | B14: 548.45884 | C14: 0.605467 | D14: 0.0011 | E14: =E13+D14 -> 0.0174
A15: 45310 | B15: 549.06772 | C15: 0.608884 | D15: 0.0011 | E15: =E14+D15 -> 0.0185
A16: 45313 | B16: 550.93395 | C16: 1866230 | D16: 0.0033 | E16: =E15+D16 -> 0.0218
A17: 45314 | B17: 551.56365 | C17: 0.629702 | D17: 0.0011 | E17: =E16+D17 -> 0.0229
A18: 45315 | B18: 552.18915 | C18: 0.625502 | D18: 0.0011 | E18: =E17+D18 -> 0.024
A19: 45316 | B19: 552.81493 | C19: 0.625781 | D19: 0.0011 | E19: =E18+D19 -> 0.0251
A20: 45317 | B20: 553.42975 | C20: 0.614817 | D20: 0.0011 | E20: =E19+D20 -> 0.0262
A21: 45320 | B21: 555.31532 | C21: 1885570 | D21: 0.0034 | E21: =E20+D21 -> 0.0296
A22: 45321 | B22: 555.95011 | C22: 0.634786 | D22: 0.0011 | E22: =E21+D22 -> 0.0307
A23: 45322 | B23: 556.58168 | C23: 0.631570 | D23: 0.0011 | E23: =E22+D23 -> 0.0318
A24: 45323 | B24: 557.21083 | C24: 0.629156 | D24: 0.0011 | E24: =E23+D24 -> 0.0329
A25: 45324 | B25: 557.85254 | C25: 0.641710 | D25: 0.0011 | E25: =E24+D25 -> 0.034
A26: 45327 | B26: 559.83386 | C26: 1981314 | D26: 0.0035 | E26: =E25+D26 -> 0.0375
A27: 45328 | B27: 560.49905 | C27: 0.665196 | D27: 0.0011 | E27: =E26+D27 -> 0.0386
A28: 45329 | B28: 561.15721 | C28: 0.658159 | D28: 0.0011 | E28: =E27+D28 -> 0.0397
A29: 45330 | B29: 561.81588 | C29: 0.658668 | D29: 0.0011 | E29: =E28+D29 -> 0.0408
A30: 45331 | B30: 562.47431 | C30: 0.658434 | D30: 0.0011 | E30: =E29+D30 -> 0.0419
A31: 45334 | B31: 564.4501 | C31: 1975784 | D31: 0.0035 | E31: =E30+D31 -> 0.0454
A32: 45335 | B32: 565.11283 | C32: 0.662731 | D32: 0.0011 | E32: =E31+D32 -> 0.0465
A33: 45336 | B33: 565.75863 | C33: 0.645802 | D33: 0.0011 | E33: =E32+D33 -> 0.0476
A34: 45337 | B34: 566.41625 | C34: 0.657615 | D34: 0.0011 | E34: =E33+D34 -> 0.0487
A35: 45338 | B35: 567.08235 | C35: 0.666105 | D35: 0.0011 | E35: =E34+D35 -> 0.0498
A36: 45341 | B36: 569.09258 | C36: 2010233 | D36: 0.0035 | E36: =E35+D36 -> 0.0533
A37: 45342 | B37: 569.76265 | C37: 0.670066 | D37: 0.0011 | E37: =E36+D37 -> 0.0544
A38: 45343 | B38: 570.43001 | C38: 0.667361 | D38: 0.0011 | E38: =E37+D38 -> 0.0555
A39: 45344 | B39: 571.10523 | C39: 0.675217 | D39: 0.0011 | E39: =E38+D39 -> 0.0566
A40: 45345 | B40: 571.78679 | C40: 0.681558 | D40: 0.0011 | E40: =E39+D40 -> 0.0577
...

Sheet Sayfa3
A3: İŞLEM | B3: KYMT | C3: FAİZ ORANI | D3: KIYMET | F3: TL | H3: TL TUTAR | J3: TL-KIYMET / | K3: AÇIKLAMA | L3: ŞUBE | M3: FİŞ NO | N3: İŞL
A4: TARİHİ | B4: ADI | C4: BİRİM FİAT | D4: ADEDİ | F4: MALİYET | G4: MASRAF | J4: BAKİYE | N4: KOD
A5: ======== | B5: ====== | C5: =========== | D5: ======== | H5: ========== | J5: ========= | K5: ====================== | L5: ==== | M5: ======== | N5: ==
A6: 45217 | C6: - | D6: - | H6: 3000.68 | I6: =H6 -> 3000.68 | J6: 3000.68 | K6: CARİ/YATIRIM VİRMANI | L6: 5800 | M6: 95113516 | N6: QC
A7: 45217 | B7: TABGD | C7: - | D7: - | H7: -2080 | I7: =I6+H7 -> 920.68 | J7: 920.68 | K7: HALKA ARZ TALEP GİRİŞİ | L7: 5800 | M7: 36114333 | N7: HF
A8: 45222 | B8: TABGD | C8: - | D8: - | H8: 910 | I8: =I7+H8 -> 1830.68 | J8: 1830.68 | K8: HALKA ARZ +0.000 ALIM TALEP SONUCU | L8: 165 | M8: 88888888 | N8: HX
A9: 45222 | B9: TABGD | C9: 130 | D9: 9 | F9: =D9*C9 -> 1170 | H9: 0 | J9: 1830.68 | K9: HALKA ARZ SENET 9 | L9: 165 | M9: 88888888 | N9: HX
A10: 45226 | B10: TABGD | C10: 157.3 | D10: 1 | H10: -157.63 | I10: 0 | J10: 1830.68 | K10: 30000025400 NOLU ALIŞ TALİMATI | L10: 165 | M10: 95215533 | N10: QX
A11: 45226 | B11: TABGD | C11: 157.3 | D11: 2 | H11: -315.26 | I11: 0 | J11: 1830.68 | K11: 30000025506 NOLU ALIŞ TALİMATI | L11: 165 | M11: 95215846 | N11: QX
A12: 45229 | B12: TABGD | C12: 173 | D12: 5 | H12: -866.82 | I12: 0 | J12: 1830.68 | K12: 30000281703 NOLU ALIŞ TALİMATI | L12: 165 | M12: 95103707 | N12: QX
A13: 45229 | B13: TABGD | C13: 173 | D13: 5 | H13: 157.63 | I13: 0 | J13: 1830.68 | K13: 030000281703 NOLU TALİMAT İPTALİ | L13: 165 | M13: 18200988 | N13: QT
A14: 45229 | B14: TABGD | C14: 157.3 | D14: 2 | H14: 315.26 | I14: 0 | J14: 1830.68 | K14: 030000025506 NOLU TALİMAT İPTALİ | L14: 165 | M14: 18201019 | N14: QT
A15: 45229 | B15: TABGD | C15: 157.3 | D15: 1 | H15: 866.82 | I15: 0 | J15: 1830.68 | K15: 030000025400 NOLU TALİMAT İPTALİ | L15: 165 | M15: 18201200 | N15: QT
A16: 45267 | B16: MEGMT | C16: - | D16: - | H16: -566 | I16: =I8+H16 -> 1264.68 | J16: 1264.68 | K16: HALKA ARZ TALEP GİRİŞİ | L16: 5800 | M16: 36093318 | N16: HF
A17: 45267 | B17: SURGY | C17: - | D17: - | H17: -983.6 | I17: =I16+H17 -> 281.08 | J17: 281.08 | K17: HALKA ARZ TALEP GİRİŞİ | L17: 5800 | M17: 36093353 | N17: HF
A18: 45267 | C18: - | D18: - | H18: 5181.13 | I18: =I17+H18 -> 5462.21 | J18: 5462.21 | K18: CARİ/YATIRIM VİRMANI | L18: 5800 | M18: 36094012 | N18: QC
A19: 45267 | B19: 808 | C19: 18.207358 | D19: 300 | F19: =D19*C19 -> 5462.2074 | H19: -5462.21 | I19: =I18+H19 -> 0 | J19: 0 | K19: YATIRIM FONU ALIŞI 300 | L19: 5800 | M19: 36094012 | N19: 72
A20: 45267 | C20: - | D20: - | H20: 5238.9 | I20: =I19+H20 -> 5238.9 | J20: 5238.9 | K20: CARİ/YATIRIM VİRMANI | L20: 5800 | M20: 36094051 | N20: QC
A21: 45267 | B21: 801 | C21: 523.88987 | D21: 10 | F21: =D21*C21 -> 5238.8987 | H21: -5238.9 | I21: =I20+H21 -> 0 | J21: 0 | K21: YATIRIM FONU ALIŞI 10 | L21: 5800 | M21: 36094051 | N21: 72
A22: 45267 | C22: - | D22: - | H22: 1576.31 | I22: =I21+H22 -> 1576.31 | J22: 1576.31 | K22: CARİ/YATIRIM VİRMANI | L22: 5800 | M22: 10001 | N22: QC
A23: 45267 | B23: TABGD | C23: 157.3 | D23: 10 | H23: -1576.31 | J23: 1576.31 | K23: 207000086784 NOLU ALIŞ TALİMATI | L23: 165 | M23: 36094616 | N23: QX
A24: 45267 | B24: TABGD | C24: -157.53 | D24: 10 | H24: -1575.3 | J24: 1576.31 | K24: 207000086784 NOLU TLM.EMİR İYİLEŞT | L24: 165 | M24: 36094724 | N24: QU
A25: 45271 | B25: TABGD | C25: -143.7 | D25: 10 | F25: -1440.01 | G25: 3.01 | H25: -1440.01 | I25: =I22+H25 -> 136.3 | J25: 136.3 | K25: TAKAS KOM: 2.87 - 19 - ALIŞ BSMV: 0.14 | L25: 165 | M25: 0 | N25: QA
A26: 45271 | B26: SURGY | C26: - | H26: 491.8 | I26: =I25+H26 -> 628.1 | J26: 628.1 | K26: HALKA ARZ ALIM TALEP SONUCU | L26: 165 | M26: 88888888 | N26: HX
A27: 45271 | B27: SURGY | C27: 49.18 | D27: 10 | F27: =D27*C27 -> 491.8 | H27: 0 | J27: 628.1 | K27: HALKA ARZ SENET 10 GİRİŞİ,SIRANO: | L27: 165 | M27: 88888888 | N27: HX
A28: 45271 | B28: MEGMT | C28: - | D28: - | H28: 198.1 | I28: =I26+H28 -> 826.2 | J28: 826.2 | K28: HALKA ARZ ALIM TALEP SONUCU | L28: 165 | M28: 88888888 | N28: HX
A29: 45271 | B29: MEGMT | C29: 28.3 | D29: 13 | F29: =D29*C29 -> 367.9 | H29: 0 | J29: 826.2 | K29: HALKA ARZ SENET 13 GİRİŞİ,SIRANO: | L29: 165 | M29: 88888888 | N29: HX
A30: 45273 | C30: - | D30: - | H30: 826.2 | I30: =I28+H30 -> 1652.4 | J30: 1652.4 | K30: CARİ/YATIRIM VİRMANI | L30: 5800 | M30: 36151331 | N30: QC
A31: 45273 | B31: AVPGY | C31: - | D31: - | H31: -1652.4 | I31: =I30+H31 -> 0 | J31: 0 | K31: HALKA ARZ TALEP GİRİŞİ | L31: 5800 | M31: 36151331 | N31: HF
A32: 45273 | C32: - | D32: - | H32: 21088.49 | I32: =I31+H32 -> 21088.49 | J32: 21088.49 | K32: CARİ/YATIRIM VİRMANI | L32: 5800 | M32: 36151857 | N32: QC
A33: 45273 | B33: 801 | C33: 527.21224 | D33: 40 | F33: =D33*C33 -> 21088.49 | H33: -21088.49 | I33: =I32+H33 -> 0 | J33: 0 | K33: YATIRIM FONU ALIŞI 50 | L33: 5800 | M33: 36151857 | N33: 72
A34: 45278 | B34: AVPGY | C34: - | D34: - | H34: 220.32 | I34: =I33+H34 -> 220.32 | J34: 220.32 | K34: HALKA ARZ ALIM TALEP SONUCU | L34: 165 | M34: 88888888 | N34: HX
A35: 45278 | B35: AVPGY | C35: 55.08 | D35: 26 | F35: =D35*C35 -> 1432.08 | H35: 0 | J35: 220.32 | K35: HALKA ARZ SENET 26 GİRİŞİ,SIRANO: | L35: 165 | M35: 88888888 | N35: HX
A36: 45288 | B36: 808 | C36: 18.625761 | D36: -300 | H36: 5587.73 | I36: =I34+H36 -> 5808.05 | J36: 5808.05 | K36: YATIRIM FONU SATIŞI | L36: 5800 | M36: 95105725 | N36: 73
A37: 45288 | C37: - | D37: - | H37: -5587.73 | I37: =I36+H37 -> 220.32 | J37: 220.32 | K37: YATIRIM/CARİ VİRMANI | L37: 5800 | M37: 95105725 | N37: QP
A38: 45288 | C38: - | D38: - | H38: 2086.51 | I38: =I37+H38 -> 2306.83 | J38: 2306.83 | K38: CARİ/YATIRIM VİRMANI | L38: 5800 | M38: 10001 | N38: QC
A39: 45288 | B39: TABGD | C39: 115.1 | D39: 20 | H39: -2306.83 | J39: 2306.83 | K39: 228000154978 NOLU ALIŞ TALİMATI | L39: 165 | M39: 95110347 | N39: QX
A40: 45288 | C40: - | D40: - | H40: 3960.3 | I40: =I38+H40 -> 6267.13 | J40: 6267.13 | K40: CARİ/YATIRIM VİRMANI | L40: 5800 | M40: 10001 | N40: QC
A41: 45288 | B41: AVPGY | C41: 39.52 | D41: 100 | H41: -3960.3 | J41: 6267.13 | K41: 228000162133 NOLU ALIŞ TALİMATI | L41: 165 | M41: 95111027 | N41: QX
A43: 45293 | B43: TABGD | C43: -115.1 | D43: 20 | F43: =H43/D43 -> -115.3415 | G43: 4.83 | H43: -2306.83 | I43: =I40+H43 -> 3960.3 | J43: 3960.3 | K43: TAKAS KOM: 4.60 - 39 - ALIŞ BSMV: 0.23 | L43: 165 | M43: 0 | N43: QA
...

Sheet Sayfa1
C5: 2240
C6: ev elektrik
C7: umut
C8: yasemin
C9: peri
C10: hmb
C11: kr a
C12: kr b
C13: kr c
C14: kr d
C15: kr e
C16: kr f
C17: kr g
... C30: 110.23 TABGD
